Workbook
Name _4432mm×3632mm×6mm×7.85Kg__100万_758.17Kg: #REF!

Sheet 外ダイヤフラム(トップを除く)
A1: 柱サイズ | B1: 柱板厚 | C1: 外ダイヤフラム外形サイズ | D1: ダイアフラム板厚 | E1: 柱×ダイアフラム板厚 | F1: 飯尾さんの表現 | G1: (Y1) | H1: (Y2) | I1: (Y3/Y4) | J1: (Y5) | K1: (Y6) | L1: (Y7) | N1: 通り芯(Y8) | O1: 通り芯(Y9) | P1: 通り芯(Y10) | Q1: 通り芯(Y11) | R1: 通り芯(Y12) | S1: トップダイヤ | T1: 数量(トップダイヤ引き算) | U1: 枚 | W1: d | X1: ×t | Y1: 柱サイズ | Z1: 柱板厚 | AA1: 隣接する梁 | AB1: 外ダイアフラム板厚 | AC1: □ | AE1: ( | AF1: ) | AG1: t | AH1: ×
A2: 300 | B2: 12 | C2: =IF(A2=0,"",A2+50) -> 350 | D2: 25 | E2: =IF(A2=0,"",A2&X2&D2&W2) -> 300×t25d | F2: =IF(A2=0,"",AG2&D2&AH2&A2&AE2&AC2&C2&AF2) -> t25×300(□350) | H2: 2 | S2: =IF(ISNA(VLOOKUP(F2,'外ダイヤフラム(トッププレート)'!F:S,14,FALSE)),"",VLOOKUP(F2,'外ダイヤフラム(トッププレート)'!F:S,14,FALSE)) -> 1 | T2: =IF(SUM(G2:R2)=0,"",IF(S2="",SUM(G2:R2)&U2,SUM(G2:R2)-S2&U2)) -> 1枚 | U2: 枚 | W2: d | X2: ×t | Y2: 250 | Z2: 12 | AB2: 25 | AC2: □ | AE2: ( | AF2: ) | AG2: t | AH2: ×
A3: 300 | C3: =IF(A3=0,"",A3+50) -> 350 | D3: 36 | E3: =IF(A3=0,"",A3&X3&D3&W3) -> 300×t36d | F3: =IF(A3=0,"",AG3&D3&AH3&A3&AE3&AC3&C3&AF3) -> t36×300(□350) | L3: 2 | S3: =IF(ISNA(VLOOKUP(F3,'外ダイヤフラム(トッププレート)'!F:S,14,FALSE)),"",VLOOKUP(F3,'外ダイヤフラム(トッププレート)'!F:S,14,FALSE)) -> 1 | T3: =IF(SUM(G3:R3)=0,"",IF(S3="",SUM(G3:R3)&U3,SUM(G3:R3)-S3&U3)) -> 1枚 | U3: 枚 | W3: d | X3: ×t | Y3: 300 | Z3: 16 | AB3: 28 | AC3: □ | AE3: ( | AF3: ) | AG3: t | AH3: ×
A4: 300 | C4: =IF(A4=0,"",A4+50) -> 350 | D4: 45 | E4: =IF(A4=0,"",A4&X4&D4&W4) -> 300×t45d | F4: =IF(A4=0,"",AG4&D4&AH4&A4&AE4&AC4&C4&AF4) -> t45×300(□350) | K4: 2 | S4: =IF(ISNA(VLOOKUP(F4,'外ダイヤフラム(トッププレート)'!F:S,14,FALSE)),"",VLOOKUP(F4,'外ダイヤフラム(トッププレート)'!F:S,14,FALSE)) -> 1 | T4: =IF(SUM(G4:R4)=0,"",IF(S4="",SUM(G4:R4)&U4,SUM(G4:R4)-S4&U4)) -> 1枚 | U4: 枚 | W4: d | X4: ×t | Y4: 350 | Z4: 19 | AB4: 30 | AC4: □ | AE4: ( | AF4: ) | AG4: t | AH4: ×
A5: 350 | C5: =IF(A5=0,"",A5+50) -> 400 | D5: 25 | E5: =IF(A5=0,"",A5&X5&D5&W5) -> 350×t25d | F5: =IF(A5=0,"",AG5&D5&AH5&A5&AE5&AC5&C5&AF5) -> t25×350(□400) | G5: 2 | H5: 10 | I5: 1 | J5: 1 | K5: 4 | L5: 7 | S5: =IF(ISNA(VLOOKUP(F5,'外ダイヤフラム(トッププレート)'!F:S,14,FALSE)),"",VLOOKUP(F5,'外ダイヤフラム(トッププレート)'!F:S,14,FALSE)) -> 10 | T5: =IF(SUM(G5:R5)=0,"",IF(S5="",SUM(G5:R5)&U5,SUM(G5:R5)-S5&U5)) -> 15枚 | U5: 枚 | W5: d | X5: ×t | Y5: 400 | AB5: 32 | AC5: □ | AE5: ( | AF5: ) | AG5: t | AH5: ×
A6: 350 | C6: =IF(A6=0,"",A6+50) -> 400 | D6: 28 | E6: =IF(A6=0,"",A6&X6&D6&W6) -> 350×t28d | F6: =IF(A6=0,"",AG6&D6&AH6&A6&AE6&AC6&C6&AF6) -> t28×350(□400) | H6: 6 | J6: 2 | K6: 5 | L6: 12 | S6: =IF(ISNA(VLOOKUP(F6,'外ダイヤフラム(トッププレート)'!F:S,14,FALSE)),"",VLOOKUP(F6,'外ダイヤフラム(トッププレート)'!F:S,14,FALSE)) | T6: =IF(SUM(G6:R6)=0,"",IF(S6="",SUM(G6:R6)&U6,SUM(G6:R6)-S6&U6)) -> 25枚 | U6: 枚 | W6: d | X6: ×t | Y6: 450 | AB6: 36 | AC6: □ | AE6: ( | AF6: ) | AG6: t | AH6: ×
A7: 350 | C7: =IF(A7=0,"",A7+50) -> 400 | D7: 32 | E7: =IF(A7=0,"",A7&X7&D7&W7) -> 350×t32d | F7: =IF(A7=0,"",AG7&D7&AH7&A7&AE7&AC7&C7&AF7) -> t32×350(□400) | L7: 2 | S7: =IF(ISNA(VLOOKUP(F7,'外ダイヤフラム(トッププレート)'!F:S,14,FALSE)),"",VLOOKUP(F7,'外ダイヤフラム(トッププレート)'!F:S,14,FALSE)) | T7: =IF(SUM(G7:R7)=0,"",IF(S7="",SUM(G7:R7)&U7,SUM(G7:R7)-S7&U7)) -> 2枚 | U7: 枚 | W7: d | X7: ×t | Y7: 500 | AB7: 40 | AC7: □ | AE7: ( | AF7: ) | AG7: t | AH7: ×
A8: 350 | C8: =IF(A8=0,"",A8+50) -> 400 | D8: 36 | E8: =IF(A8=0,"",A8&X8&D8&W8) -> 350×t36d | F8: =IF(A8=0,"",AG8&D8&AH8&A8&AE8&AC8&C8&AF8) -> t36×350(□400) | G8: 2 | H8: 11 | I8: 6 | J8: 12 | K8: 16 | L8: 26 | S8: =IF(ISNA(VLOOKUP(F8,'外ダイヤフラム(トッププレート)'!F:S,14,FALSE)),"",VLOOKUP(F8,'外ダイヤフラム(トッププレート)'!F:S,14,FALSE)) -> 9 | T8: =IF(SUM(G8:R8)=0,"",IF(S8="",SUM(G8:R8)&U8,SUM(G8:R8)-S8&U8)) -> 64枚 | U8: 枚 | W8: d | X8: ×t | Y8: 550 | AB8: 45 | AC8: □ | AE8: ( | AF8: ) | AG8: t | AH8: ×
A9: 350 | C9: =IF(A9=0,"",A9+50) -> 400 | D9: 40 | E9: =IF(A9=0,"",A9&X9&D9&W9) -> 350×t40d | F9: =IF(A9=0,"",AG9&D9&AH9&A9&AE9&AC9&C9&AF9) -> t40×350(□400) | G9: 4 | H9: 6 | I9: 6 | J9: 12 | K9: 10 | L9: 17 | S9: =IF(ISNA(VLOOKUP(F9,'外ダイヤフラム(トッププレート)'!F:S,14,FALSE)),"",VLOOKUP(F9,'外ダイヤフラム(トッププレート)'!F:S,14,FALSE)) | T9: =IF(SUM(G9:R9)=0,"",IF(S9="",SUM(G9:R9)&U9,SUM(G9:R9)-S9&U9)) -> 55枚 | U9: 枚 | W9: d | X9: ×t | Y9: 600 | AB9: 50 | AC9: □ | AE9: ( | AF9: ) | AG9: t | AH9: ×
A10: 350 | C10: =IF(A10=0,"",A10+50) -> 400 | D10: 45 | E10: =IF(A10=0,"",A10&X10&D10&W10) -> 350×t45d | F10: =IF(A10=0,"",AG10&D10&AH10&A10&AE10&AC10&C10&AF10) -> t45×350(□400) | G10: 2 | H10: 4 | I10: 4 | J10: 4 | L10: 12 | S10: =IF(ISNA(VLOOKUP(F10,'外ダイヤフラム(トッププレート)'!F:S,14,FALSE)),"",VLOOKUP(F10,'外ダイヤフラム(トッププレート)'!F:S,14,FALSE)) -> 4 | T10: =IF(SUM(G10:R10)=0,"",IF(S10="",SUM(G10:R10)&U10,SUM(G10:R10)-S10&U10)) -> 22枚 | U10: 枚 | W10: d | X10: ×t | AB10: 65 | AC10: □ | AE10: ( | AF10: ) | AG10: t | AH10: ×
A11: 350 | C11: =IF(A11=0,"",A11+50) -> 400 | D11: 65 | E11: =IF(A11=0,"",A11&X11&D11&W11) -> 350×t65d | F11: =IF(A11=0,"",AG11&D11&AH11&A11&AE11&AC11&C11&AF11) -> t65×350(□400) | H11: 1 | K11: 1 | L11: 1 | S11: =IF(ISNA(VLOOKUP(F11,'外ダイヤフラム(トッププレート)'!F:S,14,FALSE)),"",VLOOKUP(F11,'外ダイヤフラム(トッププレート)'!F:S,14,FALSE)) | T11: =IF(SUM(G11:R11)=0,"",IF(S11="",SUM(G11:R11)&U11,SUM(G11:R11)-S11&U11)) -> 3枚 | U11: 枚 | W11: d | X11: ×t | AB11: 70 | AC11: □ | AE11: ( | AF11: ) | AG11: t | AH11: ×
A12: 400 | C12: =IF(A12=0,"",A12+50) -> 450 | D12: 25 | E12: =IF(A12=0,"",A12&X12&D12&W12) -> 400×t25d | F12: =IF(A12=0,"",AG12&D12&AH12&A12&AE12&AC12&C12&AF12) -> t25×400(□450) | G12: 1 | L12: 1 | S12: =IF(ISNA(VLOOKUP(F12,'外ダイヤフラム(トッププレート)'!F:S,14,FALSE)),"",VLOOKUP(F12,'外ダイヤフラム(トッププレート)'!F:S,14,FALSE)) -> 1 | T12: =IF(SUM(G12:R12)=0,"",IF(S12="",SUM(G12:R12)&U12,SUM(G12:R12)-S12&U12)) -> 1枚 | U12: 枚 | W12: d | X12: ×t | AC12: □ | AE12: ( | AF12: ) | AG12: t | AH12: ×
A13: 400 | C13: =IF(A13=0,"",A13+50) -> 450 | D13: 28 | E13: =IF(A13=0,"",A13&X13&D13&W13) -> 400×t28d | F13: =IF(A13=0,"",AG13&D13&AH13&A13&AE13&AC13&C13&AF13) -> t28×400(□450) | K13: 2 | S13: =IF(ISNA(VLOOKUP(F13,'外ダイヤフラム(トッププレート)'!F:S,14,FALSE)),"",VLOOKUP(F13,'外ダイヤフラム(トッププレート)'!F:S,14,FALSE)) | T13: =IF(SUM(G13:R13)=0,"",IF(S13="",SUM(G13:R13)&U13,SUM(G13:R13)-S13&U13)) -> 2枚 | U13: 枚 | W13: d | X13: ×t | AC13: □ | AE13: ( | AF13: ) | AG13: t | AH13: ×
A14: 400 | C14: =IF(A14=0,"",A14+50) -> 450 | D14: 36 | E14: =IF(A14=0,"",A14&X14&D14&W14) -> 400×t36d | F14: =IF(A14=0,"",AG14&D14&AH14&A14&AE14&AC14&C14&AF14) -> t36×400(□450) | G14: 1 | H14: 4 | S14: =IF(ISNA(VLOOKUP(F14,'外ダイヤフラム(トッププレート)'!F:S,14,FALSE)),"",VLOOKUP(F14,'外ダイヤフラム(トッププレート)'!F:S,14,FALSE)) -> 1 | T14: =IF(SUM(G14:R14)=0,"",IF(S14="",SUM(G14:R14)&U14,SUM(G14:R14)-S14&U14)) -> 4枚 | U14: 枚 | W14: d | X14: ×t | AC14: □ | AE14: ( | AF14: ) | AG14: t | AH14: ×
A15: 400 | C15: =IF(A15=0,"",A15+50) -> 450 | D15: 40 | E15: =IF(A15=0,"",A15&X15&D15&W15) -> 400×t40d | F15: =IF(A15=0,"",AG15&D15&AH15&A15&AE15&AC15&C15&AF15) -> t40×400(□450) | I15: 2 | J15: 2 | S15: =IF(ISNA(VLOOKUP(F15,'外ダイヤフラム(トッププレート)'!F:S,14,FALSE)),"",VLOOKUP(F15,'外ダイヤフラム(トッププレート)'!F:S,14,FALSE)) | T15: =IF(SUM(G15:R15)=0,"",IF(S15="",SUM(G15:R15)&U15,SUM(G15:R15)-S15&U15)) -> 4枚 | U15: 枚 | W15: d | X15: ×t | AC15: □ | AE15: ( | AF15: ) | AG15: t | AH15: ×
A16: 400 | C16: =IF(A16=0,"",A16+50) -> 450 | D16: 45 | E16: =IF(A16=0,"",A16&X16&D16&W16) -> 400×t45d | F16: =IF(A16=0,"",AG16&D16&AH16&A16&AE16&AC16&C16&AF16) -> t45×400(□450) | I16: 3 | J16: 2 | K16: 2 | S16: =IF(ISNA(VLOOKUP(F16,'外ダイヤフラム(トッププレート)'!F:S,14,FALSE)),"",VLOOKUP(F16,'外ダイヤフラム(トッププレート)'!F:S,14,FALSE)) -> 3 | T16: =IF(SUM(G16:R16)=0,"",IF(S16="",SUM(G16:R16)&U16,SUM(G16:R16)-S16&U16)) -> 4枚 | U16: 枚 | W16: d | X16: ×t | AC16: □ | AE16: ( | AF16: ) | AG16: t | AH16: ×
A17: 400 | C17: =IF(A17=0,"",A17+50) -> 450 | D17: 50 | E17: =IF(A17=0,"",A17&X17&D17&W17) -> 400×t50d | F17: =IF(A17=0,"",AG17&D17&AH17&A17&AE17&AC17&C17&AF17) -> t50×400(□450) | I17: 2 | S17: =IF(ISNA(VLOOKUP(F17,'外ダイヤフラム(トッププレート)'!F:S,14,FALSE)),"",VLOOKUP(F17,'外ダイヤフラム(トッププレート)'!F:S,14,FALSE)) -> 2 | T17: =IF(SUM(G17:R17)=0,"",IF(S17="",SUM(G17:R17)&U17,SUM(G17:R17)-S17&U17)) -> 0枚 | U17: 枚 | W17: d | X17: ×t | AC17: □ | AE17: ( | AF17: ) | AG17: t | AH17: ×
A18: 400 | C18: =IF(A18=0,"",A18+50) -> 450 | D18: 70 | E18: =IF(A18=0,"",A18&X18&D18&W18) -> 400×t70d | F18: =IF(A18=0,"",AG18&D18&AH18&A18&AE18&AC18&C18&AF18) -> t70×400(□450) | G18: 1 | H18: 2 | I18: 1 | L18: 1 | S18: =IF(ISNA(VLOOKUP(F18,'外ダイヤフラム(トッププレート)'!F:S,14,FALSE)),"",VLOOKUP(F18,'外ダイヤフラム(トッププレート)'!F:S,14,FALSE)) | T18: =IF(SUM(G18:R18)=0,"",IF(S18="",SUM(G18:R18)&U18,SUM(G18:R18)-S18&U18)) -> 5枚 | U18: 枚 | W18: d | X18: ×t | AC18: □ | AE18: ( | AF18: ) | AG18: t | AH18: ×
A19: 450 | C19: =IF(A19=0,"",A19+50) -> 500 | D19: 25 | E19: =IF(A19=0,"",A19&X19&D19&W19) -> 450×t25d | F19: =IF(A19=0,"",AG19&D19&AH19&A19&AE19&AC19&C19&AF19) -> t25×450(□500) | G19: 2 | H19: 3 | K19: 1 | S19: =IF(ISNA(VLOOKUP(F19,'外ダイヤフラム(トッププレート)'!F:S,14,FALSE)),"",VLOOKUP(F19,'外ダイヤフラム(トッププレート)'!F:S,14,FALSE)) -> 4 | T19: =IF(SUM(G19:R19)=0,"",IF(S19="",SUM(G19:R19)&U19,SUM(G19:R19)-S19&U19)) -> 2枚 | U19: 枚 | W19: d | X19: ×t | AC19: □ | AE19: ( | AF19: ) | AG19: t | AH19: ×
A20: 450 | C20: =IF(A20=0,"",A20+50) -> 500 | D20: 28 | E20: =IF(A20=0,"",A20&X20&D20&W20) -> 450×t28d | F20: =IF(A20=0,"",AG20&D20&AH20&A20&AE20&AC20&C20&AF20) -> t28×450(□500) | H20: 2 | S20: =IF(ISNA(VLOOKUP(F20,'外ダイヤフラム(トッププレート)'!F:S,14,FALSE)),"",VLOOKUP(F20,'外ダイヤフラム(トッププレート)'!F:S,14,FALSE)) | T20: =IF(SUM(G20:R20)=0,"",IF(S20="",SUM(G20:R20)&U20,SUM(G20:R20)-S20&U20)) -> 2枚 | U20: 枚 | W20: d | X20: ×t | AC20: □ | AE20: ( | AF20: ) | AG20: t | AH20: ×
A21: 450 | C21: =IF(A21=0,"",A21+50) -> 500 | D21: 36 | E21: =IF(A21=0,"",A21&X21&D21&W21) -> 450×t36d | F21: =IF(A21=0,"",AG21&D21&AH21&A21&AE21&AC21&C21&AF21) -> t36×450(□500) | G21: 9 | H21: 11 | J21: 4 | K21: 9 | S21: =IF(ISNA(VLOOKUP(F21,'外ダイヤフラム(トッププレート)'!F:S,14,FALSE)),"",VLOOKUP(F21,'外ダイヤフラム(トッププレート)'!F:S,14,FALSE)) -> 6 | T21: =IF(SUM(G21:R21)=0,"",IF(S21="",SUM(G21:R21)&U21,SUM(G21:R21)-S21&U21)) -> 27枚 | U21: 枚 | W21: d | X21: ×t | AC21: □ | AE21: ( | AF21: ) | AG21: t | AH21: ×
A22: 450 | C22: =IF(A22=0,"",A22+50) -> 500 | D22: 40 | E22: =IF(A22=0,"",A22&X22&D22&W22) -> 450×t40d | F22: =IF(A22=0,"",AG22&D22&AH22&A22&AE22&AC22&C22&AF22) -> t40×450(□500) | G22: 9 | H22: 5 | J22: 8 | K22: 14 | L22: 2 | S22: =IF(ISNA(VLOOKUP(F22,'外ダイヤフラム(トッププレート)'!F:S,14,FALSE)),"",VLOOKUP(F22,'外ダイヤフラム(トッププレート)'!F:S,14,FALSE)) | T22: =IF(SUM(G22:R22)=0,"",IF(S22="",SUM(G22:R22)&U22,SUM(G22:R22)-S22&U22)) -> 38枚 | U22: 枚 | W22: d | X22: ×t | AC22: □ | AE22: ( | AF22: ) | AG22: t | AH22: ×
A23: 450 | C23: =IF(A23=0,"",A23+50) -> 500 | D23: 45 | E23: =IF(A23=0,"",A23&X23&D23&W23) -> 450×t45d | F23: =IF(A23=0,"",AG23&D23&AH23&A23&AE23&AC23&C23&AF23) -> t45×450(□500) | G23: 4 | H23: 9 | I23: 7 | J23: 15 | K23: 28 | L23: 3 | S23: =IF(ISNA(VLOOKUP(F23,'外ダイヤフラム(トッププレート)'!F:S,14,FALSE)),"",VLOOKUP(F23,'外ダイヤフラム(トッププレート)'!F:S,14,FALSE)) -> 4 | T23: =IF(SUM(G23:R23)=0,"",IF(S23="",SUM(G23:R23)&U23,SUM(G23:R23)-S23&U23)) -> 62枚 | U23: 枚 | W23: d | X23: ×t | AC23: □ | AE23: ( | AF23: ) | AG23: t | AH23: ×
A24: 450 | C24: =IF(A24=0,"",A24+50) -> 500 | D24: 50 | E24: =IF(A24=0,"",A24&X24&D24&W24) -> 450×t50d | F24: =IF(A24=0,"",AG24&D24&AH24&A24&AE24&AC24&C24&AF24) -> t50×450(□500) | G24: 2 | H24: 2 | I24: 4 | J24: 4 | S24: =IF(ISNA(VLOOKUP(F24,'外ダイヤフラム(トッププレート)'!F:S,14,FALSE)),"",VLOOKUP(F24,'外ダイヤフラム(トッププレート)'!F:S,14,FALSE)) -> 2 | T24: =IF(SUM(G24:R24)=0,"",IF(S24="",SUM(G24:R24)&U24,SUM(G24:R24)-S24&U24)) -> 10枚 | U24: 枚 | W24: d | X24: ×t | AC24: □ | AE24: ( | AF24: ) | AG24: t | AH24: ×
A25: 450 | C25: =IF(A25=0,"",A25+50) -> 500 | D25: 70 | E25: =IF(A25=0,"",A25&X25&D25&W25) -> 450×t70d | F25: =IF(A25=0,"",AG25&D25&AH25&A25&AE25&AC25&C25&AF25) -> t70×450(□500) | G25: 2 | H25: 3 | I25: 3 | J25: 1 | K25: 1 | L25: 1 | S25: =IF(ISNA(VLOOKUP(F25,'外ダイヤフラム(トッププレート)'!F:S,14,FALSE)),"",VLOOKUP(F25,'外ダイヤフラム(トッププレート)'!F:S,14,FALSE)) | T25: =IF(SUM(G25:R25)=0,"",IF(S25="",SUM(G25:R25)&U25,SUM(G25:R25)-S25&U25)) -> 11枚 | U25: 枚 | W25: d | X25: ×t | AC25: □ | AE25: ( | AF25: ) | AG25: t | AH25: ×
A26: 500 | C26: =IF(A26=0,"",A26+50) -> 550 | D26: 36 | E26: =IF(A26=0,"",A26&X26&D26&W26) -> 500×t36d | F26: =IF(A26=0,"",AG26&D26&AH26&A26&AE26&AC26&C26&AF26) -> t36×500(□550) | H26: 2 | S26: =IF(ISNA(VLOOKUP(F26,'外ダイヤフラム(トッププレート)'!F:S,14,FALSE)),"",VLOOKUP(F26,'外ダイヤフラム(トッププレート)'!F:S,14,FALSE)) | T26: =IF(SUM(G26:R26)=0,"",IF(S26="",SUM(G26:R26)&U26,SUM(G26:R26)-S26&U26)) -> 2枚 | U26: 枚 | W26: d | X26: ×t | AC26: □ | AE26: ( | AF26: ) | AG26: t | AH26: ×
A27: 500 | C27: =IF(A27=0,"",A27+50) -> 550 | D27: 40 | E27: =IF(A27=0,"",A27&X27&D27&W27) -> 500×t40d | F27: =IF(A27=0,"",AG27&D27&AH27&A27&AE27&AC27&C27&AF27) -> t40×500(□550) | G27: 2 | H27: 2 | I27: 2 | J27: 4 | S27: =IF(ISNA(VLOOKUP(F27,'外ダイヤフラム(トッププレート)'!F:S,14,FALSE)),"",VLOOKUP(F27,'外ダイヤフラム(トッププレート)'!F:S,14,FALSE)) | T27: =IF(SUM(G27:R27)=0,"",IF(S27="",SUM(G27:R27)&U27,SUM(G27:R27)-S27&U27)) -> 10枚 | U27: 枚 | W27: d | X27: ×t | AC27: □ | AE27: ( | AF27: ) | AG27: t | AH27: ×
A28: 500 | C28: =IF(A28=0,"",A28+50) -> 550 | D28: 45 | E28: =IF(A28=0,"",A28&X28&D28&W28) -> 500×t45d | F28: =IF(A28=0,"",AG28&D28&AH28&A28&AE28&AC28&C28&AF28) -> t45×500(□550) | H28: 2 | I28: 2 | J28: 4 | S28: =IF(ISNA(VLOOKUP(F28,'外ダイヤフラム(トッププレート)'!F:S,14,FALSE)),"",VLOOKUP(F28,'外ダイヤフラム(トッププレート)'!F:S,14,FALSE)) | T28: =IF(SUM(G28:R28)=0,"",IF(S28="",SUM(G28:R28)&U28,SUM(G28:R28)-S28&U28)) -> 8枚 | U28: 枚 | W28: d | X28: ×t | AC28: □ | AE28: ( | AF28: ) | AG28: t | AH28: ×
A29: 500 | C29: =IF(A29=0,"",A29+50) -> 550 | D29: 50 | E29: =IF(A29=0,"",A29&X29&D29&W29) -> 500×t50d | F29: =IF(A29=0,"",AG29&D29&AH29&A29&AE29&AC29&C29&AF29) -> t50×500(□550) | G29: 1 | H29: 1 | S29: =IF(ISNA(VLOOKUP(F29,'外ダイヤフラム(トッププレート)'!F:S,14,FALSE)),"",VLOOKUP(F29,'外ダイヤフラム(トッププレート)'!F:S,14,FALSE)) | T29: =IF(SUM(G29:R29)=0,"",IF(S29="",SUM(G29:R29)&U29,SUM(G29:R29)-S29&U29)) -> 2枚 | U29: 枚 | W29: d | X29: ×t | AC29: □ | AE29: ( | AF29: ) | AG29: t | AH29: ×
A30: 500 | C30: =IF(A30=0,"",A30+50) -> 550 | D30: 70 | E30: =IF(A30=0,"",A30&X30&D30&W30) -> 500×t70d | F30: =IF(A30=0,"",AG30&D30&AH30&A30&AE30&AC30&C30&AF30) -> t70×500(□550) | G30: 1 | H30: 1 | I30: 2 | J30: 1 | S30: =IF(ISNA(VLOOKUP(F30,'外ダイヤフラム(トッププレート)'!F:S,14,FALSE)),"",VLOOKUP(F30,'外ダイヤフラム(トッププレート)'!F:S,14,FALSE)) | T30: =IF(SUM(G30:R30)=0,"",IF(S30="",SUM(G30:R30)&U30,SUM(G30:R30)-S30&U30)) -> 5枚 | U30: 枚 | W30: d | X30: ×t | AC30: □ | AE30: ( | AF30: ) | AG30: t | AH30: ×
C31: =IF(A31=0,"",A31+50) | E31: =IF(A31=0,"",A31&X31&D31&W31) | F31: =IF(A31=0,"",AG31&D31&AH31&A31&AE31&AC31&C31&AF31) | S31: =IF(ISNA(VLOOKUP(F31,'外ダイヤフラム(トッププレート)'!F:S,14,FALSE)),"",VLOOKUP(F31,'外ダイヤフラム(トッププレート)'!F:S,14,FALSE)) | T31: =IF(SUM(G31:R31)=0,"",IF(S31="",SUM(G31:R31)&U31,SUM(G31:R31)-S31&U31)) | U31: 枚 | W31: d | X31: ×t | AC31: □ | AE31: ( | AF31: ) | AG31: t | AH31: ×
C32: =IF(A32=0,"",A32+50) | E32: =IF(A32=0,"",A32&X32&D32&W32) | F32: =IF(A32=0,"",AG32&D32&AH32&A32&AE32&AC32&C32&AF32) | S32: =IF(ISNA(VLOOKUP(F32,'外ダイヤフラム(トッププレート)'!F:S,14,FALSE)),"",VLOOKUP(F32,'外ダイヤフラム(トッププレート)'!F:S,14,FALSE)) | T32: =IF(SUM(G32:R32)=0,"",IF(S32="",SUM(G32:R32)&U32,SUM(G32:R32)-S32&U32)) | U32: 枚 | W32: d | X32: ×t | AC32: □ | AE32: ( | AF32: ) | AG32: t | AH32: ×
C33: =IF(A33=0,"",A33+50) | E33: =IF(A33=0,"",A33&X33&D33&W33) | F33: =IF(A33=0,"",AG33&D33&AH33&A33&AE33&AC33&C33&AF33) | S33: =IF(ISNA(VLOOKUP(F33,'外ダイヤフラム(トッププレート)'!F:S,14,FALSE)),"",VLOOKUP(F33,'外ダイヤフラム(トッププレート)'!F:S,14,FALSE)) | T33: =IF(SUM(G33:R33)=0,"",IF(S33="",SUM(G33:R33)&U33,SUM(G33:R33)-S33&U33)) | U33: 枚 | W33: d | X33: ×t | AC33: □ | AE33: ( | AF33: ) | AG33: t | AH33: ×
C34: =IF(A34=0,"",A34+50) | E34: =IF(A34=0,"",A34&X34&D34&W34) | F34: =IF(A34=0,"",AG34&D34&AH34&A34&AE34&AC34&C34&AF34) | S34: =IF(ISNA(VLOOKUP(F34,'外ダイヤフラム(トッププレート)'!F:S,14,FALSE)),"",VLOOKUP(F34,'外ダイヤフラム(トッププレート)'!F:S,14,FALSE)) | T34: =IF(SUM(G34:R34)=0,"",IF(S34="",SUM(G34:R34)&U34,SUM(G34:R34)-S34&U34)) | U34: 枚 | W34: d | X34: ×t | AC34: □ | AE34: ( | AF34: ) | AG34: t | AH34: ×
C35: =IF(A35=0,"",A35+50) | E35: =IF(A35=0,"",A35&X35&D35&W35) | F35: =IF(A35=0,"",AG35&D35&AH35&A35&AE35&AC35&C35&AF35) | S35: =IF(ISNA(VLOOKUP(F35,'外ダイヤフラム(トッププレート)'!F:S,14,FALSE)),"",VLOOKUP(F35,'外ダイヤフラム(トッププレート)'!F:S,14,FALSE)) | T35: =IF(SUM(G35:R35)=0,"",IF(S35="",SUM(G35:R35)&U35,SUM(G35:R35)-S35&U35)) | U35: 枚 | W35: d | X35: ×t | AC35: □ | AE35: ( | AF35: ) | AG35: t | AH35: ×
C36: =IF(A36=0,"",A36+50) | E36: =IF(A36=0,"",A36&X36&D36&W36) | F36: =IF(A36=0,"",AG36&D36&AH36&A36&AE36&AC36&C36&AF36) | S36: =IF(ISNA(VLOOKUP(F36,'外ダイヤフラム(トッププレート)'!F:S,14,FALSE)),"",VLOOKUP(F36,'外ダイヤフラム(トッププレート)'!F:S,14,FALSE)) | T36: =IF(SUM(G36:R36)=0,"",IF(S36="",SUM(G36:R36)&U36,SUM(G36:R36)-S36&U36)) | U36: 枚 | W36: d | X36: ×t | AC36: □ | AE36: ( | AF36: ) | AG36: t | AH36: ×
C37: =IF(A37=0,"",A37+50) | E37: =IF(A37=0,"",A37&X37&D37&W37) | F37: =IF(A37=0,"",AG37&D37&AH37&A37&AE37&AC37&C37&AF37) | S37: =IF(ISNA(VLOOKUP(F37,'外ダイヤフラム(トッププレート)'!F:S,14,FALSE)),"",VLOOKUP(F37,'外ダイヤフラム(トッププレート)'!F:S,14,FALSE)) | T37: =IF(SUM(G37:R37)=0,"",IF(S37="",SUM(G37:R37)&U37,SUM(G37:R37)-S37&U37)) | U37: 枚 | W37: d | X37: ×t | AC37: □ | AE37: ( | AF37: ) | AG37: t | AH37: ×
C38: =IF(A38=0,"",A38+50) | E38: =IF(A38=0,"",A38&X38&D38&W38) | F38: =IF(A38=0,"",AG38&D38&AH38&A38&AE38&AC38&C38&AF38) | S38: =IF(ISNA(VLOOKUP(F38,'外ダイヤフラム(トッププレート)'!F:S,14,FALSE)),"",VLOOKUP(F38,'外ダイヤフラム(トッププレート)'!F:S,14,FALSE)) | T38: =IF(SUM(G38:R38)=0,"",IF(S38="",SUM(G38:R38)&U38,SUM(G38:R38)-S38&U38)) | U38: 枚 | W38: d | X38: ×t | AC38: □ | AE38: ( | AF38: ) | AG38: t | AH38: ×
C39: =IF(A39=0,"",A39+50) | E39: =IF(A39=0,"",A39&X39&D39&W39) | F39: =IF(A39=0,"",AG39&D39&AH39&A39&AE39&AC39&C39&AF39) | S39: =IF(ISNA(VLOOKUP(F39,'外ダイヤフラム(トッププレート)'!F:S,14,FALSE)),"",VLOOKUP(F39,'外ダイヤフラム(トッププレート)'!F:S,14,FALSE)) | T39: =IF(SUM(G39:R39)=0,"",IF(S39="",SUM(G39:R39)&U39,SUM(G39:R39)-S39&U39)) | U39: 枚 | W39: d | X39: ×t | AC39: □ | AE39: ( | AF39: ) | AG39: t | AH39: ×
C40: =IF(A40=0,"",A40+50) | E40: =IF(A40=0,"",A40&X40&D40&W40) | F40: =IF(A40=0,"",AG40&D40&AH40&A40&AE40&AC40&C40&AF40) | S40: =IF(ISNA(VLOOKUP(F40,'外ダイヤフラム(トッププレート)'!F:S,14,FALSE)),"",VLOOKUP(F40,'外ダイヤフラム(トッププレート)'!F:S,14,FALSE)) | T40: =IF(SUM(G40:R40)=0,"",IF(S40="",SUM(G40:R40)&U40,SUM(G40:R40)-S40&U40)) | U40: 枚 | W40: d | X40: ×t | AC40: □ | AE40: ( | AF40: ) | AG40: t | AH40: ×
...

Sheet 外ダイヤフラム(トッププレート)
A1: 柱サイズ | B1: 柱板厚 | C1: 外ダイヤフラム外形サイズ | D1: ダイアフラム板厚 | E1: 柱×ダイアフラム板厚 | F1: 飯尾さんの表現 | G1: (Y1) | H1: (Y2) | I1: (Y3/Y4) | J1: (Y5) | K1: (Y6) | L1: (Y7) | N1: 通り芯(Y8) | O1: 通り芯(Y9) | P1: 通り芯(Y10) | Q1: 通り芯(Y11) | R1: 通り芯(Y12) | S1: 数量 | U1: d | V1: ×t | W1: ×t | X1: 柱サイズ | Y1: 柱板厚 | Z1: ( | AA1: 外ダイアフラム板厚 | AB1: □ | AC1: t | AD1: × | AE1: )
A2: 300 | B2: 12 | C2: =IF(A2=0,"",A2+50) -> 350 | D2: 25 | E2: =IF(A2=0,"",A2&V2&D2&U2) -> 300×t25d | F2: =IF(A2=0,"",AC2&D2&AD2&A2&Z2&AB2&C2&AE2) -> t25×300(□350) | H2: 1 | S2: =IF(SUM(G2:R2)=0,"",SUM(G2:R2)) -> 1 | U2: d | V2: ×t | W2: ×t | X2: 250 | Y2: 12 | Z2: ( | AA2: 25 | AB2: □ | AC2: t | AD2: × | AE2: )
A3: 300 | C3: =IF(A3=0,"",A3+50) -> 350 | D3: 36 | E3: =IF(A3=0,"",A3&V3&D3&U3) -> 300×t36d | F3: =IF(A3=0,"",AC3&D3&AD3&A3&Z3&AB3&C3&AE3) -> t36×300(□350) | L3: 1 | S3: =IF(SUM(G3:R3)=0,"",SUM(G3:R3)) -> 1 | U3: d | V3: ×t | W3: ×t | X3: 300 | Y3: 16 | Z3: ( | AA3: 28 | AB3: □ | AC3: t | AD3: × | AE3: )
A4: 300 | C4: =IF(A4=0,"",A4+50) -> 350 | D4: 45 | E4: =IF(A4=0,"",A4&V4&D4&U4) -> 300×t45d | F4: =IF(A4=0,"",AC4&D4&AD4&A4&Z4&AB4&C4&AE4) -> t45×300(□350) | K4: 1 | S4: =IF(SUM(G4:R4)=0,"",SUM(G4:R4)) -> 1 | U4: d | V4: ×t | W4: ×t | X4: 350 | Y4: 19 | Z4: ( | AA4: 30 | AB4: □ | AC4: t | AD4: × | AE4: )
A5: 350 | C5: =IF(A5=0,"",A5+50) -> 400 | D5: 25 | E5: =IF(A5=0,"",A5&V5&D5&U5) -> 350×t25d | F5: =IF(A5=0,"",AC5&D5&AD5&A5&Z5&AB5&C5&AE5) -> t25×350(□400) | G5: 2 | H5: 4 | I5: 1 | J5: 1 | K5: 1 | L5: 1 | S5: =IF(SUM(G5:R5)=0,"",SUM(G5:R5)) -> 10 | U5: d | V5: ×t | W5: ×t | X5: 400 | Z5: ( | AA5: 32 | AB5: □ | AC5: t | AD5: × | AE5: )
A6: 350 | C6: =IF(A6=0,"",A6+50) -> 400 | D6: 36 | E6: =IF(A6=0,"",A6&V6&D6&U6) -> 350×t36d | F6: =IF(A6=0,"",AC6&D6&AD6&A6&Z6&AB6&C6&AE6) -> t36×350(□400) | I6: 2 | J6: 2 | K6: 1 | L6: 4 | S6: =IF(SUM(G6:R6)=0,"",SUM(G6:R6)) -> 9 | U6: d | V6: ×t | W6: ×t | X6: 450 | Z6: ( | AA6: 36 | AB6: □ | AC6: t | AD6: × | AE6: )
A7: 350 | C7: =IF(A7=0,"",A7+50) -> 400 | D7: 45 | E7: =IF(A7=0,"",A7&V7&D7&U7) -> 350×t45d | F7: =IF(A7=0,"",AC7&D7&AD7&A7&Z7&AB7&C7&AE7) -> t45×350(□400) | I7: 1 | J7: 1 | L7: 2 | S7: =IF(SUM(G7:R7)=0,"",SUM(G7:R7)) -> 4 | U7: d | V7: ×t | W7: ×t | X7: 500 | Z7: ( | AA7: 40 | AB7: □ | AC7: t | AD7: × | AE7: )
A8: 400 | C8: =IF(A8=0,"",A8+50) -> 450 | D8: 25 | E8: =IF(A8=0,"",A8&V8&D8&U8) -> 400×t25d | F8: =IF(A8=0,"",AC8&D8&AD8&A8&Z8&AB8&C8&AE8) -> t25×400(□450) | G8: 1 | S8: =IF(SUM(G8:R8)=0,"",SUM(G8:R8)) -> 1 | U8: d | V8: ×t | W8: ×t | X8: 550 | Z8: ( | AA8: 45 | AB8: □ | AC8: t | AD8: × | AE8: )
A9: 400 | C9: =IF(A9=0,"",A9+50) -> 450 | D9: 36 | E9: =IF(A9=0,"",A9&V9&D9&U9) -> 400×t36d | F9: =IF(A9=0,"",AC9&D9&AD9&A9&Z9&AB9&C9&AE9) -> t36×400(□450) | H9: 1 | S9: =IF(SUM(G9:R9)=0,"",SUM(G9:R9)) -> 1 | U9: d | V9: ×t | W9: ×t | X9: 600 | Z9: ( | AA9: 50 | AB9: □ | AC9: t | AD9: × | AE9: )
A10: 400 | C10: =IF(A10=0,"",A10+50) -> 450 | D10: 45 | E10: =IF(A10=0,"",A10&V10&D10&U10) -> 400×t45d | F10: =IF(A10=0,"",AC10&D10&AD10&A10&Z10&AB10&C10&AE10) -> t45×400(□450) | I10: 1 | J10: 1 | K10: 1 | S10: =IF(SUM(G10:R10)=0,"",SUM(G10:R10)) -> 3 | U10: d | V10: ×t | W10: ×t | Z10: ( | AA10: 65 | AB10: □ | AC10: t | AD10: × | AE10: )
A11: 400 | C11: =IF(A11=0,"",A11+50) -> 450 | D11: 50 | E11: =IF(A11=0,"",A11&V11&D11&U11) -> 400×t50d | F11: =IF(A11=0,"",AC11&D11&AD11&A11&Z11&AB11&C11&AE11) -> t50×400(□450) | I11: 1 | J11: 1 | S11: =IF(SUM(G11:R11)=0,"",SUM(G11:R11)) -> 2 | U11: d | V11: ×t | W11: ×t | Z11: ( | AA11: 70 | AB11: □ | AC11: t | AD11: × | AE11: )
A12: 450 | C12: =IF(A12=0,"",A12+50) -> 500 | D12: 25 | E12: =IF(A12=0,"",A12&V12&D12&U12) -> 450×t25d | F12: =IF(A12=0,"",AC12&D12&AD12&A12&Z12&AB12&C12&AE12) -> t25×450(□500) | G12: 2 | H12: 1 | K12: 1 | S12: =IF(SUM(G12:R12)=0,"",SUM(G12:R12)) -> 4 | U12: d | V12: ×t | W12: ×t | Z12: ( | AB12: □ | AC12: t | AD12: × | AE12: )
A13: 450 | C13: =IF(A13=0,"",A13+50) -> 500 | D13: 36 | E13: =IF(A13=0,"",A13&V13&D13&U13) -> 450×t36d | F13: =IF(A13=0,"",AC13&D13&AD13&A13&Z13&AB13&C13&AE13) -> t36×450(□500) | H13: 2 | I13: 1 | J13: 1 | K13: 2 | S13: =IF(SUM(G13:R13)=0,"",SUM(G13:R13)) -> 6 | U13: d | V13: ×t | W13: ×t | Z13: ( | AB13: □ | AC13: t | AD13: × | AE13: )
A14: 450 | C14: =IF(A14=0,"",A14+50) -> 500 | D14: 45 | E14: =IF(A14=0,"",A14&V14&D14&U14) -> 450×t45d | F14: =IF(A14=0,"",AC14&D14&AD14&A14&Z14&AB14&C14&AE14) -> t45×450(□500) | J14: 2 | K14: 2 | S14: =IF(SUM(G14:R14)=0,"",SUM(G14:R14)) -> 4 | U14: d | V14: ×t | W14: ×t | Z14: ( | AB14: □ | AC14: t | AD14: × | AE14: )
A15: 450 | C15: =IF(A15=0,"",A15+50) -> 500 | D15: 50 | E15: =IF(A15=0,"",A15&V15&D15&U15) -> 450×t50d | F15: =IF(A15=0,"",AC15&D15&AD15&A15&Z15&AB15&C15&AE15) -> t50×450(□500) | I15: 1 | J15: 1 | S15: =IF(SUM(G15:R15)=0,"",SUM(G15:R15)) -> 2 | U15: d | V15: ×t | W15: ×t | Z15: ( | AB15: □ | AC15: t | AD15: × | AE15: )
C16: =IF(A16=0,"",A16+50) | E16: =IF(A16=0,"",A16&V16&D16&U16) | F16: =IF(A16=0,"",AC16&D16&AD16&A16&Z16&AB16&C16&AE16) | S16: =IF(SUM(G16:R16)=0,"",SUM(G16:R16)) | U16: d | V16: ×t | W16: ×t | Z16: ( | AB16: □ | AC16: t | AD16: × | AE16: )
C17: =IF(A17=0,"",A17+50) | E17: =IF(A17=0,"",A17&V17&D17&U17) | F17: =IF(A17=0,"",AC17&D17&AD17&A17&Z17&AB17&C17&AE17) | S17: =IF(SUM(G17:R17)=0,"",SUM(G17:R17)) | U17: d | V17: ×t | W17: ×t | Z17: ( | AB17: □ | AC17: t | AD17: × | AE17: )
C18: =IF(A18=0,"",A18+50) | E18: =IF(A18=0,"",A18&V18&D18&U18) | F18: =IF(A18=0,"",AC18&D18&AD18&A18&Z18&AB18&C18&AE18) | S18: =IF(SUM(G18:R18)=0,"",SUM(G18:R18)) | U18: d | V18: ×t | W18: ×t | Z18: ( | AB18: □ | AC18: t | AD18: × | AE18: )
C19: =IF(A19=0,"",A19+50) | E19: =IF(A19=0,"",A19&V19&D19&U19) | F19: =IF(A19=0,"",AC19&D19&AD19&A19&Z19&AB19&C19&AE19) | S19: =IF(SUM(G19:R19)=0,"",SUM(G19:R19)) | U19: d | V19: ×t | W19: ×t | Z19: ( | AB19: □ | AC19: t | AD19: × | AE19: )
C20: =IF(A20=0,"",A20+50) | E20: =IF(A20=0,"",A20&V20&D20&U20) | F20: =IF(A20=0,"",AC20&D20&AD20&A20&Z20&AB20&C20&AE20) | S20: =IF(SUM(G20:R20)=0,"",SUM(G20:R20)) | U20: d | V20: ×t | W20: ×t | Z20: ( | AB20: □ | AC20: t | AD20: × | AE20: )
C21: =IF(A21=0,"",A21+50) | E21: =IF(A21=0,"",A21&V21&D21&U21) | F21: =IF(A21=0,"",AC21&D21&AD21&A21&Z21&AB21&C21&AE21) | S21: =IF(SUM(G21:R21)=0,"",SUM(G21:R21)) | U21: d | V21: ×t | W21: ×t | Z21: ( | AB21: □ | AC21: t | AD21: × | AE21: )
C22: =IF(A22=0,"",A22+50) | E22: =IF(A22=0,"",A22&V22&D22&U22) | F22: =IF(A22=0,"",AC22&D22&AD22&A22&Z22&AB22&C22&AE22) | S22: =IF(SUM(G22:R22)=0,"",SUM(G22:R22)) | U22: d | V22: ×t | W22: ×t | Z22: ( | AB22: □ | AC22: t | AD22: × | AE22: )
C23: =IF(A23=0,"",A23+50) | E23: =IF(A23=0,"",A23&V23&D23&U23) | F23: =IF(A23=0,"",AC23&D23&AD23&A23&Z23&AB23&C23&AE23) | S23: =IF(SUM(G23:R23)=0,"",SUM(G23:R23)) | U23: d | V23: ×t | W23: ×t | Z23: ( | AB23: □ | AC23: t | AD23: × | AE23: )
C24: =IF(A24=0,"",A24+50) | E24: =IF(A24=0,"",A24&V24&D24&U24) | F24: =IF(A24=0,"",AC24&D24&AD24&A24&Z24&AB24&C24&AE24) | S24: =IF(SUM(G24:R24)=0,"",SUM(G24:R24)) | U24: d | V24: ×t | W24: ×t | Z24: ( | AB24: □ | AC24: t | AD24: × | AE24: )
C25: =IF(A25=0,"",A25+50) | E25: =IF(A25=0,"",A25&V25&D25&U25) | F25: =IF(A25=0,"",AC25&D25&AD25&A25&Z25&AB25&C25&AE25) | S25: =IF(SUM(G25:R25)=0,"",SUM(G25:R25)) | U25: d | V25: ×t | W25: ×t | Z25: ( | AB25: □ | AC25: t | AD25: × | AE25: )
C26: =IF(A26=0,"",A26+50) | E26: =IF(A26=0,"",A26&V26&D26&U26) | F26: =IF(A26=0,"",AC26&D26&AD26&A26&Z26&AB26&C26&AE26) | S26: =IF(SUM(G26:R26)=0,"",SUM(G26:R26)) | U26: d | V26: ×t | W26: ×t | Z26: ( | AB26: □ | AC26: t | AD26: × | AE26: )
C27: =IF(A27=0,"",A27+50) | E27: =IF(A27=0,"",A27&V27&D27&U27) | F27: =IF(A27=0,"",AC27&D27&AD27&A27&Z27&AB27&C27&AE27) | S27: =IF(SUM(G27:R27)=0,"",SUM(G27:R27)) | U27: d | V27: ×t | W27: ×t | Z27: ( | AB27: □ | AC27: t | AD27: × | AE27: )
... C1410: =IF(A1410=0,"",A1410+50) | E1410: =IF(A1410=0,"",A1410&V1410&D1410&U1410) | F1410: =IF(A1410=0,"",AC1410&D1410&AD1410&A1410&Z1410&AB1410&C1410&AE1410) | S1410: =IF(SUM(G1410:R1410)=0,"",SUM(G1410:R1410)) | U1410: d | V1410: ×t | W1410: ×t | Z1410: ( | AB1410: □ | AC1410: t | AD1410: × | AE1410: )
C1411: =IF(A1411=0,"",A1411+50) | E1411: =IF(A1411=0,"",A1411&V1411&D1411&U1411) | F1411: =IF(A1411=0,"",AC1411&D1411&AD1411&A1411&Z1411&AB1411&C1411&AE1411) | U1411: d | V1411: ×t | W1411: ×t | Z1411: ( | AB1411: □ | AC1411: t | AD1411: × | AE1411: )
C1412: =IF(A1412=0,"",A1412+50) | E1412: =IF(A1412=0,"",A1412&V1412&D1412&U1412) | F1412: =IF(A1412=0,"",AC1412&D1412&AD1412&A1412&Z1412&AB1412&C1412&AE1412) | U1412: d | V1412: ×t | W1412: ×t | Z1412: ( | AB1412: □ | AC1412: t | AD1412: × | AE1412: )
C1413: =IF(A1413=0,"",A1413+50) | E1413: =IF(A1413=0,"",A1413&V1413&D1413&U1413) | F1413: =IF(A1413=0,"",AC1413&D1413&AD1413&A1413&Z1413&AB1413&C1413&AE1413) | U1413: d | V1413: ×t | W1413: ×t | Z1413: ( | AB1413: □ | AC1413: t | AD1413: × | AE1413: )
C1414: =IF(A1414=0,"",A1414+50) | E1414: =IF(A1414=0,"",A1414&V1414&D1414&U1414) | F1414: =IF(A1414=0,"",AC1414&D1414&AD1414&A1414&Z1414&AB1414&C1414&AE1414) | U1414: d | V1414: ×t | W1414: ×t | Z1414: ( | AB1414: □ | AC1414: t | AD1414: × | AE1414: )
C1415: =IF(A1415=0,"",A1415+50) | E1415: =IF(A1415=0,"",A1415&V1415&D1415&U1415) | F1415: =IF(A1415=0,"",AC1415&D1415&AD1415&A1415&Z1415&AB1415&C1415&AE1415) | U1415: d | V1415: ×t | W1415: ×t | Z1415: ( | AB1415: □ | AC1415: t | AD1415: × | AE1415: )
C1416: =IF(A1416=0,"",A1416+50) | E1416: =IF(A1416=0,"",A1416&V1416&D1416&U1416) | F1416: =IF(A1416=0,"",AC1416&D1416&AD1416&A1416&Z1416&AB1416&C1416&AE1416) | U1416: d | V1416: ×t | W1416: ×t | Z1416: ( | AB1416: □ | AC1416: t | AD1416: × | AE1416: )
C1417: =IF(A1417=0,"",A1417+50) | E1417: =IF(A1417=0,"",A1417&V1417&D1417&U1417) | F1417: =IF(A1417=0,"",AC1417&D1417&AD1417&A1417&Z1417&AB1417&C1417&AE1417) | U1417: d | V1417: ×t | W1417: ×t | Z1417: ( | AB1417: □ | AC1417: t | AD1417: × | AE1417: )
C1418: =IF(A1418=0,"",A1418+50) | E1418: =IF(A1418=0,"",A1418&V1418&D1418&U1418) | F1418: =IF(A1418=0,"",AC1418&D1418&AD1418&A1418&Z1418&AB1418&C1418&AE1418) | U1418: d | V1418: ×t | W1418: ×t | Z1418: ( | AB1418: □ | AC1418: t | AD1418: × | AE1418: )
C1419: =IF(A1419=0,"",A1419+50) | E1419: =IF(A1419=0,"",A1419&V1419&D1419&U1419) | F1419: =IF(A1419=0,"",AC1419&D1419&AD1419&A1419&Z1419&AB1419&C1419&AE1419) | U1419: d | V1419: ×t | W1419: ×t | Z1419: ( | AB1419: □ | AC1419: t | AD1419: × | AE1419: )
C1420: =IF(A1420=0,"",A1420+50) | E1420: =IF(A1420=0,"",A1420&V1420&D1420&U1420) | F1420: =IF(A1420=0,"",AC1420&D1420&AD1420&A1420&Z1420&AB1420&C1420&AE1420) | U1420: d | V1420: ×t | W1420: ×t | Z1420: ( | AB1420: □ | AC1420: t | AD1420: × | AE1420: )
C1421: =IF(A1421=0,"",A1421+50) | E1421: =IF(A1421=0,"",A1421&V1421&D1421&U1421) | F1421: =IF(A1421=0,"",AC1421&D1421&AD1421&A1421&Z1421&AB1421&C1421&AE1421) | U1421: d | V1421: ×t | W1421: ×t | Z1421: ( | AB1421: □ | AC1421: t | AD1421: × | AE1421: )
C1422: =IF(A1422=0,"",A1422+50) | E1422: =IF(A1422=0,"",A1422&V1422&D1422&U1422) | F1422: =IF(A1422=0,"",AC1422&D1422&AD1422&A1422&Z1422&AB1422&C1422&AE1422) | U1422: d | V1422: ×t | W1422: ×t | Z1422: ( | AB1422: □ | AC1422: t | AD1422: × | AE1422: )
...

Sheet 内ダイヤフラム
A1: 柱サイズ | B1: 柱板厚 | C1: 内ダイヤフラム外形サイズ | D1: 内ダイヤフラム板厚 | E1: 柱×ダイアフラム板厚 | F1: 飯尾さんの表現 | G1: 外ダイアフラム仕様 | H1: (Y1) | I1: (Y2) | J1: (Y3/Y4) | K1: (Y5) | L1: (Y6) | M1: (Y7) | O1: 通り芯(Y8) | P1: 通り芯(Y9) | Q1: 通り芯(Y10) | R1: 通り芯(Y11) | S1: 通り芯(Y12) | T1: 数量 | U1: 枚 | V1: id | W1: ×t | X1: ×t | Y1: 柱サイズ | Z1: 柱板厚 | AA1: 隣接する梁 | AB1: 内ダイヤフラム板厚 | AC1: □ | AD1: t | AE1: ×
A2: 300 | B2: 12 | C2: =IF(A2=0,"",A2-(B2*2)) -> 276 | D2: 22 | E2: =IF(A2=0,"",A2&AE2&B2&W2&D2&V2) -> 300×12×t22id | F2: =IF(A2=0,"",AD2&D2&AE2&AC2&C2) -> t22×□276 | G2: =IF(A2=0,"",C2&X2&D2) -> 276×t22 | L2: 1 | T2: =IF(SUM(G2:R2)=0,"",IF(S2="",SUM(G2:R2)&U2,SUM(G2:R2))) -> 1枚 | U2: 枚 | V2: id | W2: ×t | X2: ×t | Y2: 250 | Z2: 12 | AB2: 16 | AC2: □ | AD2: t | AE2: ×
A3: 350 | B3: 16 | C3: =IF(A3=0,"",A3-(B3*2)) -> 318 | D3: 16 | E3: =IF(A3=0,"",A3&AE3&B3&W3&D3&V3) -> 350×16×t16id | F3: =IF(A3=0,"",AD3&D3&AE3&AC3&C3) -> t16×□318 | G3: =IF(A3=0,"",C3&X3&D3) -> 318×t16 | I3: 1 | L3: 3 | M3: 1 | T3: =IF(SUM(G3:R3)=0,"",IF(S3="",SUM(G3:R3)&U3,SUM(G3:R3)-S3&U3)) -> 5枚 | U3: 枚 | V3: id | W3: ×t | X3: ×t | Y3: 300 | Z3: 16 | AB3: 19 | AC3: □ | AD3: t | AE3: ×
A4: 350 | B4: 16 | C4: =IF(A4=0,"",A4-(B4*2)) -> 318 | D4: 19 | E4: =IF(A4=0,"",A4&AE4&B4&W4&D4&V4) -> 350×16×t19id | F4: =IF(A4=0,"",AD4&D4&AE4&AC4&C4) -> t19×□318 | G4: =IF(A4=0,"",C4&X4&D4) -> 318×t19 | I4: 1 | T4: =IF(SUM(G4:R4)=0,"",IF(S4="",SUM(G4:R4)&U4,SUM(G4:R4)-S4&U4)) -> 1枚 | U4: 枚 | V4: id | W4: ×t | X4: ×t | Y4: 350 | Z4: 19 | AB4: 22 | AC4: □ | AD4: t | AE4: ×
A5: 350 | B5: 16 | C5: =IF(A5=0,"",A5-(B5*2)) -> 318 | D5: 22 | E5: =IF(A5=0,"",A5&AE5&B5&W5&D5&V5) -> 350×16×t22id | F5: =IF(A5=0,"",AD5&D5&AE5&AC5&C5) -> t22×□318 | G5: =IF(A5=0,"",C5&X5&D5) -> 318×t22 | J5: 1 | K5: 1 | M5: 2 | T5: =IF(SUM(G5:R5)=0,"",IF(S5="",SUM(G5:R5)&U5,SUM(G5:R5)-S5&U5)) -> 4枚 | U5: 枚 | V5: id | W5: ×t | X5: ×t | Y5: 400 | AB5: 32 | AC5: □ | AD5: t | AE5: ×
A6: 350 | B6: 16 | C6: =IF(A6=0,"",A6-(B6*2)) -> 318 | D6: 32 | E6: =IF(A6=0,"",A6&AE6&B6&W6&D6&V6) -> 350×16×t32id | F6: =IF(A6=0,"",AD6&D6&AE6&AC6&C6) -> t32×□318 | G6: =IF(A6=0,"",C6&X6&D6) -> 318×t32 | H6: 1 | I6: 2 | J6: 2 | K6: 5 | L6: 4 | M6: 8 | T6: =IF(SUM(G6:R6)=0,"",IF(S6="",SUM(G6:R6)&U6,SUM(G6:R6)-S6&U6)) -> 22枚 | U6: 枚 | V6: id | W6: ×t | X6: ×t | Y6: 450 | AB6: 36 | AC6: □ | AD6: t | AE6: ×
A7: 350 | B7: 16 | C7: =IF(A7=0,"",A7-(B7*2)) -> 318 | D7: 36 | E7: =IF(A7=0,"",A7&AE7&B7&W7&D7&V7) -> 350×16×t36id | F7: =IF(A7=0,"",AD7&D7&AE7&AC7&C7) -> t36×□318 | G7: =IF(A7=0,"",C7&X7&D7) -> 318×t36 | J7: 1 | T7: =IF(SUM(G7:R7)=0,"",IF(S7="",SUM(G7:R7)&U7,SUM(G7:R7)-S7&U7)) -> 1枚 | U7: 枚 | V7: id | W7: ×t | X7: ×t | Y7: 500 | AB7: 40 | AC7: □ | AD7: t | AE7: ×
A8: 350 | B8: 16 | C8: =IF(A8=0,"",A8-(B8*2)) -> 318 | D8: 40 | E8: =IF(A8=0,"",A8&AE8&B8&W8&D8&V8) -> 350×16×t40id | F8: =IF(A8=0,"",AD8&D8&AE8&AC8&C8) -> t40×□318 | G8: =IF(A8=0,"",C8&X8&D8) -> 318×t40 | H8: 1 | I8: 2 | J8: 2 | T8: =IF(SUM(G8:R8)=0,"",IF(S8="",SUM(G8:R8)&U8,SUM(G8:R8)-S8&U8)) -> 5枚 | U8: 枚 | V8: id | W8: ×t | X8: ×t | Y8: 550 | AB8: 45 | AC8: □ | AD8: t | AE8: ×
A9: 350 | B9: 12 | C9: =IF(A9=0,"",A9-(B9*2)) -> 326 | D9: 19 | E9: =IF(A9=0,"",A9&AE9&B9&W9&D9&V9) -> 350×12×t19id | F9: =IF(A9=0,"",AD9&D9&AE9&AC9&C9) -> t19×□326 | G9: =IF(A9=0,"",C9&X9&D9) -> 326×t19 | T9: =IF(SUM(G9:R9)=0,"",IF(S9="",SUM(G9:R9)&U9,SUM(G9:R9)-S9&U9)) | U9: 枚 | V9: id | W9: ×t | X9: ×t | Y9: 600 | AB9: 50 | AC9: □ | AD9: t | AE9: ×
A10: 400 | B10: 16 | C10: =IF(A10=0,"",A10-(B10*2)) -> 368 | D10: 22 | E10: =IF(A10=0,"",A10&AE10&B10&W10&D10&V10) -> 400×16×t22id | F10: =IF(A10=0,"",AD10&D10&AE10&AC10&C10) -> t22×□368 | G10: =IF(A10=0,"",C10&X10&D10) -> 368×t22 | J10: 1 | K10: 1 | T10: =IF(SUM(G10:R10)=0,"",IF(S10="",SUM(G10:R10)&U10,SUM(G10:R10)-S10&U10)) -> 2枚 | U10: 枚 | V10: id | W10: ×t | X10: ×t | AC10: □ | AD10: t | AE10: ×
A11: 400 | B11: 16 | C11: =IF(A11=0,"",A11-(B11*2)) -> 368 | D11: 32 | E11: =IF(A11=0,"",A11&AE11&B11&W11&D11&V11) -> 400×16×t32id | F11: =IF(A11=0,"",AD11&D11&AE11&AC11&C11) -> t32×□368 | G11: =IF(A11=0,"",C11&X11&D11) -> 368×t32 | M11: 1 | T11: =IF(SUM(G11:R11)=0,"",IF(S11="",SUM(G11:R11)&U11,SUM(G11:R11)-S11&U11)) -> 1枚 | U11: 枚 | V11: id | W11: ×t | X11: ×t | AC11: □ | AD11: t | AE11: ×
A12: 400 | B12: 16 | C12: =IF(A12=0,"",A12-(B12*2)) -> 368 | D12: 40 | E12: =IF(A12=0,"",A12&AE12&B12&W12&D12&V12) -> 400×16×t40id | F12: =IF(A12=0,"",AD12&D12&AE12&AC12&C12) -> t40×□368 | G12: =IF(A12=0,"",C12&X12&D12) -> 368×t40 | J12: 2 | K12: 1 | T12: =IF(SUM(G12:R12)=0,"",IF(S12="",SUM(G12:R12)&U12,SUM(G12:R12)-S12&U12)) -> 3枚 | U12: 枚 | V12: id | W12: ×t | X12: ×t | AC12: □ | AD12: t | AE12: ×
A13: 400 | B13: 16 | C13: =IF(A13=0,"",A13-(B13*2)) -> 368 | D13: 45 | E13: =IF(A13=0,"",A13&AE13&B13&W13&D13&V13) -> 400×16×t45id | F13: =IF(A13=0,"",AD13&D13&AE13&AC13&C13) -> t45×□368 | G13: =IF(A13=0,"",C13&X13&D13) -> 368×t45 | J13: 1 | T13: =IF(SUM(G13:R13)=0,"",IF(S13="",SUM(G13:R13)&U13,SUM(G13:R13)-S13&U13)) -> 1枚 | U13: 枚 | V13: id | W13: ×t | X13: ×t | AC13: □ | AD13: t | AE13: ×
A14: 450 | B14: 16 | C14: =IF(A14=0,"",A14-(B14*2)) -> 418 | D14: 16 | E14: =IF(A14=0,"",A14&AE14&B14&W14&D14&V14) -> 450×16×t16id | F14: =IF(A14=0,"",AD14&D14&AE14&AC14&C14) -> t16×□418 | G14: =IF(A14=0,"",C14&X14&D14) -> 418×t16 | I14: 2 | T14: =IF(SUM(G14:R14)=0,"",IF(S14="",SUM(G14:R14)&U14,SUM(G14:R14)-S14&U14)) -> 2枚 | U14: 枚 | V14: id | W14: ×t | X14: ×t | AC14: □ | AD14: t | AE14: ×
A15: 450 | B15: 16 | C15: =IF(A15=0,"",A15-(B15*2)) -> 418 | D15: 22 | E15: =IF(A15=0,"",A15&AE15&B15&W15&D15&V15) -> 450×16×t22id | F15: =IF(A15=0,"",AD15&D15&AE15&AC15&C15) -> t22×□418 | G15: =IF(A15=0,"",C15&X15&D15) -> 418×t22 | T15: =IF(SUM(G15:R15)=0,"",IF(S15="",SUM(G15:R15)&U15,SUM(G15:R15)-S15&U15)) | U15: 枚 | V15: id | W15: ×t | X15: ×t | AC15: □ | AD15: t | AE15: ×
A16: 450 | B16: 16 | C16: =IF(A16=0,"",A16-(B16*2)) -> 418 | D16: 32 | E16: =IF(A16=0,"",A16&AE16&B16&W16&D16&V16) -> 450×16×t32id | F16: =IF(A16=0,"",AD16&D16&AE16&AC16&C16) -> t32×□418 | G16: =IF(A16=0,"",C16&X16&D16) -> 418×t32 | I16: 1 | T16: =IF(SUM(G16:R16)=0,"",IF(S16="",SUM(G16:R16)&U16,SUM(G16:R16)-S16&U16)) -> 1枚 | U16: 枚 | V16: id | W16: ×t | X16: ×t | AC16: □ | AD16: t | AE16: ×
A17: 450 | B17: 16 | C17: =IF(A17=0,"",A17-(B17*2)) -> 418 | D17: 40 | E17: =IF(A17=0,"",A17&AE17&B17&W17&D17&V17) -> 450×16×t40id | F17: =IF(A17=0,"",AD17&D17&AE17&AC17&C17) -> t40×□418 | G17: =IF(A17=0,"",C17&X17&D17) -> 418×t40 | I17: 1 | J17: 3 | T17: =IF(SUM(G17:R17)=0,"",IF(S17="",SUM(G17:R17)&U17,SUM(G17:R17)-S17&U17)) -> 4枚 | U17: 枚 | V17: id | W17: ×t | X17: ×t | AC17: □ | AD17: t | AE17: ×
A18: 450 | B18: 19 | C18: =IF(A18=0,"",A18-(B18*2)) -> 412 | D18: 16 | E18: =IF(A18=0,"",A18&AE18&B18&W18&D18&V18) -> 450×19×t16id | F18: =IF(A18=0,"",AD18&D18&AE18&AC18&C18) -> t16×□412 | G18: =IF(A18=0,"",C18&X18&D18) -> 412×t16 | I18: 2 | L18: 1 | T18: =IF(SUM(G18:R18)=0,"",IF(S18="",SUM(G18:R18)&U18,SUM(G18:R18)-S18&U18)) -> 3枚 | U18: 枚 | V18: id | W18: ×t | X18: ×t | AC18: □ | AD18: t | AE18: ×
A19: 450 | B19: 19 | C19: =IF(A19=0,"",A19-(B19*2)) -> 412 | D19: 22 | E19: =IF(A19=0,"",A19&AE19&B19&W19&D19&V19) -> 450×19×t22id | F19: =IF(A19=0,"",AD19&D19&AE19&AC19&C19) -> t22×□412 | G19: =IF(A19=0,"",C19&X19&D19) -> 412×t22 | T19: =IF(SUM(G19:R19)=0,"",IF(S19="",SUM(G19:R19)&U19,SUM(G19:R19)-S19&U19)) | U19: 枚 | V19: id | W19: ×t | X19: ×t | AC19: □ | AD19: t | AE19: ×
A20: 450 | B20: 19 | C20: =IF(A20=0,"",A20-(B20*2)) -> 412 | D20: 19 | E20: =IF(A20=0,"",A20&AE20&B20&W20&D20&V20) -> 450×19×t19id | F20: =IF(A20=0,"",AD20&D20&AE20&AC20&C20) -> t19×□412 | G20: =IF(A20=0,"",C20&X20&D20) -> 412×t19 | K20: 2 | T20: =IF(SUM(G20:R20)=0,"",IF(S20="",SUM(G20:R20)&U20,SUM(G20:R20)-S20&U20)) -> 2枚 | U20: 枚 | V20: id | W20: ×t | X20: ×t | AC20: □ | AD20: t | AE20: ×
A21: 450 | B21: 19 | C21: =IF(A21=0,"",A21-(B21*2)) -> 412 | D21: 32 | E21: =IF(A21=0,"",A21&AE21&B21&W21&D21&V21) -> 450×19×t32id | F21: =IF(A21=0,"",AD21&D21&AE21&AC21&C21) -> t32×□412 | G21: =IF(A21=0,"",C21&X21&D21) -> 412×t32 | H21: 5 | I21: 6 | J21: 1 | K21: 9 | L21: 8 | M21: 1 | T21: =IF(SUM(G21:R21)=0,"",IF(S21="",SUM(G21:R21)&U21,SUM(G21:R21)-S21&U21)) -> 30枚 | U21: 枚 | V21: id | W21: ×t | X21: ×t | AC21: □ | AD21: t | AE21: ×
A22: 450 | B22: 19 | C22: =IF(A22=0,"",A22-(B22*2)) -> 412 | D22: 36 | E22: =IF(A22=0,"",A22&AE22&B22&W22&D22&V22) -> 450×19×t36id | F22: =IF(A22=0,"",AD22&D22&AE22&AC22&C22) -> t36×□412 | G22: =IF(A22=0,"",C22&X22&D22) -> 412×t36 | H22: 1 | I22: 4 | L22: 5 | T22: =IF(SUM(G22:R22)=0,"",IF(S22="",SUM(G22:R22)&U22,SUM(G22:R22)-S22&U22)) -> 10枚 | U22: 枚 | V22: id | W22: ×t | X22: ×t | AC22: □ | AD22: t | AE22: ×
A23: 450 | B23: 19 | C23: =IF(A23=0,"",A23-(B23*2)) -> 412 | D23: 40 | E23: =IF(A23=0,"",A23&AE23&B23&W23&D23&V23) -> 450×19×t40id | F23: =IF(A23=0,"",AD23&D23&AE23&AC23&C23) -> t40×□412 | G23: =IF(A23=0,"",C23&X23&D23) -> 412×t40 | H23: 1 | I23: 2 | J23: 1 | K23: 4 | M23: 2 | T23: =IF(SUM(G23:R23)=0,"",IF(S23="",SUM(G23:R23)&U23,SUM(G23:R23)-S23&U23)) -> 10枚 | U23: 枚 | V23: id | W23: ×t | X23: ×t | AC23: □ | AD23: t | AE23: ×
A24: 450 | B24: 19 | C24: =IF(A24=0,"",A24-(B24*2)) -> 412 | D24: 45 | E24: =IF(A24=0,"",A24&AE24&B24&W24&D24&V24) -> 450×19×t45id | F24: =IF(A24=0,"",AD24&D24&AE24&AC24&C24) -> t45×□412 | G24: =IF(A24=0,"",C24&X24&D24) -> 412×t45 | T24: =IF(SUM(G24:R24)=0,"",IF(S24="",SUM(G24:R24)&U24,SUM(G24:R24)-S24&U24)) | U24: 枚 | V24: id | W24: ×t | X24: ×t | AC24: □ | AD24: t | AE24: ×
A25: 500 | B25: 19 | C25: =IF(A25=0,"",A25-(B25*2)) -> 462 | D25: 45 | E25: =IF(A25=0,"",A25&AE25&B25&W25&D25&V25) -> 500×19×t45id | F25: =IF(A25=0,"",AD25&D25&AE25&AC25&C25) -> t45×□462 | G25: =IF(A25=0,"",C25&X25&D25) -> 462×t45 | H25: 1 | I25: 1 | T25: =IF(SUM(G25:R25)=0,"",IF(S25="",SUM(G25:R25)&U25,SUM(G25:R25)-S25&U25)) -> 2枚 | U25: 枚 | V25: id | W25: ×t | X25: ×t | AC25: □ | AD25: t | AE25: ×
A26: 500 | B26: 19 | C26: =IF(A26=0,"",A26-(B26*2)) -> 462 | D26: 19 | E26: =IF(A26=0,"",A26&AE26&B26&W26&D26&V26) -> 500×19×t19id | F26: =IF(A26=0,"",AD26&D26&AE26&AC26&C26) -> t19×□462 | G26: =IF(A26=0,"",C26&X26&D26) -> 462×t19 | I26: 1 | T26: =IF(SUM(G26:R26)=0,"",IF(S26="",SUM(G26:R26)&U26,SUM(G26:R26)-S26&U26)) -> 1枚 | U26: 枚 | V26: id | W26: ×t | X26: ×t | AC26: □ | AD26: t | AE26: ×
A27: 500 | B27: 19 | C27: =IF(A27=0,"",A27-(B27*2)) -> 462 | D27: 22 | E27: =IF(A27=0,"",A27&AE27&B27&W27&D27&V27) -> 500×19×t22id | F27: =IF(A27=0,"",AD27&D27&AE27&AC27&C27) -> t22×□462 | G27: =IF(A27=0,"",C27&X27&D27) -> 462×t22 | I27: 1 | T27: =IF(SUM(G27:R27)=0,"",IF(S27="",SUM(G27:R27)&U27,SUM(G27:R27)-S27&U27)) -> 1枚 | U27: 枚 | V27: id | W27: ×t | X27: ×t | AC27: □ | AD27: t | AE27: ×
A28: 500 | B28: 19 | C28: =IF(A28=0,"",A28-(B28*2)) -> 462 | D28: 36 | E28: =IF(A28=0,"",A28&AE28&B28&W28&D28&V28) -> 500×19×t36id | F28: =IF(A28=0,"",AD28&D28&AE28&AC28&C28) -> t36×□462 | G28: =IF(A28=0,"",C28&X28&D28) -> 462×t36 | H28: 1 | I28: 1 | J28: 2 | K28: 1 | T28: =IF(SUM(G28:R28)=0,"",IF(S28="",SUM(G28:R28)&U28,SUM(G28:R28)-S28&U28)) -> 5枚 | U28: 枚 | V28: id | W28: ×t | X28: ×t | AC28: □ | AD28: t | AE28: ×
A29: 500 | B29: 19 | C29: =IF(A29=0,"",A29-(B29*2)) -> 462 | D29: 40 | E29: =IF(A29=0,"",A29&AE29&B29&W29&D29&V29) -> 500×19×t40id | F29: =IF(A29=0,"",AD29&D29&AE29&AC29&C29) -> t40×□462 | G29: =IF(A29=0,"",C29&X29&D29) -> 462×t40 | H29: 1 | T29: =IF(SUM(G29:R29)=0,"",IF(S29="",SUM(G29:R29)&U29,SUM(G29:R29)-S29&U29)) -> 1枚 | U29: 枚 | V29: id | W29: ×t | X29: ×t | AC29: □ | AD29: t | AE29: ×
A30: 500 | B30: 19 | C30: =IF(A30=0,"",A30-(B30*2)) -> 462 | D30: 45 | E30: =IF(A30=0,"",A30&AE30&B30&W30&D30&V30) -> 500×19×t45id | F30: =IF(A30=0,"",AD30&D30&AE30&AC30&C30) -> t45×□462 | G30: =IF(A30=0,"",C30&X30&D30) -> 462×t45 | H30: 1 | I30: 1 | T30: =IF(SUM(G30:R30)=0,"",IF(S30="",SUM(G30:R30)&U30,SUM(G30:R30)-S30&U30)) -> 2枚 | U30: 枚 | V30: id | W30: ×t | X30: ×t | AC30: □ | AD30: t | AE30: ×
C31: =IF(A31=0,"",A31-(B31*2)) | E31: =IF(A31=0,"",A31&AE31&B31&W31&D31&V31) | G31: =IF(A31=0,"",C31&X31&D31) | T31: =IF(SUM(H31:S31)=0,"",SUM(H31:S31)) | U31: 枚 | V31: id | W31: ×t | X31: ×t | AC31: □ | AD31: t | AE31: ×
C32: =IF(A32=0,"",A32-(B32*2)) | E32: =IF(A32=0,"",A32&AE32&B32&W32&D32&V32) | G32: =IF(A32=0,"",C32&X32&D32) | T32: =IF(SUM(H32:S32)=0,"",SUM(H32:S32)) | U32: 枚 | V32: id | W32: ×t | X32: ×t | AC32: □ | AD32: t | AE32: ×
C33: =IF(A33=0,"",A33-(B33*2)) | E33: =IF(A33=0,"",A33&AE33&B33&W33&D33&V33) | G33: =IF(A33=0,"",C33&X33&D33) | T33: =IF(SUM(H33:S33)=0,"",SUM(H33:S33)) | U33: 枚 | V33: id | W33: ×t | X33: ×t | AC33: □ | AD33: t | AE33: ×
C34: =IF(A34=0,"",A34-(B34*2)) | E34: =IF(A34=0,"",A34&AE34&B34&W34&D34&V34) | G34: =IF(A34=0,"",C34&X34&D34) | T34: =IF(SUM(H34:S34)=0,"",SUM(H34:S34)) | U34: 枚 | V34: id | W34: ×t | X34: ×t | AC34: □ | AD34: t | AE34: ×
C35: =IF(A35=0,"",A35-(B35*2)) | E35: =IF(A35=0,"",A35&AE35&B35&W35&D35&V35) | G35: =IF(A35=0,"",C35&X35&D35) | T35: =IF(SUM(H35:S35)=0,"",SUM(H35:S35)) | U35: 枚 | V35: id | W35: ×t | X35: ×t | AC35: □ | AD35: t | AE35: ×
C36: =IF(A36=0,"",A36-(B36*2)) | E36: =IF(A36=0,"",A36&AE36&B36&W36&D36&V36) | G36: =IF(A36=0,"",C36&X36&D36) | T36: =IF(SUM(H36:S36)=0,"",SUM(H36:S36)) | U36: 枚 | V36: id | W36: ×t | X36: ×t | AC36: □ | AD36: t | AE36: ×
C37: =IF(A37=0,"",A37-(B37*2)) | E37: =IF(A37=0,"",A37&AE37&B37&W37&D37&V37) | G37: =IF(A37=0,"",C37&X37&D37) | T37: =IF(SUM(H37:S37)=0,"",SUM(H37:S37)) | U37: 枚 | V37: id | W37: ×t | X37: ×t | AC37: □ | AD37: t | AE37: ×
C38: =IF(A38=0,"",A38-(B38*2)) | E38: =IF(A38=0,"",A38&AE38&B38&W38&D38&V38) | G38: =IF(A38=0,"",C38&X38&D38) | T38: =IF(SUM(H38:S38)=0,"",SUM(H38:S38)) | U38: 枚 | V38: id | W38: ×t | X38: ×t | AC38: □ | AD38: t | AE38: ×
C39: =IF(A39=0,"",A39-(B39*2)) | E39: =IF(A39=0,"",A39&AE39&B39&W39&D39&V39) | G39: =IF(A39=0,"",C39&X39&D39) | T39: =IF(SUM(H39:S39)=0,"",SUM(H39:S39)) | U39: 枚 | V39: id | W39: ×t | X39: ×t | AC39: □ | AD39: t | AE39: ×
C40: =IF(A40=0,"",A40-(B40*2)) | E40: =IF(A40=0,"",A40&AE40&B40&W40&D40&V40) | G40: =IF(A40=0,"",C40&X40&D40) | T40: =IF(SUM(H40:S40)=0,"",SUM(H40:S40)) | U40: 枚 | V40: id | W40: ×t | X40: ×t | AC40: □ | AD40: t | AE40: ×
...
