Workbook
Name _4432mm×3632mm×6mm×7.85Kg__100万_758.17Kg: 計算式内訳!$C$2

Sheet 四角板専用
A1: 参照図 | B1: 使用部位 | C1: 使用部材 | D1: 重量定数 | E1: 長さ(mm) | F1: 弧長(mm) | G1: Φ(ドーナツ)mm | H1: ドーナツ角度 | I1: ドーナツ幅(mm)or90° | J1: 幅(mm) | K1: 厚み(mm) | L1: 数量 | M1: 重量 | N1: 付属品(Kg) | O1: 小計 | T1: 総計シート計算用 | AA1: 部材リスト | AB1: 部材重量定数リスト | AC1: 単位
A2: 本体 | B2: 天板 | C2: SS400 | D2: =IF(ISNA(VLOOKUP(四角板専用!C2,四角板専用!AA$1:AC$9999,2,FALSE)),0,VLOOKUP(四角板専用!C2,四角板専用!AA$1:AC$9999,2,FALSE)) -> 7.85 | E2: 4432 | F2: =IF(G2=0,0,G2*PI()*(1-(H2/360))) -> 0 | H2: =IF(G2=0,0,IF(I2="90°",270,ASIN((I2/2)/(G2/2))*180/PI()*2)) -> 0 | J2: 3632 | K2: 6 | L2: 1 | M2: =IF(D2+E2+F2+N2=0,"",IF(E2=0,(D2*F2*J2*K2*L2)/1000000+N2,(D2*E2*J2*K2*L2)/1000000+N2)-IF(COUNTIFS(B$1:B2,B2,A$1:A2,A2)>1,0,SUMIFS(四角板抜き穴専用!Q:Q,四角板抜き穴専用!A:A,四角板専用!A2,四角板抜き穴専用!B:B,B2))) -> 758.16983 | O2: =IF(O1>0,0,IF(A3&B3=A2&B2,0,IF(COUNTIFS(A:A,A2,B:B,B2)>=2,SUMIFS(M:M,A:A,A2,B:B,B2),0))) -> 0 | T2: =M2 -> 758.16983 | AA2: SS400 | AB2: 7.85 | AC2: g/cm³
A3: 本体 | B3: 側板 | C3: SS400 | D3: =IF(ISNA(VLOOKUP(四角板専用!C3,四角板専用!AA$1:AC$9999,2,FALSE)),0,VLOOKUP(四角板専用!C3,四角板専用!AA$1:AC$9999,2,FALSE)) -> 7.85 | E3: 4312 | F3: =IF(G3=0,0,G3*PI()*(1-(H3/360))) -> 0 | H3: =IF(G3=0,0,IF(I3="90°",270,ASIN((I3/2)/(G3/2))*180/PI()*2)) -> 0 | J3: 2480 | K3: 6 | L3: 2 | M3: =IF(D3+E3+F3+N3=0,"",IF(E3=0,(D3*F3*J3*K3*L3)/1000000+N3,(D3*E3*J3*K3*L3)/1000000+N3)-IF(COUNTIFS(B$1:B3,B3,A$1:A3,A3)>1,0,SUMIFS(四角板抜き穴専用!Q:Q,四角板抜き穴専用!A:A,四角板専用!A3,四角板抜き穴専用!B:B,B3))) -> 1007.3522 | O3: =IF(O2>0,0,IF(A4&B4=A3&B3,0,IF(COUNTIFS(A:A,A3,B:B,B3)>=2,SUMIFS(M:M,A:A,A3,B:B,B3),0))) -> 0 | T3: =M3 -> 1007.3522 | AA3: SUS304 | AB3: 7.93 | AC3: g/cm³
A4: 本体 | B4: 側板 | C4: SS400 | D4: =IF(ISNA(VLOOKUP(四角板専用!C4,四角板専用!AA$1:AC$9999,2,FALSE)),0,VLOOKUP(四角板専用!C4,四角板専用!AA$1:AC$9999,2,FALSE)) -> 7.85 | E4: 3512 | F4: =IF(G4=0,0,G4*PI()*(1-(H4/360))) -> 0 | H4: =IF(G4=0,0,IF(I4="90°",270,ASIN((I4/2)/(G4/2))*180/PI()*2)) -> 0 | J4: 2500 | K4: 6 | L4: 2 | M4: =IF(D4+E4+F4+N4=0,"",IF(E4=0,(D4*F4*J4*K4*L4)/1000000+N4,(D4*E4*J4*K4*L4)/1000000+N4)-IF(COUNTIFS(B$1:B4,B4,A$1:A4,A4)>1,0,SUMIFS(四角板抜き穴専用!Q:Q,四角板抜き穴専用!A:A,四角板専用!A4,四角板抜き穴専用!B:B,B4))) -> 827.076 | O4: =IF(O3>0,0,IF(A5&B5=A4&B4,0,IF(COUNTIFS(A:A,A4,B:B,B4)>=2,SUMIFS(M:M,A:A,A4,B:B,B4),0))) -> 1834.4282 | T4: =M4 -> 827.076 | AA4: 不明 | AC4: 不明
A5: 本体 | B5: 底板 | C5: SS400 | D5: =IF(ISNA(VLOOKUP(四角板専用!C5,四角板専用!AA$1:AC$9999,2,FALSE)),0,VLOOKUP(四角板専用!C5,四角板専用!AA$1:AC$9999,2,FALSE)) -> 7.85 | E5: 4500 | F5: =IF(G5=0,0,G5*PI()*(1-(H5/360))) -> 0 | H5: =IF(G5=0,0,IF(I5="90°",270,ASIN((I5/2)/(G5/2))*180/PI()*2)) -> 0 | J5: 3700 | K5: 9 | L5: 1 | M5: =IF(D5+E5+F5+N5=0,"",IF(E5=0,(D5*F5*J5*K5*L5)/1000000+N5,(D5*E5*J5*K5*L5)/1000000+N5)-IF(COUNTIFS(B$1:B5,B5,A$1:A5,A5)>1,0,SUMIFS(四角板抜き穴専用!Q:Q,四角板抜き穴専用!A:A,四角板専用!A5,四角板抜き穴専用!B:B,B5))) -> 1176.3225 | O5: =IF(O4>0,0,IF(A6&B6=A5&B5,0,IF(COUNTIFS(A:A,A5,B:B,B5)>=2,SUMIFS(M:M,A:A,A5,B:B,B5),0))) -> 0 | T5: =M5 -> 1176.3225
A6: 本体 | B6: G詳細 | C6: SS400 | D6: =IF(ISNA(VLOOKUP(四角板専用!C6,四角板専用!AA$1:AC$9999,2,FALSE)),0,VLOOKUP(四角板専用!C6,四角板専用!AA$1:AC$9999,2,FALSE)) -> 7.85 | E6: 150 | F6: =IF(G6=0,0,G6*PI()*(1-(H6/360))) -> 0 | H6: =IF(G6=0,0,IF(I6="90°",270,ASIN((I6/2)/(G6/2))*180/PI()*2)) -> 0 | J6: 75 | K6: 16 | L6: 20 | M6: =IF(D6+E6+F6+N6=0,"",IF(E6=0,(D6*F6*J6*K6*L6)/1000000+N6,(D6*E6*J6*K6*L6)/1000000+N6)-IF(COUNTIFS(B$1:B6,B6,A$1:A6,A6)>1,0,SUMIFS(四角板抜き穴専用!Q:Q,四角板抜き穴専用!A:A,四角板専用!A6,四角板抜き穴専用!B:B,B6))) -> 28.26 | O6: =IF(O5>0,0,IF(A7&B7=A6&B6,0,IF(COUNTIFS(A:A,A6,B:B,B6)>=2,SUMIFS(M:M,A:A,A6,B:B,B6),0))) -> 0 | T6: =M6 -> 28.26
A7: 本体 | B7: H詳細 | C7: SS400 | D7: =IF(ISNA(VLOOKUP(四角板専用!C7,四角板専用!AA$1:AC$9999,2,FALSE)),0,VLOOKUP(四角板専用!C7,四角板専用!AA$1:AC$9999,2,FALSE)) -> 7.85 | E7: 170 | F7: =IF(G7=0,0,G7*PI()*(1-(H7/360))) -> 0 | H7: =IF(G7=0,0,IF(I7="90°",270,ASIN((I7/2)/(G7/2))*180/PI()*2)) -> 0 | J7: 75 | K7: 16 | L7: 8 | M7: =IF(D7+E7+F7+N7=0,"",IF(E7=0,(D7*F7*J7*K7*L7)/1000000+N7,(D7*E7*J7*K7*L7)/1000000+N7)-IF(COUNTIFS(B$1:B7,B7,A$1:A7,A7)>1,0,SUMIFS(四角板抜き穴専用!Q:Q,四角板抜き穴専用!A:A,四角板専用!A7,四角板抜き穴専用!B:B,B7))) -> 12.8112 | O7: =IF(O6>0,0,IF(A8&B8=A7&B7,0,IF(COUNTIFS(A:A,A7,B:B,B7)>=2,SUMIFS(M:M,A:A,A7,B:B,B7),0))) -> 0 | T7: =M7 -> 12.8112
A8: 本体 | B8: 吊金具 | C8: SS400 | D8: =IF(ISNA(VLOOKUP(四角板専用!C8,四角板専用!AA$1:AC$9999,2,FALSE)),0,VLOOKUP(四角板専用!C8,四角板専用!AA$1:AC$9999,2,FALSE)) -> 7.85 | E8: 150 | F8: =IF(G8=0,0,G8*PI()*(1-(H8/360))) -> 0 | H8: =IF(G8=0,0,IF(I8="90°",270,ASIN((I8/2)/(G8/2))*180/PI()*2)) -> 0 | J8: 100 | K8: 12 | L8: 8 | M8: =IF(D8+E8+F8+N8=0,"",IF(E8=0,(D8*F8*J8*K8*L8)/1000000+N8,(D8*E8*J8*K8*L8)/1000000+N8)-IF(COUNTIFS(B$1:B8,B8,A$1:A8,A8)>1,0,SUMIFS(四角板抜き穴専用!Q:Q,四角板抜き穴専用!A:A,四角板専用!A8,四角板抜き穴専用!B:B,B8))) -> 11.304 | O8: =IF(O7>0,0,IF(A9&B9=A8&B8,0,IF(COUNTIFS(A:A,A8,B:B,B8)>=2,SUMIFS(M:M,A:A,A8,B:B,B8),0))) -> 0 | T8: =M8 -> 11.304
A9: 本体 | B9: 銘板取付座 | C9: SS400 | D9: =IF(ISNA(VLOOKUP(四角板専用!C9,四角板専用!AA$1:AC$9999,2,FALSE)),0,VLOOKUP(四角板専用!C9,四角板専用!AA$1:AC$9999,2,FALSE)) -> 7.85 | E9: 215 | F9: =IF(G9=0,0,G9*PI()*(1-(H9/360))) -> 0 | H9: =IF(G9=0,0,IF(I9="90°",270,ASIN((I9/2)/(G9/2))*180/PI()*2)) -> 0 | J9: 175 | K9: 4.5 | L9: 1 | M9: =IF(D9+E9+F9+N9=0,"",IF(E9=0,(D9*F9*J9*K9*L9)/1000000+N9,(D9*E9*J9*K9*L9)/1000000+N9)-IF(COUNTIFS(B$1:B9,B9,A$1:A9,A9)>1,0,SUMIFS(四角板抜き穴専用!Q:Q,四角板抜き穴専用!A:A,四角板専用!A9,四角板抜き穴専用!B:B,B9))) -> 1.3291031 | O9: =IF(O8>0,0,IF(A10&B10=A9&B9,0,IF(COUNTIFS(A:A,A9,B:B,B9)>=2,SUMIFS(M:M,A:A,A9,B:B,B9),0))) -> 0 | T9: =M9 -> 1.3291031
A10: 本体 | B10: 銘板取付座 | C10: SS400 | D10: =IF(ISNA(VLOOKUP(四角板専用!C10,四角板専用!AA$1:AC$9999,2,FALSE)),0,VLOOKUP(四角板専用!C10,四角板専用!AA$1:AC$9999,2,FALSE)) -> 7.85 | E10: 175 | F10: =IF(G10=0,0,G10*PI()*(1-(H10/360))) -> 0 | H10: =IF(G10=0,0,IF(I10="90°",270,ASIN((I10/2)/(G10/2))*180/PI()*2)) -> 0 | J10: 50 | K10: 4.5 | L10: 2 | M10: =IF(D10+E10+F10+N10=0,"",IF(E10=0,(D10*F10*J10*K10*L10)/1000000+N10,(D10*E10*J10*K10*L10)/1000000+N10)-IF(COUNTIFS(B$1:B10,B10,A$1:A10,A10)>1,0,SUMIFS(四角板抜き穴専用!Q:Q,四角板抜き穴専用!A:A,四角板専用!A10,四角板抜き穴専用!B:B,B10))) -> 0.6181875 | O10: =IF(O9>0,0,IF(A11&B11=A10&B10,0,IF(COUNTIFS(A:A,A10,B:B,B10)>=2,SUMIFS(M:M,A:A,A10,B:B,B10),0))) -> 1.9472906 | T10: =M10 -> 0.6181875
A11: ノズル他詳細 | B11: N-7 | C11: SS400 | D11: =IF(ISNA(VLOOKUP(四角板専用!C11,四角板専用!AA$1:AC$9999,2,FALSE)),0,VLOOKUP(四角板専用!C11,四角板専用!AA$1:AC$9999,2,FALSE)) -> 7.85 | E11: 133.7 | F11: =IF(G11=0,0,G11*PI()*(1-(H11/360))) -> 0 | H11: =IF(G11=0,0,IF(I11="90°",270,ASIN((I11/2)/(G11/2))*180/PI()*2)) -> 0 | J11: 267.4 | K11: 6 | L11: 1 | M11: =IF(D11+E11+F11+N11=0,"",IF(E11=0,(D11*F11*J11*K11*L11)/1000000+N11,(D11*E11*J11*K11*L11)/1000000+N11)-IF(COUNTIFS(B$1:B11,B11,A$1:A11,A11)>1,0,SUMIFS(四角板抜き穴専用!Q:Q,四角板抜き穴専用!A:A,四角板専用!A11,四角板抜き穴専用!B:B,B11))) -> 1.68389 | O11: =IF(O10>0,0,IF(A12&B12=A11&B11,0,IF(COUNTIFS(A:A,A11,B:B,B11)>=2,SUMIFS(M:M,A:A,A11,B:B,B11),0))) -> 0 | T11: =M11 -> 1.68389
A12: ノズル他詳細 | B12: M-1蓋 | C12: SS400 | D12: =IF(ISNA(VLOOKUP(四角板専用!C12,四角板専用!AA$1:AC$9999,2,FALSE)),0,VLOOKUP(四角板専用!C12,四角板専用!AA$1:AC$9999,2,FALSE)) -> 7.85 | E12: 325 | F12: =IF(G12=0,0,G12*PI()*(1-(H12/360))) -> 0 | H12: =IF(G12=0,0,IF(I12="90°",270,ASIN((I12/2)/(G12/2))*180/PI()*2)) -> 0 | J12: 50 | K12: 9 | L12: 2 | M12: =IF(D12+E12+F12+N12=0,"",IF(E12=0,(D12*F12*J12*K12*L12)/1000000+N12,(D12*E12*J12*K12*L12)/1000000+N12)-IF(COUNTIFS(B$1:B12,B12,A$1:A12,A12)>1,0,SUMIFS(四角板抜き穴専用!Q:Q,四角板抜き穴専用!A:A,四角板専用!A12,四角板抜き穴専用!B:B,B12))) -> 2.296125 | O12: =IF(O11>0,0,IF(A13&B13=A12&B12,0,IF(COUNTIFS(A:A,A12,B:B,B12)>=2,SUMIFS(M:M,A:A,A12,B:B,B12),0))) -> 0 | T12: =M12 -> 2.296125
A13: ノズル他詳細 | B13: M-1蓋 | C13: SS400 | D13: =IF(ISNA(VLOOKUP(四角板専用!C13,四角板専用!AA$1:AC$9999,2,FALSE)),0,VLOOKUP(四角板専用!C13,四角板専用!AA$1:AC$9999,2,FALSE)) -> 7.85 | E13: 37 | F13: =IF(G13=0,0,G13*PI()*(1-(H13/360))) -> 0 | H13: =IF(G13=0,0,IF(I13="90°",270,ASIN((I13/2)/(G13/2))*180/PI()*2)) -> 0 | J13: 50 | K13: 9 | L13: 2 | M13: =IF(D13+E13+F13+N13=0,"",IF(E13=0,(D13*F13*J13*K13*L13)/1000000+N13,(D13*E13*J13*K13*L13)/1000000+N13)-IF(COUNTIFS(B$1:B13,B13,A$1:A13,A13)>1,0,SUMIFS(四角板抜き穴専用!Q:Q,四角板抜き穴専用!A:A,四角板専用!A13,四角板抜き穴専用!B:B,B13))) -> 0.261405 | O13: =IF(O12>0,0,IF(A14&B14=A13&B13,0,IF(COUNTIFS(A:A,A13,B:B,B13)>=2,SUMIFS(M:M,A:A,A13,B:B,B13),0))) -> 2.55753 | T13: =M13 -> 0.261405
A14: ノズル他詳細 | B14: M-1受 | C14: SS400 | D14: =IF(ISNA(VLOOKUP(四角板専用!C14,四角板専用!AA$1:AC$9999,2,FALSE)),0,VLOOKUP(四角板専用!C14,四角板専用!AA$1:AC$9999,2,FALSE)) -> 7.85 | F14: =IF(G14=0,0,G14*PI()*(1-(H14/360))) -> 1903.8051 | G14: 606 | H14: =IF(G14=0,0,IF(I14="90°",270,ASIN((I14/2)/(G14/2))*180/PI()*2)) -> 0 | J14: 365 | K14: 6 | L14: 1 | M14: =IF(D14+E14+F14+N14=0,"",IF(E14=0,(D14*F14*J14*K14*L14)/1000000+N14,(D14*E14*J14*K14*L14)/1000000+N14)-IF(COUNTIFS(B$1:B14,B14,A$1:A14,A14)>1,0,SUMIFS(四角板抜き穴専用!Q:Q,四角板抜き穴専用!A:A,四角板専用!A14,四角板抜き穴専用!B:B,B14))) -> 32.729266 | O14: =IF(O13>0,0,IF(A15&B15=A14&B14,0,IF(COUNTIFS(A:A,A14,B:B,B14)>=2,SUMIFS(M:M,A:A,A14,B:B,B14),0))) -> 0 | T14: =M14 -> 32.729266
A15: ノズル他詳細 | B15: 落下防止 | C15: SUS304 | D15: =IF(ISNA(VLOOKUP(四角板専用!C15,四角板専用!AA$1:AC$9999,2,FALSE)),0,VLOOKUP(四角板専用!C15,四角板専用!AA$1:AC$9999,2,FALSE)) -> 7.93 | E15: 80 | F15: =IF(G15=0,0,G15*PI()*(1-(H15/360))) -> 0 | H15: =IF(G15=0,0,IF(I15="90°",270,ASIN((I15/2)/(G15/2))*180/PI()*2)) -> 0 | J15: 62 | K15: 9 | L15: 2 | M15: =IF(D15+E15+F15+N15=0,"",IF(E15=0,(D15*F15*J15*K15*L15)/1000000+N15,(D15*E15*J15*K15*L15)/1000000+N15)-IF(COUNTIFS(B$1:B15,B15,A$1:A15,A15)>1,0,SUMIFS(四角板抜き穴専用!Q:Q,四角板抜き穴専用!A:A,四角板専用!A15,四角板抜き穴専用!B:B,B15))) -> 0.7079904 | O15: =IF(O14>0,0,IF(A16&B16=A15&B15,0,IF(COUNTIFS(A:A,A15,B:B,B15)>=2,SUMIFS(M:M,A:A,A15,B:B,B15),0))) -> 0 | T15: =M15 -> 0.7079904
A16: ノズル他詳細 | B16: 落下防止 | C16: SUS304 | D16: =IF(ISNA(VLOOKUP(四角板専用!C16,四角板専用!AA$1:AC$9999,2,FALSE)),0,VLOOKUP(四角板専用!C16,四角板専用!AA$1:AC$9999,2,FALSE)) -> 7.93 | E16: 61 | F16: =IF(G16=0,0,G16*PI()*(1-(H16/360))) -> 0 | H16: =IF(G16=0,0,IF(I16="90°",270,ASIN((I16/2)/(G16/2))*180/PI()*2)) -> 0 | J16: 38 | K16: 9 | L16: 2 | M16: =IF(D16+E16+F16+N16=0,"",IF(E16=0,(D16*F16*J16*K16*L16)/1000000+N16,(D16*E16*J16*K16*L16)/1000000+N16)-IF(COUNTIFS(B$1:B16,B16,A$1:A16,A16)>1,0,SUMIFS(四角板抜き穴専用!Q:Q,四角板抜き穴専用!A:A,四角板専用!A16,四角板抜き穴専用!B:B,B16))) -> 0.33087132 | O16: =IF(O15>0,0,IF(A17&B17=A16&B16,0,IF(COUNTIFS(A:A,A16,B:B,B16)>=2,SUMIFS(M:M,A:A,A16,B:B,B16),0))) -> 0 | T16: =M16 -> 0.33087132
A17: ノズル他詳細 | B17: 落下防止 | C17: SUS304 | D17: =IF(ISNA(VLOOKUP(四角板専用!C17,四角板専用!AA$1:AC$9999,2,FALSE)),0,VLOOKUP(四角板専用!C17,四角板専用!AA$1:AC$9999,2,FALSE)) -> 7.93 | E17: 69 | F17: =IF(G17=0,0,G17*PI()*(1-(H17/360))) -> 0 | H17: =IF(G17=0,0,IF(I17="90°",270,ASIN((I17/2)/(G17/2))*180/PI()*2)) -> 0 | J17: 38 | K17: 9 | L17: 2 | M17: =IF(D17+E17+F17+N17=0,"",IF(E17=0,(D17*F17*J17*K17*L17)/1000000+N17,(D17*E17*J17*K17*L17)/1000000+N17)-IF(COUNTIFS(B$1:B17,B17,A$1:A17,A17)>1,0,SUMIFS(四角板抜き穴専用!Q:Q,四角板抜き穴専用!A:A,四角板専用!A17,四角板抜き穴専用!B:B,B17))) -> 0.37426428 | O17: =IF(O16>0,0,IF(A18&B18=A17&B17,0,IF(COUNTIFS(A:A,A17,B:B,B17)>=2,SUMIFS(M:M,A:A,A17,B:B,B17),0))) -> 1.413126 | T17: =M17 -> 0.37426428
A18: ノズル他詳細 | B18: M-2 | C18: SS400 | D18: =IF(ISNA(VLOOKUP(四角板専用!C18,四角板専用!AA$1:AC$9999,2,FALSE)),0,VLOOKUP(四角板専用!C18,四角板専用!AA$1:AC$9999,2,FALSE)) -> 7.85 | E18: 206 | F18: =IF(G18=0,0,G18*PI()*(1-(H18/360))) -> 0 | H18: =IF(G18=0,0,IF(I18="90°",270,ASIN((I18/2)/(G18/2))*180/PI()*2)) -> 0 | J18: 270 | K18: 6 | L18: 2 | M18: =IF(D18+E18+F18+N18=0,"",IF(E18=0,(D18*F18*J18*K18*L18)/1000000+N18,(D18*E18*J18*K18*L18)/1000000+N18)-IF(COUNTIFS(B$1:B18,B18,A$1:A18,A18)>1,0,SUMIFS(四角板抜き穴専用!Q:Q,四角板抜き穴専用!A:A,四角板専用!A18,四角板抜き穴専用!B:B,B18))) -> 5.239404 | O18: =IF(O17>0,0,IF(A19&B19=A18&B18,0,IF(COUNTIFS(A:A,A18,B:B,B18)>=2,SUMIFS(M:M,A:A,A18,B:B,B18),0))) -> 0 | T18: =M18 -> 5.239404
A19: ノズル他詳細 | B19: M-2 | C19: SS400 | D19: =IF(ISNA(VLOOKUP(四角板専用!C19,四角板専用!AA$1:AC$9999,2,FALSE)),0,VLOOKUP(四角板専用!C19,四角板専用!AA$1:AC$9999,2,FALSE)) -> 7.85 | E19: 294 | F19: =IF(G19=0,0,G19*PI()*(1-(H19/360))) -> 0 | H19: =IF(G19=0,0,IF(I19="90°",270,ASIN((I19/2)/(G19/2))*180/PI()*2)) -> 0 | J19: 270 | K19: 6 | L19: 2 | M19: =IF(D19+E19+F19+N19=0,"",IF(E19=0,(D19*F19*J19*K19*L19)/1000000+N19,(D19*E19*J19*K19*L19)/1000000+N19)-IF(COUNTIFS(B$1:B19,B19,A$1:A19,A19)>1,0,SUMIFS(四角板抜き穴専用!Q:Q,四角板抜き穴専用!A:A,四角板専用!A19,四角板抜き穴専用!B:B,B19))) -> 7.477596 | O19: =IF(O18>0,0,IF(A20&B20=A19&B19,0,IF(COUNTIFS(A:A,A19,B:B,B19)>=2,SUMIFS(M:M,A:A,A19,B:B,B19),0))) -> 0 | T19: =M19 -> 7.477596
A20: ノズル他詳細 | B20: M-2 | C20: SS400 | D20: =IF(ISNA(VLOOKUP(四角板専用!C20,四角板専用!AA$1:AC$9999,2,FALSE)),0,VLOOKUP(四角板専用!C20,四角板専用!AA$1:AC$9999,2,FALSE)) -> 7.85 | F20: =IF(G20=0,0,G20*PI()*(1-(H20/360))) -> 0 | H20: =IF(G20=0,0,IF(I20="90°",270,ASIN((I20/2)/(G20/2))*180/PI()*2)) -> 0 | M20: =IF(D20+E20+F20+N20=0,"",IF(E20=0,(D20*F20*J20*K20*L20)/1000000+N20,(D20*E20*J20*K20*L20)/1000000+N20)-IF(COUNTIFS(B$1:B20,B20,A$1:A20,A20)>1,0,SUMIFS(四角板抜き穴専用!Q:Q,四角板抜き穴専用!A:A,四角板専用!A20,四角板抜き穴専用!B:B,B20))) -> 3.3 | N20: 3.3 | O20: =IF(O19>0,0,IF(A21&B21=A20&B20,0,IF(COUNTIFS(A:A,A20,B:B,B20)>=2,SUMIFS(M:M,A:A,A20,B:B,B20),0))) -> 16.017 | T20: =M20 -> 3.3
A21: ノズル他詳細 | B21: 8詳細 | C21: SS400 | D21: =IF(ISNA(VLOOKUP(四角板専用!C21,四角板専用!AA$1:AC$9999,2,FALSE)),0,VLOOKUP(四角板専用!C21,四角板専用!AA$1:AC$9999,2,FALSE)) -> 7.85 | F21: =IF(G21=0,0,G21*PI()*(1-(H21/360))) -> 0 | H21: =IF(G21=0,0,IF(I21="90°",270,ASIN((I21/2)/(G21/2))*180/PI()*2)) -> 0 | M21: =IF(D21+E21+F21+N21=0,"",IF(E21=0,(D21*F21*J21*K21*L21)/1000000+N21,(D21*E21*J21*K21*L21)/1000000+N21)-IF(COUNTIFS(B$1:B21,B21,A$1:A21,A21)>1,0,SUMIFS(四角板抜き穴専用!Q:Q,四角板抜き穴専用!A:A,四角板専用!A21,四角板抜き穴専用!B:B,B21))) -> 0.07332 | N21: =0.0592+0.0063*2+0.00152 -> 0.07332 | O21: =IF(O20>0,0,IF(A22&B22=A21&B21,0,IF(COUNTIFS(A:A,A21,B:B,B21)>=2,SUMIFS(M:M,A:A,A21,B:B,B21),0))) -> 0 | T21: =M21 -> 0.07332
A22: 点検ステージ | B22: 床 | C22: SS400 | D22: =IF(ISNA(VLOOKUP(四角板専用!C22,四角板専用!AA$1:AC$9999,2,FALSE)),0,VLOOKUP(四角板専用!C22,四角板専用!AA$1:AC$9999,2,FALSE)) -> 7.85 | E22: 3455 | F22: =IF(G22=0,0,G22*PI()*(1-(H22/360))) -> 0 | H22: =IF(G22=0,0,IF(I22="90°",270,ASIN((I22/2)/(G22/2))*180/PI()*2)) -> 0 | J22: 2300 | K22: 4.5 | L22: 1 | M22: =IF(D22+E22+F22+N22=0,"",IF(E22=0,(D22*F22*J22*K22*L22)/1000000+N22,(D22*E22*J22*K22*L22)/1000000+N22)-IF(COUNTIFS(B$1:B22,B22,A$1:A22,A22)>1,0,SUMIFS(四角板抜き穴専用!Q:Q,四角板抜き穴専用!A:A,四角板専用!A22,四角板抜き穴専用!B:B,B22))) -> 242.14916 | O22: =IF(O21>0,0,IF(A23&B23=A22&B22,0,IF(COUNTIFS(A:A,A22,B:B,B22)>=2,SUMIFS(M:M,A:A,A22,B:B,B22),0))) -> 0 | T22: =M22 -> 242.14916
A23: 点検ステージ | B23: 床 | C23: SS400 | D23: =IF(ISNA(VLOOKUP(四角板専用!C23,四角板専用!AA$1:AC$9999,2,FALSE)),0,VLOOKUP(四角板専用!C23,四角板専用!AA$1:AC$9999,2,FALSE)) -> 7.85 | E23: 2177.5 | F23: =IF(G23=0,0,G23*PI()*(1-(H23/360))) -> 0 | H23: =IF(G23=0,0,IF(I23="90°",270,ASIN((I23/2)/(G23/2))*180/PI()*2)) -> 0 | J23: 1705 | K23: 4.5 | L23: 1 | M23: =IF(D23+E23+F23+N23=0,"",IF(E23=0,(D23*F23*J23*K23*L23)/1000000+N23,(D23*E23*J23*K23*L23)/1000000+N23)-IF(COUNTIFS(B$1:B23,B23,A$1:A23,A23)>1,0,SUMIFS(四角板抜き穴専用!Q:Q,四角板抜き穴専用!A:A,四角板専用!A23,四角板抜き穴専用!B:B,B23))) -> 131.14892 | O23: =IF(O22>0,0,IF(A24&B24=A23&B23,0,IF(COUNTIFS(A:A,A23,B:B,B23)>=2,SUMIFS(M:M,A:A,A23,B:B,B23),0))) -> 373.29808 | T23: =M23 -> 131.14892
A24: 点検ステージ | B24: ケ止メ | C24: SS400 | D24: =IF(ISNA(VLOOKUP(四角板専用!C24,四角板専用!AA$1:AC$9999,2,FALSE)),0,VLOOKUP(四角板専用!C24,四角板専用!AA$1:AC$9999,2,FALSE)) -> 7.85 | F24: =IF(G24=0,0,G24*PI()*(1-(H24/360))) -> 694.29198 | G24: 221 | H24: =IF(G24=0,0,IF(I24="90°",270,ASIN((I24/2)/(G24/2))*180/PI()*2)) -> 0 | J24: 50 | K24: 6 | L24: 1 | M24: =IF(D24+E24+F24+N24=0,"",IF(E24=0,(D24*F24*J24*K24*L24)/1000000+N24,(D24*E24*J24*K24*L24)/1000000+N24)-IF(COUNTIFS(B$1:B24,B24,A$1:A24,A24)>1,0,SUMIFS(四角板抜き穴専用!Q:Q,四角板抜き穴専用!A:A,四角板専用!A24,四角板抜き穴専用!B:B,B24))) -> 1.6350576 | O24: =IF(O23>0,0,IF(A25&B25=A24&B24,0,IF(COUNTIFS(A:A,A24,B:B,B24)>=2,SUMIFS(M:M,A:A,A24,B:B,B24),0))) -> 0 | T24: =M24 -> 1.6350576
A25: 点検ステージ | B25: ケ止メ | C25: SS400 | D25: =IF(ISNA(VLOOKUP(四角板専用!C25,四角板専用!AA$1:AC$9999,2,FALSE)),0,VLOOKUP(四角板専用!C25,四角板専用!AA$1:AC$9999,2,FALSE)) -> 7.85 | F25: =IF(G25=0,0,G25*PI()*(1-(H25/360))) -> 757.12383 | G25: 241 | H25: =IF(G25=0,0,IF(I25="90°",270,ASIN((I25/2)/(G25/2))*180/PI()*2)) -> 0 | J25: 50 | K25: 6 | L25: 1 | M25: =IF(D25+E25+F25+N25=0,"",IF(E25=0,(D25*F25*J25*K25*L25)/1000000+N25,(D25*E25*J25*K25*L25)/1000000+N25)-IF(COUNTIFS(B$1:B25,B25,A$1:A25,A25)>1,0,SUMIFS(四角板抜き穴専用!Q:Q,四角板抜き穴専用!A:A,四角板専用!A25,四角板抜き穴専用!B:B,B25))) -> 1.7830266 | O25: =IF(O24>0,0,IF(A26&B26=A25&B25,0,IF(COUNTIFS(A:A,A25,B:B,B25)>=2,SUMIFS(M:M,A:A,A25,B:B,B25),0))) -> 0 | T25: =M25 -> 1.7830266
A26: 点検ステージ | B26: ケ止メ | C26: SS400 | D26: =IF(ISNA(VLOOKUP(四角板専用!C26,四角板専用!AA$1:AC$9999,2,FALSE)),0,VLOOKUP(四角板専用!C26,四角板専用!AA$1:AC$9999,2,FALSE)) -> 7.85 | F26: =IF(G26=0,0,G26*PI()*(1-(H26/360))) -> 867.07957 | G26: 276 | H26: =IF(G26=0,0,IF(I26="90°",270,ASIN((I26/2)/(G26/2))*180/PI()*2)) -> 0 | J26: 50 | K26: 6 | L26: 2 | M26: =IF(D26+E26+F26+N26=0,"",IF(E26=0,(D26*F26*J26*K26*L26)/1000000+N26,(D26*E26*J26*K26*L26)/1000000+N26)-IF(COUNTIFS(B$1:B26,B26,A$1:A26,A26)>1,0,SUMIFS(四角板抜き穴専用!Q:Q,四角板抜き穴専用!A:A,四角板専用!A26,四角板抜き穴専用!B:B,B26))) -> 4.0839448 | O26: =IF(O25>0,0,IF(A27&B27=A26&B26,0,IF(COUNTIFS(A:A,A26,B:B,B26)>=2,SUMIFS(M:M,A:A,A26,B:B,B26),0))) -> 0 | T26: =M26 -> 4.0839448
A27: 点検ステージ | B27: ケ止メ | C27: SS400 | D27: =IF(ISNA(VLOOKUP(四角板専用!C27,四角板専用!AA$1:AC$9999,2,FALSE)),0,VLOOKUP(四角板専用!C27,四角板専用!AA$1:AC$9999,2,FALSE)) -> 7.85 | F27: =IF(G27=0,0,G27*PI()*(1-(H27/360))) -> 1039.8672 | G27: 331 | H27: =IF(G27=0,0,IF(I27="90°",270,ASIN((I27/2)/(G27/2))*180/PI()*2)) -> 0 | J27: 50 | K27: 6 | L27: 1 | M27: =IF(D27+E27+F27+N27=0,"",IF(E27=0,(D27*F27*J27*K27*L27)/1000000+N27,(D27*E27*J27*K27*L27)/1000000+N27)-IF(COUNTIFS(B$1:B27,B27,A$1:A27,A27)>1,0,SUMIFS(四角板抜き穴専用!Q:Q,四角板抜き穴専用!A:A,四角板専用!A27,四角板抜き穴専用!B:B,B27))) -> 2.4488872 | O27: =IF(O26>0,0,IF(A28&B28=A27&B27,0,IF(COUNTIFS(A:A,A27,B:B,B27)>=2,SUMIFS(M:M,A:A,A27,B:B,B27),0))) -> 0 | T27: =M27 -> 2.4488872
A28: 点検ステージ | B28: ケ止メ | C28: SS400 | D28: =IF(ISNA(VLOOKUP(四角板専用!C28,四角板専用!AA$1:AC$9999,2,FALSE)),0,VLOOKUP(四角板専用!C28,四角板専用!AA$1:AC$9999,2,FALSE)) -> 7.85 | F28: =IF(G28=0,0,G28*PI()*(1-(H28/360))) -> 2626.3715 | G28: 836 | H28: =IF(G28=0,0,IF(I28="90°",270,ASIN((I28/2)/(G28/2))*180/PI()*2)) -> 0 | J28: 50 | K28: 6 | L28: 1 | M28: =IF(D28+E28+F28+N28=0,"",IF(E28=0,(D28*F28*J28*K28*L28)/1000000+N28,(D28*E28*J28*K28*L28)/1000000+N28)-IF(COUNTIFS(B$1:B28,B28,A$1:A28,A28)>1,0,SUMIFS(四角板抜き穴専用!Q:Q,四角板抜き穴専用!A:A,四角板専用!A28,四角板抜き穴専用!B:B,B28))) -> 6.1851048 | O28: =IF(O27>0,0,IF(A29&B29=A28&B28,0,IF(COUNTIFS(A:A,A28,B:B,B28)>=2,SUMIFS(M:M,A:A,A28,B:B,B28),0))) -> 0 | T28: =M28 -> 6.1851048
A29: 点検ステージ | B29: ケ止メ | C29: SS400 | D29: =IF(ISNA(VLOOKUP(四角板専用!C29,四角板専用!AA$1:AC$9999,2,FALSE)),0,VLOOKUP(四角板専用!C29,四角板専用!AA$1:AC$9999,2,FALSE)) -> 7.85 | F29: =IF(G29=0,0,G29*PI()*(1-(H29/360))) -> 1872.3892 | G29: 596 | H29: =IF(G29=0,0,IF(I29="90°",270,ASIN((I29/2)/(G29/2))*180/PI()*2)) -> 0 | J29: 50 | K29: 6 | L29: 1 | M29: =IF(D29+E29+F29+N29=0,"",IF(E29=0,(D29*F29*J29*K29*L29)/1000000+N29,(D29*E29*J29*K29*L29)/1000000+N29)-IF(COUNTIFS(B$1:B29,B29,A$1:A29,A29)>1,0,SUMIFS(四角板抜き穴専用!Q:Q,四角板抜き穴専用!A:A,四角板専用!A29,四角板抜き穴専用!B:B,B29))) -> 4.4094766 | O29: =IF(O28>0,0,IF(A30&B30=A29&B29,0,IF(COUNTIFS(A:A,A29,B:B,B29)>=2,SUMIFS(M:M,A:A,A29,B:B,B29),0))) -> 20.545498 | T29: =M29 -> 4.4094766
A30: 点検ステージ | B30: C詳細(スペーサ) | C30: SS400 | D30: =IF(ISNA(VLOOKUP(四角板専用!C30,四角板専用!AA$1:AC$9999,2,FALSE)),0,VLOOKUP(四角板専用!C30,四角板専用!AA$1:AC$9999,2,FALSE)) -> 7.85 | E30: 170 | F30: =IF(G30=0,0,G30*PI()*(1-(H30/360))) -> 0 | H30: =IF(G30=0,0,IF(I30="90°",270,ASIN((I30/2)/(G30/2))*180/PI()*2)) -> 0 | J30: 75 | K30: 6 | L30: 8 | M30: =IF(D30+E30+F30+N30=0,"",IF(E30=0,(D30*F30*J30*K30*L30)/1000000+N30,(D30*E30*J30*K30*L30)/1000000+N30)-IF(COUNTIFS(B$1:B30,B30,A$1:A30,A30)>1,0,SUMIFS(四角板抜き穴専用!Q:Q,四角板抜き穴専用!A:A,四角板専用!A30,四角板抜き穴専用!B:B,B30))) -> 4.8042 | O30: =IF(O29>0,0,IF(A31&B31=A30&B30,0,IF(COUNTIFS(A:A,A30,B:B,B30)>=2,SUMIFS(M:M,A:A,A30,B:B,B30),0))) -> 0 | T30: =M30 -> 4.8042
A31: 点検ステージ | B31: D詳細(ガセット) | C31: SS400 | D31: =IF(ISNA(VLOOKUP(四角板専用!C31,四角板専用!AA$1:AC$9999,2,FALSE)),0,VLOOKUP(四角板専用!C31,四角板専用!AA$1:AC$9999,2,FALSE)) -> 7.85 | E31: 198.5 | F31: =IF(G31=0,0,G31*PI()*(1-(H31/360))) -> 0 | H31: =IF(G31=0,0,IF(I31="90°",270,ASIN((I31/2)/(G31/2))*180/PI()*2)) -> 0 | J31: 150 | K31: 6 | L31: 2 | M31: =IF(D31+E31+F31+N31=0,"",IF(E31=0,(D31*F31*J31*K31*L31)/1000000+N31,(D31*E31*J31*K31*L31)/1000000+N31)-IF(COUNTIFS(B$1:B31,B31,A$1:A31,A31)>1,0,SUMIFS(四角板抜き穴専用!Q:Q,四角板抜き穴専用!A:A,四角板専用!A31,四角板抜き穴専用!B:B,B31))) -> 2.804805 | O31: =IF(O30>0,0,IF(A32&B32=A31&B31,0,IF(COUNTIFS(A:A,A31,B:B,B31)>=2,SUMIFS(M:M,A:A,A31,B:B,B31),0))) -> 0 | T31: =M31 -> 2.804805
A32: 手摺配置 | B32: 取付座(25A) | C32: SS400 | D32: =IF(ISNA(VLOOKUP(四角板専用!C32,四角板専用!AA$1:AC$9999,2,FALSE)),0,VLOOKUP(四角板専用!C32,四角板専用!AA$1:AC$9999,2,FALSE)) -> 7.85 | E32: 140 | F32: =IF(G32=0,0,G32*PI()*(1-(H32/360))) -> 0 | H32: =IF(G32=0,0,IF(I32="90°",270,ASIN((I32/2)/(G32/2))*180/PI()*2)) -> 0 | J32: 50 | K32: 6 | L32: 23 | M32: =IF(D32+E32+F32+N32=0,"",IF(E32=0,(D32*F32*J32*K32*L32)/1000000+N32,(D32*E32*J32*K32*L32)/1000000+N32)-IF(COUNTIFS(B$1:B32,B32,A$1:A32,A32)>1,0,SUMIFS(四角板抜き穴専用!Q:Q,四角板抜き穴専用!A:A,四角板専用!A32,四角板抜き穴専用!B:B,B32))) -> 7.5831 | O32: =IF(O31>0,0,IF(A33&B33=A32&B32,0,IF(COUNTIFS(A:A,A32,B:B,B32)>=2,SUMIFS(M:M,A:A,A32,B:B,B32),0))) -> 0 | T32: =M32 -> 7.5831
A33: 手摺配置 | B33: 32A取付座(ラダー以外) | C33: SS400 | D33: =IF(ISNA(VLOOKUP(四角板専用!C33,四角板専用!AA$1:AC$9999,2,FALSE)),0,VLOOKUP(四角板専用!C33,四角板専用!AA$1:AC$9999,2,FALSE)) -> 7.85 | E33: 140 | F33: =IF(G33=0,0,G33*PI()*(1-(H33/360))) -> 0 | H33: =IF(G33=0,0,IF(I33="90°",270,ASIN((I33/2)/(G33/2))*180/PI()*2)) -> 0 | J33: 50 | K33: 6 | L33: 12 | M33: =IF(D33+E33+F33+N33=0,"",IF(E33=0,(D33*F33*J33*K33*L33)/1000000+N33,(D33*E33*J33*K33*L33)/1000000+N33)-IF(COUNTIFS(B$1:B33,B33,A$1:A33,A33)>1,0,SUMIFS(四角板抜き穴専用!Q:Q,四角板抜き穴専用!A:A,四角板専用!A33,四角板抜き穴専用!B:B,B33))) -> 3.9564 | O33: =IF(O32>0,0,IF(A34&B34=A33&B33,0,IF(COUNTIFS(A:A,A33,B:B,B33)>=2,SUMIFS(M:M,A:A,A33,B:B,B33),0))) -> 0 | T33: =M33 -> 3.9564
A34: ラダー | B34: AB詳細 | C34: SS400 | D34: =IF(ISNA(VLOOKUP(四角板専用!C34,四角板専用!AA$1:AC$9999,2,FALSE)),0,VLOOKUP(四角板専用!C34,四角板専用!AA$1:AC$9999,2,FALSE)) -> 7.85 | E34: 83.65 | F34: =IF(G34=0,0,G34*PI()*(1-(H34/360))) -> 0 | H34: =IF(G34=0,0,IF(I34="90°",270,ASIN((I34/2)/(G34/2))*180/PI()*2)) -> 0 | J34: 100 | K34: 9 | L34: 4 | M34: =IF(D34+E34+F34+N34=0,"",IF(E34=0,(D34*F34*J34*K34*L34)/1000000+N34,(D34*E34*J34*K34*L34)/1000000+N34)-IF(COUNTIFS(B$1:B34,B34,A$1:A34,A34)>1,0,SUMIFS(四角板抜き穴専用!Q:Q,四角板抜き穴専用!A:A,四角板専用!A34,四角板抜き穴専用!B:B,B34))) -> 2.363949 | O34: =IF(O33>0,0,IF(A35&B35=A34&B34,0,IF(COUNTIFS(A:A,A34,B:B,B34)>=2,SUMIFS(M:M,A:A,A34,B:B,B34),0))) -> 0 | T34: =M34 -> 2.363949
A35: ラダー | B35: AB詳細 | C35: SS400 | D35: =IF(ISNA(VLOOKUP(四角板専用!C35,四角板専用!AA$1:AC$9999,2,FALSE)),0,VLOOKUP(四角板専用!C35,四角板専用!AA$1:AC$9999,2,FALSE)) -> 7.85 | E35: 80 | F35: =IF(G35=0,0,G35*PI()*(1-(H35/360))) -> 0 | H35: =IF(G35=0,0,IF(I35="90°",270,ASIN((I35/2)/(G35/2))*180/PI()*2)) -> 0 | J35: 100 | K35: 9 | L35: 4 | M35: =IF(D35+E35+F35+N35=0,"",IF(E35=0,(D35*F35*J35*K35*L35)/1000000+N35,(D35*E35*J35*K35*L35)/1000000+N35)-IF(COUNTIFS(B$1:B35,B35,A$1:A35,A35)>1,0,SUMIFS(四角板抜き穴専用!Q:Q,四角板抜き穴専用!A:A,四角板専用!A35,四角板抜き穴専用!B:B,B35))) -> 2.2608 | O35: =IF(O34>0,0,IF(A36&B36=A35&B35,0,IF(COUNTIFS(A:A,A35,B:B,B35)>=2,SUMIFS(M:M,A:A,A35,B:B,B35),0))) -> 4.624749 | T35: =M35 -> 2.2608
A36: ラダー | B36: D詳細 | C36: SS400 | D36: =IF(ISNA(VLOOKUP(四角板専用!C36,四角板専用!AA$1:AC$9999,2,FALSE)),0,VLOOKUP(四角板専用!C36,四角板専用!AA$1:AC$9999,2,FALSE)) -> 7.85 | E36: 120 | F36: =IF(G36=0,0,G36*PI()*(1-(H36/360))) -> 0 | H36: =IF(G36=0,0,IF(I36="90°",270,ASIN((I36/2)/(G36/2))*180/PI()*2)) -> 0 | J36: 50 | K36: 6 | L36: 1 | M36: =IF(D36+E36+F36+N36=0,"",IF(E36=0,(D36*F36*J36*K36*L36)/1000000+N36,(D36*E36*J36*K36*L36)/1000000+N36)-IF(COUNTIFS(B$1:B36,B36,A$1:A36,A36)>1,0,SUMIFS(四角板抜き穴専用!Q:Q,四角板抜き穴専用!A:A,四角板専用!A36,四角板抜き穴専用!B:B,B36))) -> 0.2826 | O36: =IF(O35>0,0,IF(A37&B37=A36&B36,0,IF(COUNTIFS(A:A,A36,B:B,B36)>=2,SUMIFS(M:M,A:A,A36,B:B,B36),0))) -> 0 | T36: =M36 -> 0.2826
A37: ラダー | B37: D詳細 | C37: SS400 | D37: =IF(ISNA(VLOOKUP(四角板専用!C37,四角板専用!AA$1:AC$9999,2,FALSE)),0,VLOOKUP(四角板専用!C37,四角板専用!AA$1:AC$9999,2,FALSE)) -> 7.85 | E37: 150 | F37: =IF(G37=0,0,G37*PI()*(1-(H37/360))) -> 0 | H37: =IF(G37=0,0,IF(I37="90°",270,ASIN((I37/2)/(G37/2))*180/PI()*2)) -> 0 | J37: 50 | K37: 6 | L37: 1 | M37: =IF(D37+E37+F37+N37=0,"",IF(E37=0,(D37*F37*J37*K37*L37)/1000000+N37,(D37*E37*J37*K37*L37)/1000000+N37)-IF(COUNTIFS(B$1:B37,B37,A$1:A37,A37)>1,0,SUMIFS(四角板抜き穴専用!Q:Q,四角板抜き穴専用!A:A,四角板専用!A37,四角板抜き穴専用!B:B,B37))) -> 0.35325 | O37: =IF(O36>0,0,IF(A38&B38=A37&B37,0,IF(COUNTIFS(A:A,A37,B:B,B37)>=2,SUMIFS(M:M,A:A,A37,B:B,B37),0))) -> 0 | T37: =M37 -> 0.35325
A38: ラダー | B38: D詳細 | C38: SS400 | D38: =IF(ISNA(VLOOKUP(四角板専用!C38,四角板専用!AA$1:AC$9999,2,FALSE)),0,VLOOKUP(四角板専用!C38,四角板専用!AA$1:AC$9999,2,FALSE)) -> 7.85 | E38: 73.65 | F38: =IF(G38=0,0,G38*PI()*(1-(H38/360))) -> 0 | H38: =IF(G38=0,0,IF(I38="90°",270,ASIN((I38/2)/(G38/2))*180/PI()*2)) -> 0 | J38: 50 | K38: 6 | L38: 1 | M38: =IF(D38+E38+F38+N38=0,"",IF(E38=0,(D38*F38*J38*K38*L38)/1000000+N38,(D38*E38*J38*K38*L38)/1000000+N38)-IF(COUNTIFS(B$1:B38,B38,A$1:A38,A38)>1,0,SUMIFS(四角板抜き穴専用!Q:Q,四角板抜き穴専用!A:A,四角板専用!A38,四角板抜き穴専用!B:B,B38))) -> 0.17344575 | O38: =IF(O37>0,0,IF(A39&B39=A38&B38,0,IF(COUNTIFS(A:A,A38,B:B,B38)>=2,SUMIFS(M:M,A:A,A38,B:B,B38),0))) -> 0.80929575 | T38: =M38 -> 0.17344575
A39: ラダー | B39: 手摺受座 | C39: SS400 | D39: =IF(ISNA(VLOOKUP(四角板専用!C39,四角板専用!AA$1:AC$9999,2,FALSE)),0,VLOOKUP(四角板専用!C39,四角板専用!AA$1:AC$9999,2,FALSE)) -> 7.85 | E39: 100 | F39: =IF(G39=0,0,G39*PI()*(1-(H39/360))) -> 0 | H39: =IF(G39=0,0,IF(I39="90°",270,ASIN((I39/2)/(G39/2))*180/PI()*2)) -> 0 | J39: 50 | K39: 6 | L39: 1 | M39: =IF(D39+E39+F39+N39=0,"",IF(E39=0,(D39*F39*J39*K39*L39)/1000000+N39,(D39*E39*J39*K39*L39)/1000000+N39)-IF(COUNTIFS(B$1:B39,B39,A$1:A39,A39)>1,0,SUMIFS(四角板抜き穴専用!Q:Q,四角板抜き穴専用!A:A,四角板専用!A39,四角板抜き穴専用!B:B,B39))) -> 0.2355 | O39: =IF(O38>0,0,IF(A40&B40=A39&B39,0,IF(COUNTIFS(A:A,A39,B:B,B39)>=2,SUMIFS(M:M,A:A,A39,B:B,B39),0))) -> 0 | T39: =M39 -> 0.2355
D40: =IF(ISNA(VLOOKUP(四角板専用!C40,四角板専用!AA$1:AC$9999,2,FALSE)),0,VLOOKUP(四角板専用!C40,四角板専用!AA$1:AC$9999,2,FALSE)) -> 0 | F40: =IF(G40=0,0,G40*PI()*(1-(H40/360))) -> 0 | H40: =IF(G40=0,0,IF(I40="90°",270,ASIN((I40/2)/(G40/2))*180/PI()*2)) -> 0 | M40: =IF(D40+E40+F40+N40=0,"",IF(E40=0,(D40*F40*J40*K40*L40)/1000000+N40,(D40*E40*J40*K40*L40)/1000000+N40)-IF(COUNTIFS(B$1:B40,B40,A$1:A40,A40)>1,0,SUMIFS(四角板抜き穴専用!Q:Q,四角板抜き穴専用!A:A,四角板専用!A40,四角板抜き穴専用!B:B,B40))) | O40: =IF(O39>0,0,IF(A41&B41=A40&B40,0,IF(COUNTIFS(A:A,A40,B:B,B40)>=2,SUMIFS(M:M,A:A,A40,B:B,B40),0))) -> 0 | T40: =M40
...

Sheet 四角板抜き穴専用
A1: 参照図 | B1: 使用部位 | C1: 使用部材 | D1: 重量定数 | E1: 長さ(mm) | F1: 幅(mm) | G1: 直径(mm) | H1: 厚み(mm) | I1: 数量 | J1: 重量 | K1: 付属品(Kg) | L1: 小計 | Q1: 総計シート計算用 | AA1: 部材リスト | AB1: 部材重量定数リスト | AC1: 単位
A2: 点検ステージ | B2: 床 | C2: SS400 | D2: =IF(ISNA(VLOOKUP(C2,AA$1:AC$9999,2,FALSE)),"",VLOOKUP(C2,AA$1:AC$9999,2,FALSE)) -> 7.85 | G2: 215 | H2: 4.5 | I2: 1 | J2: =IF(E2+G2+K2=0,"",IF(E2=0,((G2^2*PI()/4)*(H2*D2*I2))/1000000+K2,((E2*F2*H2)*(D2*I2))/1000000+K2)) -> 1.2824752 | L2: =IF(L1>0,0,IF(A3&B3=A2&B2,0,IF(COUNTIFS(A:A,A2,B:B,B2)>=2,SUMIFS(J:J,A:A,A2,B:B,B2),0))) -> 0 | Q2: =J2 -> 1.2824752 | AA2: SS400 | AB2: 7.85 | AC2: g/cm³
A3: 点検ステージ | B3: 床 | C3: SS400 | D3: =IF(ISNA(VLOOKUP(C3,AA$1:AC$9999,2,FALSE)),"",VLOOKUP(C3,AA$1:AC$9999,2,FALSE)) -> 7.85 | G3: 235 | H3: 4.5 | I3: 1 | J3: =IF(E3+G3+K3=0,"",IF(E3=0,((G3^2*PI()/4)*(H3*D3*I3))/1000000+K3,((E3*F3*H3)*(D3*I3))/1000000+K3)) -> 1.5321729 | L3: =IF(L2>0,0,IF(A4&B4=A3&B3,0,IF(COUNTIFS(A:A,A3,B:B,B3)>=2,SUMIFS(J:J,A:A,A3,B:B,B3),0))) -> 0 | Q3: =J3 -> 1.5321729 | AA3: SUS304 | AB3: 7.93 | AC3: g/cm³
A4: 点検ステージ | B4: 床 | C4: SS400 | D4: =IF(ISNA(VLOOKUP(C4,AA$1:AC$9999,2,FALSE)),"",VLOOKUP(C4,AA$1:AC$9999,2,FALSE)) -> 7.85 | G4: 270 | H4: 4.5 | I4: 2 | J4: =IF(E4+G4+K4=0,"",IF(E4=0,((G4^2*PI()/4)*(H4*D4*I4))/1000000+K4,((E4*F4*H4)*(D4*I4))/1000000+K4)) -> 4.0451029 | L4: =IF(L3>0,0,IF(A5&B5=A4&B4,0,IF(COUNTIFS(A:A,A4,B:B,B4)>=2,SUMIFS(J:J,A:A,A4,B:B,B4),0))) -> 0 | Q4: =J4 -> 4.0451029
A5: 点検ステージ | B5: 床 | C5: SS400 | D5: =IF(ISNA(VLOOKUP(C5,AA$1:AC$9999,2,FALSE)),"",VLOOKUP(C5,AA$1:AC$9999,2,FALSE)) -> 7.85 | G5: 325 | H5: 4.5 | I5: 1 | J5: =IF(E5+G5+K5=0,"",IF(E5=0,((G5^2*PI()/4)*(H5*D5*I5))/1000000+K5,((E5*F5*H5)*(D5*I5))/1000000+K5)) -> 2.9304801 | L5: =IF(L4>0,0,IF(A6&B6=A5&B5,0,IF(COUNTIFS(A:A,A5,B:B,B5)>=2,SUMIFS(J:J,A:A,A5,B:B,B5),0))) -> 0 | Q5: =J5 -> 2.9304801
A6: 点検ステージ | B6: 床 | C6: SS400 | D6: =IF(ISNA(VLOOKUP(C6,AA$1:AC$9999,2,FALSE)),"",VLOOKUP(C6,AA$1:AC$9999,2,FALSE)) -> 7.85 | G6: 830 | H6: 4.5 | I6: 1 | J6: =IF(E6+G6+K6=0,"",IF(E6=0,((G6^2*PI()/4)*(H6*D6*I6))/1000000+K6,((E6*F6*H6)*(D6*I6))/1000000+K6)) -> 19.112973 | L6: =IF(L5>0,0,IF(A7&B7=A6&B6,0,IF(COUNTIFS(A:A,A6,B:B,B6)>=2,SUMIFS(J:J,A:A,A6,B:B,B6),0))) -> 0 | Q6: =J6 -> 19.112973
A7: 点検ステージ | B7: 床 | C7: SS400 | D7: =IF(ISNA(VLOOKUP(C7,AA$1:AC$9999,2,FALSE)),"",VLOOKUP(C7,AA$1:AC$9999,2,FALSE)) -> 7.85 | G7: 590 | H7: 4.5 | I7: 1 | J7: =IF(E7+G7+K7=0,"",IF(E7=0,((G7^2*PI()/4)*(H7*D7*I7))/1000000+K7,((E7*F7*H7)*(D7*I7))/1000000+K7)) -> 9.6577526 | L7: =IF(L6>0,0,IF(A8&B8=A7&B7,0,IF(COUNTIFS(A:A,A7,B:B,B7)>=2,SUMIFS(J:J,A:A,A7,B:B,B7),0))) -> 38.560956 | Q7: =J7 -> 9.6577526
D8: =IF(ISNA(VLOOKUP(C8,AA$1:AC$9999,2,FALSE)),"",VLOOKUP(C8,AA$1:AC$9999,2,FALSE)) | J8: =IF(E8+G8+K8=0,"",IF(E8=0,((G8^2*PI()/4)*(H8*D8*I8))/1000000+K8,((E8*F8*H8)*(D8*I8))/1000000+K8)) | L8: =IF(L7>0,0,IF(A9&B9=A8&B8,0,IF(COUNTIFS(A:A,A8,B:B,B8)>=2,SUMIFS(J:J,A:A,A8,B:B,B8),0))) -> 0 | Q8: =J8
D9: =IF(ISNA(VLOOKUP(C9,AA$1:AC$9999,2,FALSE)),"",VLOOKUP(C9,AA$1:AC$9999,2,FALSE)) | J9: =IF(E9+G9+K9=0,"",IF(E9=0,((G9^2*PI()/4)*(H9*D9*I9))/1000000+K9,((E9*F9*H9)*(D9*I9))/1000000+K9)) | L9: =IF(L8>0,0,IF(A10&B10=A9&B9,0,IF(COUNTIFS(A:A,A9,B:B,B9)>=2,SUMIFS(J:J,A:A,A9,B:B,B9),0))) -> 0 | Q9: =J9
D10: =IF(ISNA(VLOOKUP(C10,AA$1:AC$9999,2,FALSE)),"",VLOOKUP(C10,AA$1:AC$9999,2,FALSE)) | J10: =IF(E10+G10+K10=0,"",IF(E10=0,((G10^2*PI()/4)*(H10*D10*I10))/1000000+K10,((E10*F10*H10)*(D10*I10))/1000000+K10)) | L10: =IF(L9>0,0,IF(A11&B11=A10&B10,0,IF(COUNTIFS(A:A,A10,B:B,B10)>=2,SUMIFS(J:J,A:A,A10,B:B,B10),0))) -> 0 | Q10: =J10
D11: =IF(ISNA(VLOOKUP(C11,AA$1:AC$9999,2,FALSE)),"",VLOOKUP(C11,AA$1:AC$9999,2,FALSE)) | J11: =IF(E11+G11+K11=0,"",IF(E11=0,((G11^2*PI()/4)*(H11*D11*I11))/1000000+K11,((E11*F11*H11)*(D11*I11))/1000000+K11)) | L11: =IF(L10>0,0,IF(A12&B12=A11&B11,0,IF(COUNTIFS(A:A,A11,B:B,B11)>=2,SUMIFS(J:J,A:A,A11,B:B,B11),0))) -> 0 | Q11: =J11
D12: =IF(ISNA(VLOOKUP(C12,AA$1:AC$9999,2,FALSE)),"",VLOOKUP(C12,AA$1:AC$9999,2,FALSE)) | J12: =IF(E12+G12+K12=0,"",IF(E12=0,((G12^2*PI()/4)*(H12*D12*I12))/1000000+K12,((E12*F12*H12)*(D12*I12))/1000000+K12)) | L12: =IF(L11>0,0,IF(A13&B13=A12&B12,0,IF(COUNTIFS(A:A,A12,B:B,B12)>=2,SUMIFS(J:J,A:A,A12,B:B,B12),0))) -> 0 | Q12: =J12
D13: =IF(ISNA(VLOOKUP(C13,AA$1:AC$9999,2,FALSE)),"",VLOOKUP(C13,AA$1:AC$9999,2,FALSE)) | J13: =IF(E13+G13+K13=0,"",IF(E13=0,((G13^2*PI()/4)*(H13*D13*I13))/1000000+K13,((E13*F13*H13)*(D13*I13))/1000000+K13)) | L13: =IF(L12>0,0,IF(A14&B14=A13&B13,0,IF(COUNTIFS(A:A,A13,B:B,B13)>=2,SUMIFS(J:J,A:A,A13,B:B,B13),0))) -> 0 | Q13: =J13
D14: =IF(ISNA(VLOOKUP(C14,AA$1:AC$9999,2,FALSE)),"",VLOOKUP(C14,AA$1:AC$9999,2,FALSE)) | J14: =IF(E14+G14+K14=0,"",IF(E14=0,((G14^2*PI()/4)*(H14*D14*I14))/1000000+K14,((E14*F14*H14)*(D14*I14))/1000000+K14)) | L14: =IF(L13>0,0,IF(A15&B15=A14&B14,0,IF(COUNTIFS(A:A,A14,B:B,B14)>=2,SUMIFS(J:J,A:A,A14,B:B,B14),0))) -> 0 | Q14: =J14
D15: =IF(ISNA(VLOOKUP(C15,AA$1:AC$9999,2,FALSE)),"",VLOOKUP(C15,AA$1:AC$9999,2,FALSE)) | J15: =IF(E15+G15+K15=0,"",IF(E15=0,((G15^2*PI()/4)*(H15*D15*I15))/1000000+K15,((E15*F15*H15)*(D15*I15))/1000000+K15)) | L15: =IF(L14>0,0,IF(A16&B16=A15&B15,0,IF(COUNTIFS(A:A,A15,B:B,B15)>=2,SUMIFS(J:J,A:A,A15,B:B,B15),0))) -> 0 | Q15: =J15
D16: =IF(ISNA(VLOOKUP(C16,AA$1:AC$9999,2,FALSE)),"",VLOOKUP(C16,AA$1:AC$9999,2,FALSE)) | J16: =IF(E16+G16+K16=0,"",IF(E16=0,((G16^2*PI()/4)*(H16*D16*I16))/1000000+K16,((E16*F16*H16)*(D16*I16))/1000000+K16)) | L16: =IF(L15>0,0,IF(A17&B17=A16&B16,0,IF(COUNTIFS(A:A,A16,B:B,B16)>=2,SUMIFS(J:J,A:A,A16,B:B,B16),0))) -> 0 | Q16: =J16
D17: =IF(ISNA(VLOOKUP(C17,AA$1:AC$9999,2,FALSE)),"",VLOOKUP(C17,AA$1:AC$9999,2,FALSE)) | J17: =IF(E17+G17+K17=0,"",IF(E17=0,((G17^2*PI()/4)*(H17*D17*I17))/1000000+K17,((E17*F17*H17)*(D17*I17))/1000000+K17)) | L17: =IF(L16>0,0,IF(A18&B18=A17&B17,0,IF(COUNTIFS(A:A,A17,B:B,B17)>=2,SUMIFS(J:J,A:A,A17,B:B,B17),0))) -> 0 | Q17: =J17
D18: =IF(ISNA(VLOOKUP(C18,AA$1:AC$9999,2,FALSE)),"",VLOOKUP(C18,AA$1:AC$9999,2,FALSE)) | J18: =IF(E18+G18+K18=0,"",IF(E18=0,((G18^2*PI()/4)*(H18*D18*I18))/1000000+K18,((E18*F18*H18)*(D18*I18))/1000000+K18)) | L18: =IF(L17>0,0,IF(A19&B19=A18&B18,0,IF(COUNTIFS(A:A,A18,B:B,B18)>=2,SUMIFS(J:J,A:A,A18,B:B,B18),0))) -> 0 | Q18: =J18
D19: =IF(ISNA(VLOOKUP(C19,AA$1:AC$9999,2,FALSE)),"",VLOOKUP(C19,AA$1:AC$9999,2,FALSE)) | J19: =IF(E19+G19+K19=0,"",IF(E19=0,((G19^2*PI()/4)*(H19*D19*I19))/1000000+K19,((E19*F19*H19)*(D19*I19))/1000000+K19)) | L19: =IF(L18>0,0,IF(A20&B20=A19&B19,0,IF(COUNTIFS(A:A,A19,B:B,B19)>=2,SUMIFS(J:J,A:A,A19,B:B,B19),0))) -> 0 | Q19: =J19
... D1000: =IF(ISNA(VLOOKUP(C1000,AA$1:AC$9999,2,FALSE)),"",VLOOKUP(C1000,AA$1:AC$9999,2,FALSE)) | J1000: =IF(E1000+G1000+K1000=0,"",IF(E1000=0,((G1000^2*PI()/4)*(H1000*D1000*I1000))/1000000+K1000,((E1000*F1000*H1000)*(D1000*I1000))/1000000+K1000)) | L1000: =IF(L999>0,0,IF(A1001&B1001=A1000&B1000,0,IF(COUNTIFS(A:A,A1000,B:B,B1000)>=2,SUMIFS(J:J,A:A,A1000,B:B,B1000),0))) -> 0 | Q1000: =J1000
D1001: =IF(ISNA(VLOOKUP(C1001,AA$1:AC$9999,2,FALSE)),"",VLOOKUP(C1001,AA$1:AC$9999,2,FALSE)) | Q1001: =J1001 -> 0
D1002: =IF(ISNA(VLOOKUP(C1002,AA$1:AC$9999,2,FALSE)),"",VLOOKUP(C1002,AA$1:AC$9999,2,FALSE)) | Q1002: =J1002 -> 0
D1003: =IF(ISNA(VLOOKUP(C1003,AA$1:AC$9999,2,FALSE)),"",VLOOKUP(C1003,AA$1:AC$9999,2,FALSE)) | Q1003: =J1003 -> 0
D1004: =IF(ISNA(VLOOKUP(C1004,AA$1:AC$9999,2,FALSE)),"",VLOOKUP(C1004,AA$1:AC$9999,2,FALSE)) | Q1004: =J1004 -> 0
D1005: =IF(ISNA(VLOOKUP(C1005,AA$1:AC$9999,2,FALSE)),"",VLOOKUP(C1005,AA$1:AC$9999,2,FALSE)) | Q1005: =J1005 -> 0
D1006: =IF(ISNA(VLOOKUP(C1006,AA$1:AC$9999,2,FALSE)),"",VLOOKUP(C1006,AA$1:AC$9999,2,FALSE)) | Q1006: =J1006 -> 0
D1007: =IF(ISNA(VLOOKUP(C1007,AA$1:AC$9999,2,FALSE)),"",VLOOKUP(C1007,AA$1:AC$9999,2,FALSE)) | Q1007: =J1007 -> 0
D1008: =IF(ISNA(VLOOKUP(C1008,AA$1:AC$9999,2,FALSE)),"",VLOOKUP(C1008,AA$1:AC$9999,2,FALSE)) | Q1008: =J1008 -> 0
D1009: =IF(ISNA(VLOOKUP(C1009,AA$1:AC$9999,2,FALSE)),"",VLOOKUP(C1009,AA$1:AC$9999,2,FALSE)) | Q1009: =J1009 -> 0
D1010: =IF(ISNA(VLOOKUP(C1010,AA$1:AC$9999,2,FALSE)),"",VLOOKUP(C1010,AA$1:AC$9999,2,FALSE)) | Q1010: =J1010 -> 0
D1011: =IF(ISNA(VLOOKUP(C1011,AA$1:AC$9999,2,FALSE)),"",VLOOKUP(C1011,AA$1:AC$9999,2,FALSE)) | Q1011: =J1011 -> 0
D1012: =IF(ISNA(VLOOKUP(C1012,AA$1:AC$9999,2,FALSE)),"",VLOOKUP(C1012,AA$1:AC$9999,2,FALSE)) | Q1012: =J1012 -> 0
... D1106: =IF(ISNA(VLOOKUP(C1106,AA$1:AC$9999,2,FALSE)),"",VLOOKUP(C1106,AA$1:AC$9999,2,FALSE)) | Q1106: =J1106 -> 0
Q1107: =J1107 -> 0
Q1108: =J1108 -> 0
Q1109: =J1109 -> 0
Q1110: =J1110 -> 0
Q1111: =J1111 -> 0
Q1112: =J1112 -> 0
Q1113: =J1113 -> 0
...

Sheet FB&L専用
A1: 参照図 | B1: 使用部位 | C1: 使用部材 | D1: 重量定数 | E1: 長さ(mm) | F1: 弧長/斜め長さ(mm) | G1: 底辺(mm) | H1: 高さ(mm) | I1: Φ(ドーナツ)mm | J1: ドーナツ角度 | K1: ドーナツ幅(mm)or90° | L1: 数量 | M1: 重量 | N1: 付属品(Kg) | O1: 小計 | V1: 総計シート計算用 | AC1: 部材リスト | AD1: 部材重量定数リスト | AE1: 単位
A2: 本体 | B2: FB | C2: FB75x6 | D2: =IF(ISNA(VLOOKUP(C2,AC$1:AE$9999,2,FALSE)),"",VLOOKUP(C2,AC$1:AE$9999,2,FALSE)) -> 3.53 | E2: 4312 | F2: =IF(I2+G2=0,0,IF(I2=0,SQRT(G2^2+H2^2),I2*PI()*(1-(J2/360)))) -> 0 | J2: =IF(I2=0,0,IF(K2="90°",270,ASIN((K2/2)/(I2/2))*180/PI()*2)) -> 0 | L2: 6 | M2: =IF(E2+F2+N2=0,"",IF((D2*F2*L2)/1000+N2=0,(D2*E2*L2)/1000+N2,(D2*F2*L2)/1000+N2)) -> 91.32816 | O2: =IF(O1>0,0,IF(A3&B3=A2&B2,0,IF(COUNTIFS(A:A,A2,B:B,B2)>=2,SUMIFS(M:M,A:A,A2,B:B,B2),0))) -> 0 | V2: =M2 -> 91.32816 | AC2: FB75x6 | AD2: 3.53 | AE2: Kg/m
A3: 本体 | B3: FB | C3: FB75x6 | D3: =IF(ISNA(VLOOKUP(C3,AC$1:AE$9999,2,FALSE)),"",VLOOKUP(C3,AC$1:AE$9999,2,FALSE)) -> 3.53 | E3: 3662 | F3: =IF(I3+G3=0,0,IF(I3=0,SQRT(G3^2+H3^2),I3*PI()*(1-(J3/360)))) -> 0 | J3: =IF(I3=0,0,IF(K3="90°",270,ASIN((K3/2)/(I3/2))*180/PI()*2)) -> 0 | L3: 6 | M3: =IF(E3+F3+N3=0,"",IF((D3*F3*L3)/1000+N3=0,(D3*E3*L3)/1000+N3,(D3*F3*L3)/1000+N3)) -> 77.56116 | O3: =IF(O2>0,0,IF(A4&B4=A3&B3,0,IF(COUNTIFS(A:A,A3,B:B,B3)>=2,SUMIFS(M:M,A:A,A3,B:B,B3),0))) -> 0 | V3: =M3 -> 77.56116 | AC3: FB25x4.5 | AD3: 0.883 | AE3: Kg/m
A4: 本体 | B4: FB | C4: FB75x6 | D4: =IF(ISNA(VLOOKUP(C4,AC$1:AE$9999,2,FALSE)),"",VLOOKUP(C4,AC$1:AE$9999,2,FALSE)) -> 3.53 | E4: 2150 | F4: =IF(I4+G4=0,0,IF(I4=0,SQRT(G4^2+H4^2),I4*PI()*(1-(J4/360)))) -> 0 | J4: =IF(I4=0,0,IF(K4="90°",270,ASIN((K4/2)/(I4/2))*180/PI()*2)) -> 0 | L4: 3 | M4: =IF(E4+F4+N4=0,"",IF((D4*F4*L4)/1000+N4=0,(D4*E4*L4)/1000+N4,(D4*F4*L4)/1000+N4)) -> 22.7685 | O4: =IF(O3>0,0,IF(A5&B5=A4&B4,0,IF(COUNTIFS(A:A,A4,B:B,B4)>=2,SUMIFS(M:M,A:A,A4,B:B,B4),0))) -> 0 | V4: =M4 -> 22.7685 | AC4: L50x50x6 | AD4: 4.43 | AE4: Kg/m
A5: 本体 | B5: FB | C5: FB75x6 | D5: =IF(ISNA(VLOOKUP(C5,AC$1:AE$9999,2,FALSE)),"",VLOOKUP(C5,AC$1:AE$9999,2,FALSE)) -> 3.53 | E5: 1784 | F5: =IF(I5+G5=0,0,IF(I5=0,SQRT(G5^2+H5^2),I5*PI()*(1-(J5/360)))) -> 0 | J5: =IF(I5=0,0,IF(K5="90°",270,ASIN((K5/2)/(I5/2))*180/PI()*2)) -> 0 | L5: 1 | M5: =IF(E5+F5+N5=0,"",IF((D5*F5*L5)/1000+N5=0,(D5*E5*L5)/1000+N5,(D5*F5*L5)/1000+N5)) -> 6.29752 | O5: =IF(O4>0,0,IF(A6&B6=A5&B5,0,IF(COUNTIFS(A:A,A5,B:B,B5)>=2,SUMIFS(M:M,A:A,A5,B:B,B5),0))) -> 197.95534 | V5: =M5 -> 6.29752 | AC5: FB50x6 | AD5: 2.36 | AE5: Kg/m
A6: ノズル他詳細 | B6: 落下防止 | C6: FB25x4.5 | D6: =IF(ISNA(VLOOKUP(C6,AC$1:AE$9999,2,FALSE)),"",VLOOKUP(C6,AC$1:AE$9999,2,FALSE)) -> 0.883 | E6: 444.7 | F6: =IF(I6+G6=0,0,IF(I6=0,SQRT(G6^2+H6^2),I6*PI()*(1-(J6/360)))) -> 0 | J6: =IF(I6=0,0,IF(K6="90°",270,ASIN((K6/2)/(I6/2))*180/PI()*2)) -> 0 | L6: 4 | M6: =IF(E6+F6+N6=0,"",IF((D6*F6*L6)/1000+N6=0,(D6*E6*L6)/1000+N6,(D6*F6*L6)/1000+N6)) -> 1.5706804 | O6: =IF(O5>0,0,IF(A7&B7=A6&B6,0,IF(COUNTIFS(A:A,A6,B:B,B6)>=2,SUMIFS(M:M,A:A,A6,B:B,B6),0))) -> 0 | V6: =M6 -> 1.5706804
A7: 点検ステージ | B7: ステージ内梁L | C7: L50x50x6 | D7: =IF(ISNA(VLOOKUP(C7,AC$1:AE$9999,2,FALSE)),"",VLOOKUP(C7,AC$1:AE$9999,2,FALSE)) -> 4.43 | E7: 1769 | F7: =IF(I7+G7=0,0,IF(I7=0,SQRT(G7^2+H7^2),I7*PI()*(1-(J7/360)))) -> 0 | J7: =IF(I7=0,0,IF(K7="90°",270,ASIN((K7/2)/(I7/2))*180/PI()*2)) -> 0 | L7: 1 | M7: =IF(E7+F7+N7=0,"",IF((D7*F7*L7)/1000+N7=0,(D7*E7*L7)/1000+N7,(D7*F7*L7)/1000+N7)) -> 7.83667 | O7: =IF(O6>0,0,IF(A8&B8=A7&B7,0,IF(COUNTIFS(A:A,A7,B:B,B7)>=2,SUMIFS(M:M,A:A,A7,B:B,B7),0))) -> 0 | V7: =M7 -> 7.83667
A8: 点検ステージ | B8: ステージ内梁L | C8: L50x50x6 | D8: =IF(ISNA(VLOOKUP(C8,AC$1:AE$9999,2,FALSE)),"",VLOOKUP(C8,AC$1:AE$9999,2,FALSE)) -> 4.43 | E8: 831.5 | F8: =IF(I8+G8=0,0,IF(I8=0,SQRT(G8^2+H8^2),I8*PI()*(1-(J8/360)))) -> 0 | J8: =IF(I8=0,0,IF(K8="90°",270,ASIN((K8/2)/(I8/2))*180/PI()*2)) -> 0 | L8: 3 | M8: =IF(E8+F8+N8=0,"",IF((D8*F8*L8)/1000+N8=0,(D8*E8*L8)/1000+N8,(D8*F8*L8)/1000+N8)) -> 11.050635 | O8: =IF(O7>0,0,IF(A9&B9=A8&B8,0,IF(COUNTIFS(A:A,A8,B:B,B8)>=2,SUMIFS(M:M,A:A,A8,B:B,B8),0))) -> 0 | V8: =M8 -> 11.050635
A9: 点検ステージ | B9: ステージ内梁L | C9: L50x50x6 | D9: =IF(ISNA(VLOOKUP(C9,AC$1:AE$9999,2,FALSE)),"",VLOOKUP(C9,AC$1:AE$9999,2,FALSE)) -> 4.43 | E9: 706.5 | F9: =IF(I9+G9=0,0,IF(I9=0,SQRT(G9^2+H9^2),I9*PI()*(1-(J9/360)))) -> 0 | J9: =IF(I9=0,0,IF(K9="90°",270,ASIN((K9/2)/(I9/2))*180/PI()*2)) -> 0 | L9: 1 | M9: =IF(E9+F9+N9=0,"",IF((D9*F9*L9)/1000+N9=0,(D9*E9*L9)/1000+N9,(D9*F9*L9)/1000+N9)) -> 3.129795 | O9: =IF(O8>0,0,IF(A10&B10=A9&B9,0,IF(COUNTIFS(A:A,A9,B:B,B9)>=2,SUMIFS(M:M,A:A,A9,B:B,B9),0))) -> 0 | V9: =M9 -> 3.129795
A10: 点検ステージ | B10: ステージ内梁L | C10: L50x50x6 | D10: =IF(ISNA(VLOOKUP(C10,AC$1:AE$9999,2,FALSE)),"",VLOOKUP(C10,AC$1:AE$9999,2,FALSE)) -> 4.43 | E10: 500 | F10: =IF(I10+G10=0,0,IF(I10=0,SQRT(G10^2+H10^2),I10*PI()*(1-(J10/360)))) -> 0 | J10: =IF(I10=0,0,IF(K10="90°",270,ASIN((K10/2)/(I10/2))*180/PI()*2)) -> 0 | L10: 3 | M10: =IF(E10+F10+N10=0,"",IF((D10*F10*L10)/1000+N10=0,(D10*E10*L10)/1000+N10,(D10*F10*L10)/1000+N10)) -> 6.645 | O10: =IF(O9>0,0,IF(A11&B11=A10&B10,0,IF(COUNTIFS(A:A,A10,B:B,B10)>=2,SUMIFS(M:M,A:A,A10,B:B,B10),0))) -> 0 | V10: =M10 -> 6.645
A11: 点検ステージ | B11: ステージ内梁L | C11: L50x50x6 | D11: =IF(ISNA(VLOOKUP(C11,AC$1:AE$9999,2,FALSE)),"",VLOOKUP(C11,AC$1:AE$9999,2,FALSE)) -> 4.43 | F11: =IF(I11+G11=0,0,IF(I11=0,SQRT(G11^2+H11^2),I11*PI()*(1-(J11/360)))) -> 707.10678 | G11: 500 | H11: 500 | J11: =IF(I11=0,0,IF(K11="90°",270,ASIN((K11/2)/(I11/2))*180/PI()*2)) -> 0 | L11: 1 | M11: =IF(E11+F11+N11=0,"",IF((D11*F11*L11)/1000+N11=0,(D11*E11*L11)/1000+N11,(D11*F11*L11)/1000+N11)) -> 3.132483 | O11: =IF(O10>0,0,IF(A12&B12=A11&B11,0,IF(COUNTIFS(A:A,A11,B:B,B11)>=2,SUMIFS(M:M,A:A,A11,B:B,B11),0))) -> 31.794583 | V11: =M11 -> 3.132483
A12: 手摺配置 | B12: 正面 | C12: FB50x6 | D12: =IF(ISNA(VLOOKUP(C12,AC$1:AE$9999,2,FALSE)),"",VLOOKUP(C12,AC$1:AE$9999,2,FALSE)) -> 2.36 | E12: 3500 | F12: =IF(I12+G12=0,0,IF(I12=0,SQRT(G12^2+H12),I12*PI()*(1-(J12/360)))) -> 0 | J12: =IF(I12=0,0,IF(K12="90°",270,ASIN((K12/2)/(I12/2))*180/PI()*2)) -> 0 | L12: 1 | M12: =IF(E12+F12+N12=0,"",IF((D12*F12*L12)/1000+N12=0,(D12*E12*L12)/1000+N12,(D12*F12*L12)/1000+N12)) -> 8.26 | O12: =IF(O11>0,0,IF(A13&B13=A12&B12,0,IF(COUNTIFS(A:A,A12,B:B,B12)>=2,SUMIFS(M:M,A:A,A12,B:B,B12),0))) -> 0 | V12: =M12 -> 8.26
A13: 手摺配置 | B13: 右側面 | C13: FB50x6 | D13: =IF(ISNA(VLOOKUP(C13,AC$1:AE$9999,2,FALSE)),"",VLOOKUP(C13,AC$1:AE$9999,2,FALSE)) -> 2.36 | E13: 2500 | F13: =IF(I13+G13=0,0,IF(I13=0,SQRT(G13^2+H13),I13*PI()*(1-(J13/360)))) -> 0 | J13: =IF(I13=0,0,IF(K13="90°",270,ASIN((K13/2)/(I13/2))*180/PI()*2)) -> 0 | L13: 1 | M13: =IF(E13+F13+N13=0,"",IF((D13*F13*L13)/1000+N13=0,(D13*E13*L13)/1000+N13,(D13*F13*L13)/1000+N13)) -> 5.9 | O13: =IF(O12>0,0,IF(A14&B14=A13&B13,0,IF(COUNTIFS(A:A,A13,B:B,B13)>=2,SUMIFS(M:M,A:A,A13,B:B,B13),0))) -> 0 | V13: =M13 -> 5.9
A14: 手摺配置 | B14: 左側面1 | C14: FB50x6 | D14: =IF(ISNA(VLOOKUP(C14,AC$1:AE$9999,2,FALSE)),"",VLOOKUP(C14,AC$1:AE$9999,2,FALSE)) -> 2.36 | E14: 2462.5 | F14: =IF(I14+G14=0,0,IF(I14=0,SQRT(G14^2+H14),I14*PI()*(1-(J14/360)))) -> 0 | J14: =IF(I14=0,0,IF(K14="90°",270,ASIN((K14/2)/(I14/2))*180/PI()*2)) -> 0 | L14: 1 | M14: =IF(E14+F14+N14=0,"",IF((D14*F14*L14)/1000+N14=0,(D14*E14*L14)/1000+N14,(D14*F14*L14)/1000+N14)) -> 5.8115 | O14: =IF(O13>0,0,IF(A15&B15=A14&B14,0,IF(COUNTIFS(A:A,A14,B:B,B14)>=2,SUMIFS(M:M,A:A,A14,B:B,B14),0))) -> 0 | V14: =M14 -> 5.8115
A15: 手摺配置 | B15: 左側面2 | C15: FB50x6 | D15: =IF(ISNA(VLOOKUP(C15,AC$1:AE$9999,2,FALSE)),"",VLOOKUP(C15,AC$1:AE$9999,2,FALSE)) -> 2.36 | E15: 1500 | F15: =IF(I15+G15=0,0,IF(I15=0,SQRT(G15^2+H15),I15*PI()*(1-(J15/360)))) -> 0 | J15: =IF(I15=0,0,IF(K15="90°",270,ASIN((K15/2)/(I15/2))*180/PI()*2)) -> 0 | L15: 1 | M15: =IF(E15+F15+N15=0,"",IF((D15*F15*L15)/1000+N15=0,(D15*E15*L15)/1000+N15,(D15*F15*L15)/1000+N15)) -> 3.54 | O15: =IF(O14>0,0,IF(A16&B16=A15&B15,0,IF(COUNTIFS(A:A,A15,B:B,B15)>=2,SUMIFS(M:M,A:A,A15,B:B,B15),0))) -> 0 | V15: =M15 -> 3.54
A16: 手摺配置 | B16: 背面1 | C16: FB50x6 | D16: =IF(ISNA(VLOOKUP(C16,AC$1:AE$9999,2,FALSE)),"",VLOOKUP(C16,AC$1:AE$9999,2,FALSE)) -> 2.36 | E16: 1450 | F16: =IF(I16+G16=0,0,IF(I16=0,SQRT(G16^2+H16),I16*PI()*(1-(J16/360)))) -> 0 | J16: =IF(I16=0,0,IF(K16="90°",270,ASIN((K16/2)/(I16/2))*180/PI()*2)) -> 0 | L16: 1 | M16: =IF(E16+F16+N16=0,"",IF((D16*F16*L16)/1000+N16=0,(D16*E16*L16)/1000+N16,(D16*F16*L16)/1000+N16)) -> 3.422 | O16: =IF(O15>0,0,IF(A17&B17=A16&B16,0,IF(COUNTIFS(A:A,A16,B:B,B16)>=2,SUMIFS(M:M,A:A,A16,B:B,B16),0))) -> 0 | V16: =M16 -> 3.422
A17: 手摺配置 | B17: 背面2 | C17: FB50x6 | D17: =IF(ISNA(VLOOKUP(C17,AC$1:AE$9999,2,FALSE)),"",VLOOKUP(C17,AC$1:AE$9999,2,FALSE)) -> 2.36 | E17: 2812.5 | F17: =IF(I17+G17=0,0,IF(I17=0,SQRT(G17^2+H17),I17*PI()*(1-(J17/360)))) -> 0 | J17: =IF(I17=0,0,IF(K17="90°",270,ASIN((K17/2)/(I17/2))*180/PI()*2)) -> 0 | L17: 1 | M17: =IF(E17+F17+N17=0,"",IF((D17*F17*L17)/1000+N17=0,(D17*E17*L17)/1000+N17,(D17*F17*L17)/1000+N17)) -> 6.6375 | O17: =IF(O16>0,0,IF(A18&B18=A17&B17,0,IF(COUNTIFS(A:A,A17,B:B,B17)>=2,SUMIFS(M:M,A:A,A17,B:B,B17),0))) -> 0 | V17: =M17 -> 6.6375
A18: 手摺配置 | B18: A詳細 | C18: FB50x6 | D18: =IF(ISNA(VLOOKUP(C18,AC$1:AE$9999,2,FALSE)),"",VLOOKUP(C18,AC$1:AE$9999,2,FALSE)) -> 2.36 | E18: 48.65 | F18: =IF(I18+G18=0,0,IF(I18=0,SQRT(G18^2+H18),I18*PI()*(1-(J18/360)))) -> 0 | J18: =IF(I18=0,0,IF(K18="90°",270,ASIN((K18/2)/(I18/2))*180/PI()*2)) -> 0 | L18: 2 | M18: =IF(E18+F18+N18=0,"",IF((D18*F18*L18)/1000+N18=0,(D18*E18*L18)/1000+N18,(D18*F18*L18)/1000+N18)) -> 0.229628 | O18: =IF(O17>0,0,IF(A19&B19=A18&B18,0,IF(COUNTIFS(A:A,A18,B:B,B18)>=2,SUMIFS(M:M,A:A,A18,B:B,B18),0))) -> 0 | V18: =M18 -> 0.229628
A19: ラダー | B19: FB | C19: FB50x6 | D19: =IF(ISNA(VLOOKUP(C19,AC$1:AE$9999,2,FALSE)),"",VLOOKUP(C19,AC$1:AE$9999,2,FALSE)) -> 2.36 | E19: 1140 | F19: =IF(I19+G19=0,0,IF(I19=0,SQRT(G19^2+H19),I19*PI()*(1-(J19/360)))) -> 0 | J19: =IF(I19=0,0,IF(K19="90°",270,ASIN((K19/2)/(I19/2))*180/PI()*2)) -> 0 | L19: 5 | M19: =IF(E19+F19+N19=0,"",IF((D19*F19*L19)/1000+N19=0,(D19*E19*L19)/1000+N19,(D19*F19*L19)/1000+N19)) -> 13.452 | O19: =IF(O18>0,0,IF(A20&B20=A19&B19,0,IF(COUNTIFS(A:A,A19,B:B,B19)>=2,SUMIFS(M:M,A:A,A19,B:B,B19),0))) -> 0 | V19: =M19 -> 13.452
A20: ラダー | B20: FB | C20: FB50x6 | D20: =IF(ISNA(VLOOKUP(C20,AC$1:AE$9999,2,FALSE)),"",VLOOKUP(C20,AC$1:AE$9999,2,FALSE)) -> 2.36 | E20: 980 | F20: =IF(I20+G20=0,0,IF(I20=0,SQRT(G20^2+H20),I20*PI()*(1-(J20/360)))) -> 0 | J20: =IF(I20=0,0,IF(K20="90°",270,ASIN((K20/2)/(I20/2))*180/PI()*2)) -> 0 | L20: 5 | M20: =IF(E20+F20+N20=0,"",IF((D20*F20*L20)/1000+N20=0,(D20*E20*L20)/1000+N20,(D20*F20*L20)/1000+N20)) -> 11.564 | O20: =IF(O19>0,0,IF(A21&B21=A20&B20,0,IF(COUNTIFS(A:A,A20,B:B,B20)>=2,SUMIFS(M:M,A:A,A20,B:B,B20),0))) -> 0 | V20: =M20 -> 11.564
A21: ラダー | B21: FB | C21: FB50x6 | D21: =IF(ISNA(VLOOKUP(C21,AC$1:AE$9999,2,FALSE)),"",VLOOKUP(C21,AC$1:AE$9999,2,FALSE)) -> 2.36 | E21: 268.5 | F21: =IF(I21+G21=0,0,IF(I21=0,SQRT(G21^2+H21),I21*PI()*(1-(J21/360)))) -> 0 | J21: =IF(I21=0,0,IF(K21="90°",270,ASIN((K21/2)/(I21/2))*180/PI()*2)) -> 0 | L21: 1 | M21: =IF(E21+F21+N21=0,"",IF((D21*F21*L21)/1000+N21=0,(D21*E21*L21)/1000+N21,(D21*F21*L21)/1000+N21)) -> 0.63366 | O21: =IF(O20>0,0,IF(A22&B22=A21&B21,0,IF(COUNTIFS(A:A,A21,B:B,B21)>=2,SUMIFS(M:M,A:A,A21,B:B,B21),0))) -> 0 | V21: =M21 -> 0.63366
A22: ラダー | B22: FB | C22: FB50x6 | D22: =IF(ISNA(VLOOKUP(C22,AC$1:AE$9999,2,FALSE)),"",VLOOKUP(C22,AC$1:AE$9999,2,FALSE)) -> 2.36 | F22: =IF(I22+G22=0,0,IF(I22=0,SQRT(G22^2+H22),I22*PI()*(1-(J22/360)))) -> 1578.0977 | I22: 700 | J22: =IF(I22=0,0,IF(K22="90°",270,ASIN((K22/2)/(I22/2))*180/PI()*2)) -> 101.66189 | K22: 542.7 | L22: 2 | M22: =IF(E22+F22+N22=0,"",IF((D22*F22*L22)/1000+N22=0,(D22*E22*L22)/1000+N22,(D22*F22*L22)/1000+N22)) -> 7.4486213 | O22: =IF(O21>0,0,IF(A23&B23=A22&B22,0,IF(COUNTIFS(A:A,A22,B:B,B22)>=2,SUMIFS(M:M,A:A,A22,B:B,B22),0))) -> 33.098281 | V22: =M22 -> 7.4486213
D23: =IF(ISNA(VLOOKUP(C23,AC$1:AE$9999,2,FALSE)),"",VLOOKUP(C23,AC$1:AE$9999,2,FALSE)) | F23: =IF(I23+G23=0,0,IF(I23=0,SQRT(G23^2+H23),I23*PI()*(1-(J23/360)))) -> 0 | J23: =IF(I23=0,0,IF(K23="90°",270,ASIN((K23/2)/(I23/2))*180/PI()*2)) -> 0 | M23: =IF(E23+F23+N23=0,"",IF((D23*F23*L23)/1000+N23=0,(D23*E23*L23)/1000+N23,(D23*F23*L23)/1000+N23)) | O23: =IF(O22>0,0,IF(A24&B24=A23&B23,0,IF(COUNTIFS(A:A,A23,B:B,B23)>=2,SUMIFS(M:M,A:A,A23,B:B,B23),0))) -> 0 | V23: =M23
D24: =IF(ISNA(VLOOKUP(C24,AC$1:AE$9999,2,FALSE)),"",VLOOKUP(C24,AC$1:AE$9999,2,FALSE)) | F24: =IF(I24+G24=0,0,IF(I24=0,SQRT(G24^2+H24),I24*PI()*(1-(J24/360)))) -> 0 | J24: =IF(I24=0,0,IF(K24="90°",270,ASIN((K24/2)/(I24/2))*180/PI()*2)) -> 0 | M24: =IF(E24+F24+N24=0,"",IF((D24*F24*L24)/1000+N24=0,(D24*E24*L24)/1000+N24,(D24*F24*L24)/1000+N24)) | O24: =IF(O23>0,0,IF(A25&B25=A24&B24,0,IF(COUNTIFS(A:A,A24,B:B,B24)>=2,SUMIFS(M:M,A:A,A24,B:B,B24),0))) -> 0 | V24: =M24
D25: =IF(ISNA(VLOOKUP(C25,AC$1:AE$9999,2,FALSE)),"",VLOOKUP(C25,AC$1:AE$9999,2,FALSE)) | F25: =IF(I25+G25=0,0,IF(I25=0,SQRT(G25^2+H25),I25*PI()*(1-(J25/360)))) -> 0 | J25: =IF(I25=0,0,IF(K25="90°",270,ASIN((K25/2)/(I25/2))*180/PI()*2)) -> 0 | M25: =IF(E25+F25+N25=0,"",IF((D25*F25*L25)/1000+N25=0,(D25*E25*L25)/1000+N25,(D25*F25*L25)/1000+N25)) | O25: =IF(O24>0,0,IF(A26&B26=A25&B25,0,IF(COUNTIFS(A:A,A25,B:B,B25)>=2,SUMIFS(M:M,A:A,A25,B:B,B25),0))) -> 0 | V25: =M25
D26: =IF(ISNA(VLOOKUP(C26,AC$1:AE$9999,2,FALSE)),"",VLOOKUP(C26,AC$1:AE$9999,2,FALSE)) | F26: =IF(I26+G26=0,0,IF(I26=0,SQRT(G26^2+H26),I26*PI()*(1-(J26/360)))) -> 0 | J26: =IF(I26=0,0,IF(K26="90°",270,ASIN((K26/2)/(I26/2))*180/PI()*2)) -> 0 | M26: =IF(E26+F26+N26=0,"",IF((D26*F26*L26)/1000+N26=0,(D26*E26*L26)/1000+N26,(D26*F26*L26)/1000+N26)) | O26: =IF(O25>0,0,IF(A27&B27=A26&B26,0,IF(COUNTIFS(A:A,A26,B:B,B26)>=2,SUMIFS(M:M,A:A,A26,B:B,B26),0))) -> 0 | V26: =M26
D27: =IF(ISNA(VLOOKUP(C27,AC$1:AE$9999,2,FALSE)),"",VLOOKUP(C27,AC$1:AE$9999,2,FALSE)) | F27: =IF(I27+G27=0,0,IF(I27=0,SQRT(G27^2+H27),I27*PI()*(1-(J27/360)))) -> 0 | J27: =IF(I27=0,0,IF(K27="90°",270,ASIN((K27/2)/(I27/2))*180/PI()*2)) -> 0 | M27: =IF(E27+F27+N27=0,"",IF((D27*F27*L27)/1000+N27=0,(D27*E27*L27)/1000+N27,(D27*F27*L27)/1000+N27)) | O27: =IF(O26>0,0,IF(A28&B28=A27&B27,0,IF(COUNTIFS(A:A,A27,B:B,B27)>=2,SUMIFS(M:M,A:A,A27,B:B,B27),0))) -> 0 | V27: =M27
D28: =IF(ISNA(VLOOKUP(C28,AC$1:AE$9999,2,FALSE)),"",VLOOKUP(C28,AC$1:AE$9999,2,FALSE)) | F28: =IF(I28+G28=0,0,IF(I28=0,SQRT(G28^2+H28),I28*PI()*(1-(J28/360)))) -> 0 | J28: =IF(I28=0,0,IF(K28="90°",270,ASIN((K28/2)/(I28/2))*180/PI()*2)) -> 0 | M28: =IF(E28+F28+N28=0,"",IF((D28*F28*L28)/1000+N28=0,(D28*E28*L28)/1000+N28,(D28*F28*L28)/1000+N28)) | O28: =IF(O27>0,0,IF(A29&B29=A28&B28,0,IF(COUNTIFS(A:A,A28,B:B,B28)>=2,SUMIFS(M:M,A:A,A28,B:B,B28),0))) -> 0 | V28: =M28
D29: =IF(ISNA(VLOOKUP(C29,AC$1:AE$9999,2,FALSE)),"",VLOOKUP(C29,AC$1:AE$9999,2,FALSE)) | F29: =IF(I29+G29=0,0,IF(I29=0,SQRT(G29^2+H29),I29*PI()*(1-(J29/360)))) -> 0 | J29: =IF(I29=0,0,IF(K29="90°",270,ASIN((K29/2)/(I29/2))*180/PI()*2)) -> 0 | M29: =IF(E29+F29+N29=0,"",IF((D29*F29*L29)/1000+N29=0,(D29*E29*L29)/1000+N29,(D29*F29*L29)/1000+N29)) | O29: =IF(O28>0,0,IF(A30&B30=A29&B29,0,IF(COUNTIFS(A:A,A29,B:B,B29)>=2,SUMIFS(M:M,A:A,A29,B:B,B29),0))) -> 0 | V29: =M29
D30: =IF(ISNA(VLOOKUP(C30,AC$1:AE$9999,2,FALSE)),"",VLOOKUP(C30,AC$1:AE$9999,2,FALSE)) | F30: =IF(I30+G30=0,0,IF(I30=0,SQRT(G30^2+H30),I30*PI()*(1-(J30/360)))) -> 0 | J30: =IF(I30=0,0,IF(K30="90°",270,ASIN((K30/2)/(I30/2))*180/PI()*2)) -> 0 | M30: =IF(E30+F30+N30=0,"",IF((D30*F30*L30)/1000+N30=0,(D30*E30*L30)/1000+N30,(D30*F30*L30)/1000+N30)) | O30: =IF(O29>0,0,IF(A31&B31=A30&B30,0,IF(COUNTIFS(A:A,A30,B:B,B30)>=2,SUMIFS(M:M,A:A,A30,B:B,B30),0))) -> 0 | V30: =M30
D31: =IF(ISNA(VLOOKUP(C31,AC$1:AE$9999,2,FALSE)),"",VLOOKUP(C31,AC$1:AE$9999,2,FALSE)) | F31: =IF(I31+G31=0,0,IF(I31=0,SQRT(G31^2+H31),I31*PI()*(1-(J31/360)))) -> 0 | J31: =IF(I31=0,0,IF(K31="90°",270,ASIN((K31/2)/(I31/2))*180/PI()*2)) -> 0 | M31: =IF(E31+F31+N31=0,"",IF((D31*F31*L31)/1000+N31=0,(D31*E31*L31)/1000+N31,(D31*F31*L31)/1000+N31)) | O31: =IF(O30>0,0,IF(A32&B32=A31&B31,0,IF(COUNTIFS(A:A,A31,B:B,B31)>=2,SUMIFS(M:M,A:A,A31,B:B,B31),0))) -> 0 | V31: =M31
D32: =IF(ISNA(VLOOKUP(C32,AC$1:AE$9999,2,FALSE)),"",VLOOKUP(C32,AC$1:AE$9999,2,FALSE)) | F32: =IF(I32+G32=0,0,IF(I32=0,SQRT(G32^2+H32),I32*PI()*(1-(J32/360)))) -> 0 | J32: =IF(I32=0,0,IF(K32="90°",270,ASIN((K32/2)/(I32/2))*180/PI()*2)) -> 0 | M32: =IF(E32+F32+N32=0,"",IF((D32*F32*L32)/1000+N32=0,(D32*E32*L32)/1000+N32,(D32*F32*L32)/1000+N32)) | O32: =IF(O31>0,0,IF(A33&B33=A32&B32,0,IF(COUNTIFS(A:A,A32,B:B,B32)>=2,SUMIFS(M:M,A:A,A32,B:B,B32),0))) -> 0 | V32: =M32
D33: =IF(ISNA(VLOOKUP(C33,AC$1:AE$9999,2,FALSE)),"",VLOOKUP(C33,AC$1:AE$9999,2,FALSE)) | F33: =IF(I33+G33=0,0,IF(I33=0,SQRT(G33^2+H33),I33*PI()*(1-(J33/360)))) -> 0 | J33: =IF(I33=0,0,IF(K33="90°",270,ASIN((K33/2)/(I33/2))*180/PI()*2)) -> 0 | M33: =IF(E33+F33+N33=0,"",IF((D33*F33*L33)/1000+N33=0,(D33*E33*L33)/1000+N33,(D33*F33*L33)/1000+N33)) | O33: =IF(O32>0,0,IF(A34&B34=A33&B33,0,IF(COUNTIFS(A:A,A33,B:B,B33)>=2,SUMIFS(M:M,A:A,A33,B:B,B33),0))) -> 0 | V33: =M33
D34: =IF(ISNA(VLOOKUP(C34,AC$1:AE$9999,2,FALSE)),"",VLOOKUP(C34,AC$1:AE$9999,2,FALSE)) | F34: =IF(I34+G34=0,0,IF(I34=0,SQRT(G34^2+H34),I34*PI()*(1-(J34/360)))) -> 0 | J34: =IF(I34=0,0,IF(K34="90°",270,ASIN((K34/2)/(I34/2))*180/PI()*2)) -> 0 | M34: =IF(E34+F34+N34=0,"",IF((D34*F34*L34)/1000+N34=0,(D34*E34*L34)/1000+N34,(D34*F34*L34)/1000+N34)) | O34: =IF(O33>0,0,IF(A35&B35=A34&B34,0,IF(COUNTIFS(A:A,A34,B:B,B34)>=2,SUMIFS(M:M,A:A,A34,B:B,B34),0))) -> 0 | V34: =M34
... D1000: =IF(ISNA(VLOOKUP(C1000,AC$1:AE$9999,2,FALSE)),"",VLOOKUP(C1000,AC$1:AE$9999,2,FALSE)) | F1000: =IF(I1000+G1000=0,0,IF(I1000=0,SQRT(G1000^2+H1000),I1000*PI()*(1-(J1000/360)))) -> 0 | J1000: =IF(I1000=0,0,IF(K1000="90°",270,ASIN((K1000/2)/(I1000/2))*180/PI()*2)) -> 0 | M1000: =IF(E1000+F1000+N1000=0,"",IF((D1000*F1000*L1000)/1000+N1000=0,(D1000*E1000*L1000)/1000+N1000,(D1000*F1000*L1000)/1000+N1000)) | O1000: =IF(O999>0,0,IF(A1001&B1001=A1000&B1000,0,IF(COUNTIFS(A:A,A1000,B:B,B1000)>=2,SUMIFS(M:M,A:A,A1000,B:B,B1000),0))) -> 0 | V1000: =M1000
D1001: =IF(ISNA(VLOOKUP(C1001,AC$1:AE$9999,2,FALSE)),"",VLOOKUP(C1001,AC$1:AE$9999,2,FALSE)) | V1001: =M1001 -> 0
D1002: =IF(ISNA(VLOOKUP(C1002,AC$1:AE$9999,2,FALSE)),"",VLOOKUP(C1002,AC$1:AE$9999,2,FALSE)) | V1002: =M1002 -> 0
D1003: =IF(ISNA(VLOOKUP(C1003,AC$1:AE$9999,2,FALSE)),"",VLOOKUP(C1003,AC$1:AE$9999,2,FALSE)) | V1003: =M1003 -> 0
D1004: =IF(ISNA(VLOOKUP(C1004,AC$1:AE$9999,2,FALSE)),"",VLOOKUP(C1004,AC$1:AE$9999,2,FALSE)) | V1004: =M1004 -> 0
D1005: =IF(ISNA(VLOOKUP(C1005,AC$1:AE$9999,2,FALSE)),"",VLOOKUP(C1005,AC$1:AE$9999,2,FALSE)) | V1005: =M1005 -> 0
...

Sheet 鋼材専用
A1: 参照図 | B1: 使用部位 | C1: 使用部材 | D1: 重量定数 | E1: 長さ(mm) | F1: 斜め長さ(mm) | G1: 底辺(mm) | H1: 高さ(mm) | I1: 数量 | J1: 重量 | K1: 付属品(Kg) | L1: 小計 | W1: 総計シート計算用 | AD1: 部材リスト | AE1: 部材重量定数リスト | AF1: 単位
A2: 本体 | B2: 鋼材 | C2: C150x75x6.5 | D2: =IF(ISNA(VLOOKUP(C2,AD$1:AF$9999,2,FALSE)),"",VLOOKUP(C2,AD$1:AF$9999,2,FALSE)) -> 18.6 | E2: 2500 | F2: =IF(E2+G2=0,"",SQRT(G2^2+H2^2)) -> 0 | I2: 20 | J2: =IF(AND(E2+K2=0,F2=""),"",IF(F2=0,(D2*E2*I2)/1000+K2,(D2*F2*I2)/1000+K2)) -> 930 | L2: =IF(L1>0,0,IF(A3&B3=A2&B2,0,IF(COUNTIFS(A:A,A2,B:B,B2)>=2,SUMIFS(J:J,A:A,A2,B:B,B2),0))) -> 0 | W2: =J2 -> 930 | AD2: C150x75x6.5 | AE2: 18.6 | AF2: kg/m
A3: 本体 | B3: 鋼材 | C3: C150x75x6.5 | D3: =IF(ISNA(VLOOKUP(C3,AD$1:AF$9999,2,FALSE)),"",VLOOKUP(C3,AD$1:AF$9999,2,FALSE)) -> 18.6 | E3: 3500 | F3: =IF(E3+G3=0,"",SQRT(G3^2+H3^2)) -> 0 | I3: 3 | J3: =IF(AND(E3+K3=0,F3=""),"",IF(F3=0,(D3*E3*I3)/1000+K3,(D3*F3*I3)/1000+K3)) -> 195.3 | L3: =IF(L2>0,0,IF(A4&B4=A3&B3,0,IF(COUNTIFS(A:A,A3,B:B,B3)>=2,SUMIFS(J:J,A:A,A3,B:B,B3),0))) -> 0 | W3: =J3 -> 195.3 | AD3: C100x50x5 | AE3: 9.36 | AF3: kg/m
A4: 本体 | B4: 鋼材 | C4: C150x75x6.5 | D4: =IF(ISNA(VLOOKUP(C4,AD$1:AF$9999,2,FALSE)),"",VLOOKUP(C4,AD$1:AF$9999,2,FALSE)) -> 18.6 | E4: 1710 | F4: =IF(E4+G4=0,"",SQRT(G4^2+H4^2)) -> 0 | I4: 1 | J4: =IF(AND(E4+K4=0,F4=""),"",IF(F4=0,(D4*E4*I4)/1000+K4,(D4*F4*I4)/1000+K4)) -> 31.806 | L4: =IF(L3>0,0,IF(A5&B5=A4&B4,0,IF(COUNTIFS(A:A,A4,B:B,B4)>=2,SUMIFS(J:J,A:A,A4,B:B,B4),0))) -> 1157.106 | W4: =J4 -> 31.806
A5: 点検ステージ | B5: ステージ外梁C | C5: C150x75x6.5 | D5: =IF(ISNA(VLOOKUP(C5,AD$1:AF$9999,2,FALSE)),"",VLOOKUP(C5,AD$1:AF$9999,2,FALSE)) -> 18.6 | E5: 2177.5 | F5: =IF(E5+G5=0,"",SQRT(G5^2+H5^2)) -> 0 | I5: 2 | J5: =IF(AND(E5+K5=0,F5=""),"",IF(F5=0,(D5*E5*I5)/1000+K5,(D5*F5*I5)/1000+K5)) -> 81.003 | L5: =IF(L4>0,0,IF(A6&B6=A5&B5,0,IF(COUNTIFS(A:A,A5,B:B,B5)>=2,SUMIFS(J:J,A:A,A5,B:B,B5),0))) -> 0 | W5: =J5 -> 81.003
A6: 点検ステージ | B6: ステージ外梁C | C6: C150x75x6.5 | D6: =IF(ISNA(VLOOKUP(C6,AD$1:AF$9999,2,FALSE)),"",VLOOKUP(C6,AD$1:AF$9999,2,FALSE)) -> 18.6 | E6: 2150 | F6: =IF(E6+G6=0,"",SQRT(G6^2+H6^2)) -> 0 | I6: 2 | J6: =IF(AND(E6+K6=0,F6=""),"",IF(F6=0,(D6*E6*I6)/1000+K6,(D6*F6*I6)/1000+K6)) -> 79.98 | L6: =IF(L5>0,0,IF(A7&B7=A6&B6,0,IF(COUNTIFS(A:A,A6,B:B,B6)>=2,SUMIFS(J:J,A:A,A6,B:B,B6),0))) -> 0 | W6: =J6 -> 79.98
A7: 点検ステージ | B7: ステージ外梁C | C7: C150x75x6.5 | D7: =IF(ISNA(VLOOKUP(C7,AD$1:AF$9999,2,FALSE)),"",VLOOKUP(C7,AD$1:AF$9999,2,FALSE)) -> 18.6 | E7: 3425 | F7: =IF(E7+G7=0,"",SQRT(G7^2+H7^2)) -> 0 | I7: 1 | J7: =IF(AND(E7+K7=0,F7=""),"",IF(F7=0,(D7*E7*I7)/1000+K7,(D7*F7*I7)/1000+K7)) -> 63.705 | L7: =IF(L6>0,0,IF(A8&B8=A7&B7,0,IF(COUNTIFS(A:A,A7,B:B,B7)>=2,SUMIFS(J:J,A:A,A7,B:B,B7),0))) -> 0 | W7: =J7 -> 63.705
A8: 点検ステージ | B8: ステージ外梁C | C8: C150x75x6.5 | D8: =IF(ISNA(VLOOKUP(C8,AD$1:AF$9999,2,FALSE)),"",VLOOKUP(C8,AD$1:AF$9999,2,FALSE)) -> 18.6 | E8: 3500 | F8: =IF(E8+G8=0,"",SQRT(G8^2+H8^2)) -> 0 | I8: 1 | J8: =IF(AND(E8+K8=0,F8=""),"",IF(F8=0,(D8*E8*I8)/1000+K8,(D8*F8*I8)/1000+K8)) -> 65.1 | L8: =IF(L7>0,0,IF(A9&B9=A8&B8,0,IF(COUNTIFS(A:A,A8,B:B,B8)>=2,SUMIFS(J:J,A:A,A8,B:B,B8),0))) -> 0 | W8: =J8 -> 65.1
A9: 点検ステージ | B9: ステージ外梁C | C9: C150x75x6.5 | D9: =IF(ISNA(VLOOKUP(C9,AD$1:AF$9999,2,FALSE)),"",VLOOKUP(C9,AD$1:AF$9999,2,FALSE)) -> 18.6 | E9: 1675 | F9: =IF(E9+G9=0,"",SQRT(G9^2+H9^2)) -> 0 | I9: 1 | J9: =IF(AND(E9+K9=0,F9=""),"",IF(F9=0,(D9*E9*I9)/1000+K9,(D9*F9*I9)/1000+K9)) -> 31.155 | L9: =IF(L8>0,0,IF(A10&B10=A9&B9,0,IF(COUNTIFS(A:A,A9,B:B,B9)>=2,SUMIFS(J:J,A:A,A9,B:B,B9),0))) -> 320.943 | W9: =J9 -> 31.155
A10: 点検ステージ | B10: ステージ内梁C | C10: C100x50x5 | D10: =IF(ISNA(VLOOKUP(C10,AD$1:AF$9999,2,FALSE)),"",VLOOKUP(C10,AD$1:AF$9999,2,FALSE)) -> 9.36 | E10: 2000 | F10: =IF(E10+G10=0,"",SQRT(G10^2+H10^2)) -> 0 | I10: 4 | J10: =IF(AND(E10+K10=0,F10=""),"",IF(F10=0,(D10*E10*I10)/1000+K10,(D10*F10*I10)/1000+K10)) -> 74.88 | L10: =IF(L9>0,0,IF(A11&B11=A10&B10,0,IF(COUNTIFS(A:A,A10,B:B,B10)>=2,SUMIFS(J:J,A:A,A10,B:B,B10),0))) -> 0 | W10: =J10 -> 74.88
A11: 点検ステージ | B11: ステージ内梁C | C11: C100x50x5 | D11: =IF(ISNA(VLOOKUP(C11,AD$1:AF$9999,2,FALSE)),"",VLOOKUP(C11,AD$1:AF$9999,2,FALSE)) -> 9.36 | E11: 1675 | F11: =IF(E11+G11=0,"",SQRT(G11^2+H11^2)) -> 0 | I11: 2 | J11: =IF(AND(E11+K11=0,F11=""),"",IF(F11=0,(D11*E11*I11)/1000+K11,(D11*F11*I11)/1000+K11)) -> 31.356 | L11: =IF(L10>0,0,IF(A12&B12=A11&B11,0,IF(COUNTIFS(A:A,A11,B:B,B11)>=2,SUMIFS(J:J,A:A,A11,B:B,B11),0))) -> 106.236 | W11: =J11 -> 31.356
A12: ラダー | B12: AB詳細 | C12: C100x50x5 | D12: =IF(ISNA(VLOOKUP(C12,AD$1:AF$9999,2,FALSE)),"",VLOOKUP(C12,AD$1:AF$9999,2,FALSE)) -> 9.36 | E12: 922 | F12: =IF(E12+G12=0,"",SQRT(G12^2+H12^2)) -> 0 | I12: 2 | J12: =IF(AND(E12+K12=0,F12=""),"",IF(F12=0,(D12*E12*I12)/1000+K12,(D12*F12*I12)/1000+K12)) -> 17.25984 | L12: =IF(L11>0,0,IF(A13&B13=A12&B12,0,IF(COUNTIFS(A:A,A12,B:B,B12)>=2,SUMIFS(J:J,A:A,A12,B:B,B12),0))) -> 0 | W12: =J12 -> 17.25984
D13: =IF(ISNA(VLOOKUP(C13,AD$1:AF$9999,2,FALSE)),"",VLOOKUP(C13,AD$1:AF$9999,2,FALSE)) | F13: =IF(E13+G13=0,"",SQRT(G13^2+H13^2)) | J13: =IF(AND(E13+K13=0,F13=""),"",IF(F13=0,(D13*E13*I13)/1000+K13,(D13*F13*I13)/1000+K13)) | L13: =IF(L12>0,0,IF(A14&B14=A13&B13,0,IF(COUNTIFS(A:A,A13,B:B,B13)>=2,SUMIFS(J:J,A:A,A13,B:B,B13),0))) -> 0 | W13: =J13
D14: =IF(ISNA(VLOOKUP(C14,AD$1:AF$9999,2,FALSE)),"",VLOOKUP(C14,AD$1:AF$9999,2,FALSE)) | F14: =IF(E14+G14=0,"",SQRT(G14^2+H14^2)) | J14: =IF(AND(E14+K14=0,F14=""),"",IF(F14=0,(D14*E14*I14)/1000+K14,(D14*F14*I14)/1000+K14)) | L14: =IF(L13>0,0,IF(A15&B15=A14&B14,0,IF(COUNTIFS(A:A,A14,B:B,B14)>=2,SUMIFS(J:J,A:A,A14,B:B,B14),0))) -> 0 | W14: =J14
D15: =IF(ISNA(VLOOKUP(C15,AD$1:AF$9999,2,FALSE)),"",VLOOKUP(C15,AD$1:AF$9999,2,FALSE)) | F15: =IF(E15+G15=0,"",SQRT(G15^2+H15^2)) | J15: =IF(AND(E15+K15=0,F15=""),"",IF(F15=0,(D15*E15*I15)/1000+K15,(D15*F15*I15)/1000+K15)) | L15: =IF(L14>0,0,IF(A16&B16=A15&B15,0,IF(COUNTIFS(A:A,A15,B:B,B15)>=2,SUMIFS(J:J,A:A,A15,B:B,B15),0))) -> 0 | W15: =J15
D16: =IF(ISNA(VLOOKUP(C16,AD$1:AF$9999,2,FALSE)),"",VLOOKUP(C16,AD$1:AF$9999,2,FALSE)) | F16: =IF(E16+G16=0,"",SQRT(G16^2+H16^2)) | J16: =IF(AND(E16+K16=0,F16=""),"",IF(F16=0,(D16*E16*I16)/1000+K16,(D16*F16*I16)/1000+K16)) | L16: =IF(L15>0,0,IF(A17&B17=A16&B16,0,IF(COUNTIFS(A:A,A16,B:B,B16)>=2,SUMIFS(J:J,A:A,A16,B:B,B16),0))) -> 0 | W16: =J16
