Workbook
Name _4432mm×3632mm×6mm×7.85Kg__100万_758.17Kg: #REF!

Sheet ※取り扱い説明書
A1: 1.【業務内容と時間メモ】のシートに日にちと案件とかけた時間を入れる
A3: 2.【提出用】に【業務内容と時間メモ】に書いた情報が整理＆計算されたうえで書かれてるので、その月のフィルターをかけて範囲を選択して印刷

Sheet 月毎の作業時間
A1: 月 | B1: 代表案件 | C1: 合計時間(H)/月毎 | J1: 分類 | K1: 左表に入れますねぇ！リスト | L1: 左表に入れるか入れないか | M1: ⇔見る必要なし | N1: 月 | O1: 同名案件同名作業計算表 | P1: 案件 | Q1: 作業対象/内容 | R1: 作業対象 | S1: 作業内容 | T1: 作図枚数 | U1: 同月作業合計(H)
A2: =IF(ISNA(VLOOKUP(K2,L2:S9999,3,FALSE)),"",VLOOKUP(K2,L1:S9999,3,FALSE)) | B2: =IF(ISNA(VLOOKUP(K2,L2:S9999,5,FALSE)),"",VLOOKUP(K2,L1:S9999,5,FALSE)&"など") | C2: =IF(SUMIF(N:N,A2,U:U)=0,"",SUMIF(N:N,A2,U:U)) | J2: =IF(O2="","",IF(OR(COUNTIF(O2,"*職場*"),COUNTIF(O2,"*後輩教育*")),"サブ","メイン")) | K2: 左表に入れますねぇ115 | L2: =IF(M2="","",IF(COUNTIF(INDIRECT("M$1:M"&ROW()),"左表に入れますねぇ")>=1,"左表に入れますねぇ"&COUNTIF(INDIRECT("M$1:M"&ROW()),"左表に入れますねぇ"),"")) | M2: =IF(N2="","",IF(COUNTIF(N$1:N2,N2)>1,"",IF(COUNTIF(N:N,N2)>=1,"左表に入れますねぇ",""))) | N2: =IF(ISNA(VLOOKUP(業務内容と時間メモ!M116,業務内容と時間メモ!R$2:AI$9999,11,FALSE)),"",VLOOKUP(業務内容と時間メモ!M116,業務内容と時間メモ!R$2:AI$9999,11,FALSE)) | O2: =IF(ISNA(VLOOKUP(業務内容と時間メモ!M116,業務内容と時間メモ!R$2:AI$9999,13,FALSE)),"",VLOOKUP(業務内容と時間メモ!M116,業務内容と時間メモ!R$2:AI$9999,13,FALSE)) | P2: =IF(ISNA(VLOOKUP(業務内容と時間メモ!M116,業務内容と時間メモ!R$2:AI$9999,15,FALSE)),"",VLOOKUP(業務内容と時間メモ!M116,業務内容と時間メモ!R$2:AI$9999,15,FALSE)) | Q2: =IF(ISNA(VLOOKUP(業務内容と時間メモ!M116,業務内容と時間メモ!R$2:AI$9999,14,FALSE)),"",VLOOKUP(業務内容と時間メモ!M116,業務内容と時間メモ!R$2:AI$9999,14,FALSE)) | R2: =IF(ISNA(VLOOKUP(業務内容と時間メモ!M116,業務内容と時間メモ!R$2:AI$9999,16,FALSE)),"",VLOOKUP(業務内容と時間メモ!M116,業務内容と時間メモ!R$2:AI$9999,16,FALSE)) | S2: =IF(ISNA(VLOOKUP(業務内容と時間メモ!M116,業務内容と時間メモ!R$2:AI$9999,17,FALSE)),"",VLOOKUP(業務内容と時間メモ!M116,業務内容と時間メモ!R$2:AI$9999,17,FALSE)) | T2: =IF(SUMIFS(業務内容と時間メモ!E:E,業務内容と時間メモ!AB:AB,N2,業務内容と時間メモ!AD:AD,O2)=0,"",SUMIFS(業務内容と時間メモ!E:E,業務内容と時間メモ!AB:AB,N2,業務内容と時間メモ!AD:AD,O2)) | U2: =IF(SUMIFS(業務内容と時間メモ!F:F,業務内容と時間メモ!AB:AB,N2,業務内容と時間メモ!AD:AD,O2)=0,"",SUMIFS(業務内容と時間メモ!F:F,業務内容と時間メモ!AB:AB,N2,業務内容と時間メモ!AD:AD,O2))
A3: =IF(ISNA(VLOOKUP(K3,L3:S10000,3,FALSE)),"",VLOOKUP(K3,L2:S10000,3,FALSE)) -> 10 | B3: =IF(ISNA(VLOOKUP(K3,L3:S10000,5,FALSE)),"",VLOOKUP(K3,L2:S10000,5,FALSE)&"など") -> 舞洲1号など | C3: =IF(SUMIF(N:N,A3,U:U)=0,"",SUMIF(N:N,A3,U:U)) -> 112.75 | J3: =IF(O3="","",IF(OR(COUNTIF(O3,"*職場*"),COUNTIF(O3,"*後輩教育*")),"サブ","メイン")) -> メイン | K3: 左表に入れますねぇ1 | L3: =IF(M3="","",IF(COUNTIF(INDIRECT("M$1:M"&ROW()),"左表に入れますねぇ")>=1,"左表に入れますねぇ"&COUNTIF(INDIRECT("M$1:M"&ROW()),"左表に入れますねぇ"),"")) -> 左表に入れますねぇ1 | M3: =IF(N3="","",IF(COUNTIF(N$1:N3,N3)>1,"",IF(COUNTIF(N:N,N3)>=1,"左表に入れますねぇ",""))) -> 左表に入れますねぇ | N3: =IF(ISNA(VLOOKUP(業務内容と時間メモ!M2,業務内容と時間メモ!R$2:AI$9999,11,FALSE)),"",VLOOKUP(業務内容と時間メモ!M2,業務内容と時間メモ!R$2:AI$9999,11,FALSE)) -> 10 | O3: =IF(ISNA(VLOOKUP(業務内容と時間メモ!M2,業務内容と時間メモ!R$2:AI$9999,13,FALSE)),"",VLOOKUP(業務内容と時間メモ!M2,業務内容と時間メモ!R$2:AI$9999,13,FALSE)) -> 舞洲1号砂硅砂コンベヤ振止メ・上部サポート作図 | P3: =IF(ISNA(VLOOKUP(業務内容と時間メモ!M2,業務内容と時間メモ!R$2:AI$9999,15,FALSE)),"",VLOOKUP(業務内容と時間メモ!M2,業務内容と時間メモ!R$2:AI$9999,15,FALSE)) -> 舞洲1号 | Q3: =IF(ISNA(VLOOKUP(業務内容と時間メモ!M2,業務内容と時間メモ!R$2:AI$9999,14,FALSE)),"",VLOOKUP(業務内容と時間メモ!M2,業務内容と時間メモ!R$2:AI$9999,14,FALSE)) -> 砂硅砂コンベヤ振止メ・上部サポート作図 | R3: =IF(ISNA(VLOOKUP(業務内容と時間メモ!M2,業務内容と時間メモ!R$2:AI$9999,16,FALSE)),"",VLOOKUP(業務内容と時間メモ!M2,業務内容と時間メモ!R$2:AI$9999,16,FALSE)) | S3: =IF(ISNA(VLOOKUP(業務内容と時間メモ!M2,業務内容と時間メモ!R$2:AI$9999,17,FALSE)),"",VLOOKUP(業務内容と時間メモ!M2,業務内容と時間メモ!R$2:AI$9999,17,FALSE)) -> 砂硅砂コンベヤ振止メ・上部サポート | T3: =IF(SUMIFS(業務内容と時間メモ!E:E,業務内容と時間メモ!AB:AB,N3,業務内容と時間メモ!AD:AD,O3)=0,"",SUMIFS(業務内容と時間メモ!E:E,業務内容と時間メモ!AB:AB,N3,業務内容と時間メモ!AD:AD,O3)) | U3: =IF(SUMIFS(業務内容と時間メモ!F:F,業務内容と時間メモ!AB:AB,N3,業務内容と時間メモ!AD:AD,O3)=0,"",SUMIFS(業務内容と時間メモ!F:F,業務内容と時間メモ!AB:AB,N3,業務内容と時間メモ!AD:AD,O3)) -> 98.25
A4: =IF(ISNA(VLOOKUP(K4,L4:S10001,3,FALSE)),"",VLOOKUP(K4,L3:S10001,3,FALSE)) -> 12 | B4: =IF(ISNA(VLOOKUP(K4,L4:S10001,5,FALSE)),"",VLOOKUP(K4,L3:S10001,5,FALSE)&"など") -> 職場など | C4: =IF(SUMIF(N:N,A4,U:U)=0,"",SUMIF(N:N,A4,U:U)) -> 176 | J4: =IF(O4="","",IF(OR(COUNTIF(O4,"*職場*"),COUNTIF(O4,"*後輩教育*")),"サブ","メイン")) -> メイン | K4: 左表に入れますねぇ3 | L4: =IF(M4="","",IF(COUNTIF(INDIRECT("M$1:M"&ROW()),"左表に入れますねぇ")>=1,"左表に入れますねぇ"&COUNTIF(INDIRECT("M$1:M"&ROW()),"左表に入れますねぇ"),"")) | M4: =IF(N4="","",IF(COUNTIF(N$1:N4,N4)>1,"",IF(COUNTIF(N:N,N4)>=1,"左表に入れますねぇ",""))) | N4: =IF(ISNA(VLOOKUP(業務内容と時間メモ!M4,業務内容と時間メモ!R$2:AI$9999,11,FALSE)),"",VLOOKUP(業務内容と時間メモ!M4,業務内容と時間メモ!R$2:AI$9999,11,FALSE)) -> 10 | O4: =IF(ISNA(VLOOKUP(業務内容と時間メモ!M4,業務内容と時間メモ!R$2:AI$9999,13,FALSE)),"",VLOOKUP(業務内容と時間メモ!M4,業務内容と時間メモ!R$2:AI$9999,13,FALSE)) -> 舞洲1号灰移送コンベヤ上部サポート作図 | P4: =IF(ISNA(VLOOKUP(業務内容と時間メモ!M4,業務内容と時間メモ!R$2:AI$9999,15,FALSE)),"",VLOOKUP(業務内容と時間メモ!M4,業務内容と時間メモ!R$2:AI$9999,15,FALSE)) -> 舞洲1号 | Q4: =IF(ISNA(VLOOKUP(業務内容と時間メモ!M4,業務内容と時間メモ!R$2:AI$9999,14,FALSE)),"",VLOOKUP(業務内容と時間メモ!M4,業務内容と時間メモ!R$2:AI$9999,14,FALSE)) -> 灰移送コンベヤ上部サポート作図 | R4: =IF(ISNA(VLOOKUP(業務内容と時間メモ!M4,業務内容と時間メモ!R$2:AI$9999,16,FALSE)),"",VLOOKUP(業務内容と時間メモ!M4,業務内容と時間メモ!R$2:AI$9999,16,FALSE)) | S4: =IF(ISNA(VLOOKUP(業務内容と時間メモ!M4,業務内容と時間メモ!R$2:AI$9999,17,FALSE)),"",VLOOKUP(業務内容と時間メモ!M4,業務内容と時間メモ!R$2:AI$9999,17,FALSE)) -> 灰移送コンベヤ上部サポート | T4: =IF(SUMIFS(業務内容と時間メモ!E:E,業務内容と時間メモ!AB:AB,N4,業務内容と時間メモ!AD:AD,O4)=0,"",SUMIFS(業務内容と時間メモ!E:E,業務内容と時間メモ!AB:AB,N4,業務内容と時間メモ!AD:AD,O4)) | U4: =IF(SUMIFS(業務内容と時間メモ!F:F,業務内容と時間メモ!AB:AB,N4,業務内容と時間メモ!AD:AD,O4)=0,"",SUMIFS(業務内容と時間メモ!F:F,業務内容と時間メモ!AB:AB,N4,業務内容と時間メモ!AD:AD,O4)) -> 6.75
A5: =IF(ISNA(VLOOKUP(K5,L5:S10002,3,FALSE)),"",VLOOKUP(K5,L4:S10002,3,FALSE)) -> 4 | B5: =IF(ISNA(VLOOKUP(K5,L5:S10002,5,FALSE)),"",VLOOKUP(K5,L4:S10002,5,FALSE)&"など") -> 東プラ2号など | C5: =IF(SUMIF(N:N,A5,U:U)=0,"",SUMIF(N:N,A5,U:U)) -> 160.75 | J5: =IF(O5="","",IF(OR(COUNTIF(O5,"*職場*"),COUNTIF(O5,"*後輩教育*")),"サブ","メイン")) -> メイン | K5: 左表に入れますねぇ7 | L5: =IF(M5="","",IF(COUNTIF(INDIRECT("M$1:M"&ROW()),"左表に入れますねぇ")>=1,"左表に入れますねぇ"&COUNTIF(INDIRECT("M$1:M"&ROW()),"左表に入れますねぇ"),"")) -> 左表に入れますねぇ2 | M5: =IF(N5="","",IF(COUNTIF(N$1:N5,N5)>1,"",IF(COUNTIF(N:N,N5)>=1,"左表に入れますねぇ",""))) -> 左表に入れますねぇ | N5: =IF(ISNA(VLOOKUP(業務内容と時間メモ!M8,業務内容と時間メモ!R$2:AI$9999,11,FALSE)),"",VLOOKUP(業務内容と時間メモ!M8,業務内容と時間メモ!R$2:AI$9999,11,FALSE)) -> 11 | O5: =IF(ISNA(VLOOKUP(業務内容と時間メモ!M8,業務内容と時間メモ!R$2:AI$9999,13,FALSE)),"",VLOOKUP(業務内容と時間メモ!M8,業務内容と時間メモ!R$2:AI$9999,13,FALSE)) -> 舞洲1号流動ブロワ用ホイストレール作図 | P5: =IF(ISNA(VLOOKUP(業務内容と時間メモ!M8,業務内容と時間メモ!R$2:AI$9999,15,FALSE)),"",VLOOKUP(業務内容と時間メモ!M8,業務内容と時間メモ!R$2:AI$9999,15,FALSE)) -> 舞洲1号 | Q5: =IF(ISNA(VLOOKUP(業務内容と時間メモ!M8,業務内容と時間メモ!R$2:AI$9999,14,FALSE)),"",VLOOKUP(業務内容と時間メモ!M8,業務内容と時間メモ!R$2:AI$9999,14,FALSE)) -> 流動ブロワ用ホイストレール作図 | R5: =IF(ISNA(VLOOKUP(業務内容と時間メモ!M8,業務内容と時間メモ!R$2:AI$9999,16,FALSE)),"",VLOOKUP(業務内容と時間メモ!M8,業務内容と時間メモ!R$2:AI$9999,16,FALSE)) | S5: =IF(ISNA(VLOOKUP(業務内容と時間メモ!M8,業務内容と時間メモ!R$2:AI$9999,17,FALSE)),"",VLOOKUP(業務内容と時間メモ!M8,業務内容と時間メモ!R$2:AI$9999,17,FALSE)) -> 流動ブロワ用ホイストレール | T5: =IF(SUMIFS(業務内容と時間メモ!E:E,業務内容と時間メモ!AB:AB,N5,業務内容と時間メモ!AD:AD,O5)=0,"",SUMIFS(業務内容と時間メモ!E:E,業務内容と時間メモ!AB:AB,N5,業務内容と時間メモ!AD:AD,O5)) | U5: =IF(SUMIFS(業務内容と時間メモ!F:F,業務内容と時間メモ!AB:AB,N5,業務内容と時間メモ!AD:AD,O5)=0,"",SUMIFS(業務内容と時間メモ!F:F,業務内容と時間メモ!AB:AB,N5,業務内容と時間メモ!AD:AD,O5)) -> 8.75
A6: =IF(ISNA(VLOOKUP(K6,L6:S10003,3,FALSE)),"",VLOOKUP(K6,L5:S10003,3,FALSE)) -> 2 | B6: =IF(ISNA(VLOOKUP(K6,L6:S10003,5,FALSE)),"",VLOOKUP(K6,L5:S10003,5,FALSE)&"など") -> 舞洲1号など | C6: =IF(SUMIF(N:N,A6,U:U)=0,"",SUMIF(N:N,A6,U:U)) -> 154.25 | J6: =IF(O6="","",IF(OR(COUNTIF(O6,"*職場*"),COUNTIF(O6,"*後輩教育*")),"サブ","メイン")) -> メイン | K6: 左表に入れますねぇ5 | L6: =IF(M6="","",IF(COUNTIF(INDIRECT("M$1:M"&ROW()),"左表に入れますねぇ")>=1,"左表に入れますねぇ"&COUNTIF(INDIRECT("M$1:M"&ROW()),"左表に入れますねぇ"),"")) | M6: =IF(N6="","",IF(COUNTIF(N$1:N6,N6)>1,"",IF(COUNTIF(N:N,N6)>=1,"左表に入れますねぇ",""))) | N6: =IF(ISNA(VLOOKUP(業務内容と時間メモ!M6,業務内容と時間メモ!R$2:AI$9999,11,FALSE)),"",VLOOKUP(業務内容と時間メモ!M6,業務内容と時間メモ!R$2:AI$9999,11,FALSE)) -> 11 | O6: =IF(ISNA(VLOOKUP(業務内容と時間メモ!M6,業務内容と時間メモ!R$2:AI$9999,13,FALSE)),"",VLOOKUP(業務内容と時間メモ!M6,業務内容と時間メモ!R$2:AI$9999,13,FALSE)) -> 舞洲1号乾燥スクラバ・乾燥排ガスファン用ホイストレール作図 | P6: =IF(ISNA(VLOOKUP(業務内容と時間メモ!M6,業務内容と時間メモ!R$2:AI$9999,15,FALSE)),"",VLOOKUP(業務内容と時間メモ!M6,業務内容と時間メモ!R$2:AI$9999,15,FALSE)) -> 舞洲1号 | Q6: =IF(ISNA(VLOOKUP(業務内容と時間メモ!M6,業務内容と時間メモ!R$2:AI$9999,14,FALSE)),"",VLOOKUP(業務内容と時間メモ!M6,業務内容と時間メモ!R$2:AI$9999,14,FALSE)) -> 乾燥スクラバ・乾燥排ガスファン用ホイストレール作図 | R6: =IF(ISNA(VLOOKUP(業務内容と時間メモ!M6,業務内容と時間メモ!R$2:AI$9999,16,FALSE)),"",VLOOKUP(業務内容と時間メモ!M6,業務内容と時間メモ!R$2:AI$9999,16,FALSE)) | S6: =IF(ISNA(VLOOKUP(業務内容と時間メモ!M6,業務内容と時間メモ!R$2:AI$9999,17,FALSE)),"",VLOOKUP(業務内容と時間メモ!M6,業務内容と時間メモ!R$2:AI$9999,17,FALSE)) -> 乾燥スクラバ・乾燥排ガスファン用ホイストレール | T6: =IF(SUMIFS(業務内容と時間メモ!E:E,業務内容と時間メモ!AB:AB,N6,業務内容と時間メモ!AD:AD,O6)=0,"",SUMIFS(業務内容と時間メモ!E:E,業務内容と時間メモ!AB:AB,N6,業務内容と時間メモ!AD:AD,O6)) | U6: =IF(SUMIFS(業務内容と時間メモ!F:F,業務内容と時間メモ!AB:AB,N6,業務内容と時間メモ!AD:AD,O6)=0,"",SUMIFS(業務内容と時間メモ!F:F,業務内容と時間メモ!AB:AB,N6,業務内容と時間メモ!AD:AD,O6)) -> 10.25
A7: =IF(ISNA(VLOOKUP(K7,L7:S10004,3,FALSE)),"",VLOOKUP(K7,L6:S10004,3,FALSE)) -> 3 | B7: =IF(ISNA(VLOOKUP(K7,L7:S10004,5,FALSE)),"",VLOOKUP(K7,L6:S10004,5,FALSE)&"など") -> 東プラ2号など | C7: =IF(SUMIF(N:N,A7,U:U)=0,"",SUMIF(N:N,A7,U:U)) -> 159.25 | J7: =IF(O7="","",IF(OR(COUNTIF(O7,"*職場*"),COUNTIF(O7,"*後輩教育*")),"サブ","メイン")) -> メイン | K7: 左表に入れますねぇ6 | L7: =IF(M7="","",IF(COUNTIF(INDIRECT("M$1:M"&ROW()),"左表に入れますねぇ")>=1,"左表に入れますねぇ"&COUNTIF(INDIRECT("M$1:M"&ROW()),"左表に入れますねぇ"),"")) | M7: =IF(N7="","",IF(COUNTIF(N$1:N7,N7)>1,"",IF(COUNTIF(N:N,N7)>=1,"左表に入れますねぇ",""))) | N7: =IF(ISNA(VLOOKUP(業務内容と時間メモ!M7,業務内容と時間メモ!R$2:AI$9999,11,FALSE)),"",VLOOKUP(業務内容と時間メモ!M7,業務内容と時間メモ!R$2:AI$9999,11,FALSE)) -> 11 | O7: =IF(ISNA(VLOOKUP(業務内容と時間メモ!M7,業務内容と時間メモ!R$2:AI$9999,13,FALSE)),"",VLOOKUP(業務内容と時間メモ!M7,業務内容と時間メモ!R$2:AI$9999,13,FALSE)) -> 南プラ7号防液提用渡り歩廊用ブラケット作図 | P7: =IF(ISNA(VLOOKUP(業務内容と時間メモ!M7,業務内容と時間メモ!R$2:AI$9999,15,FALSE)),"",VLOOKUP(業務内容と時間メモ!M7,業務内容と時間メモ!R$2:AI$9999,15,FALSE)) -> 南プラ7号 | Q7: =IF(ISNA(VLOOKUP(業務内容と時間メモ!M7,業務内容と時間メモ!R$2:AI$9999,14,FALSE)),"",VLOOKUP(業務内容と時間メモ!M7,業務内容と時間メモ!R$2:AI$9999,14,FALSE)) -> 防液提用渡り歩廊用ブラケット作図 | R7: =IF(ISNA(VLOOKUP(業務内容と時間メモ!M7,業務内容と時間メモ!R$2:AI$9999,16,FALSE)),"",VLOOKUP(業務内容と時間メモ!M7,業務内容と時間メモ!R$2:AI$9999,16,FALSE)) | S7: =IF(ISNA(VLOOKUP(業務内容と時間メモ!M7,業務内容と時間メモ!R$2:AI$9999,17,FALSE)),"",VLOOKUP(業務内容と時間メモ!M7,業務内容と時間メモ!R$2:AI$9999,17,FALSE)) -> 防液提用渡り歩廊用ブラケット | T7: =IF(SUMIFS(業務内容と時間メモ!E:E,業務内容と時間メモ!AB:AB,N7,業務内容と時間メモ!AD:AD,O7)=0,"",SUMIFS(業務内容と時間メモ!E:E,業務内容と時間メモ!AB:AB,N7,業務内容と時間メモ!AD:AD,O7)) | U7: =IF(SUMIFS(業務内容と時間メモ!F:F,業務内容と時間メモ!AB:AB,N7,業務内容と時間メモ!AD:AD,O7)=0,"",SUMIFS(業務内容と時間メモ!F:F,業務内容と時間メモ!AB:AB,N7,業務内容と時間メモ!AD:AD,O7)) -> 17
A8: =IF(ISNA(VLOOKUP(K8,L8:S10005,3,FALSE)),"",VLOOKUP(K8,L7:S10005,3,FALSE)) | B8: =IF(ISNA(VLOOKUP(K8,L8:S10005,5,FALSE)),"",VLOOKUP(K8,L7:S10005,5,FALSE)&"など") | C8: =IF(SUMIF(N:N,A8,U:U)=0,"",SUMIF(N:N,A8,U:U)) | J8: =IF(O8="","",IF(OR(COUNTIF(O8,"*職場*"),COUNTIF(O8,"*後輩教育*")),"サブ","メイン")) -> メイン | K8: 左表に入れますねぇ2 | L8: =IF(M8="","",IF(COUNTIF(INDIRECT("M$1:M"&ROW()),"左表に入れますねぇ")>=1,"左表に入れますねぇ"&COUNTIF(INDIRECT("M$1:M"&ROW()),"左表に入れますねぇ"),"")) | M8: =IF(N8="","",IF(COUNTIF(N$1:N8,N8)>1,"",IF(COUNTIF(N:N,N8)>=1,"左表に入れますねぇ",""))) | N8: =IF(ISNA(VLOOKUP(業務内容と時間メモ!M3,業務内容と時間メモ!R$2:AI$9999,11,FALSE)),"",VLOOKUP(業務内容と時間メモ!M3,業務内容と時間メモ!R$2:AI$9999,11,FALSE)) -> 10 | O8: =IF(ISNA(VLOOKUP(業務内容と時間メモ!M3,業務内容と時間メモ!R$2:AI$9999,13,FALSE)),"",VLOOKUP(業務内容と時間メモ!M3,業務内容と時間メモ!R$2:AI$9999,13,FALSE)) -> 舞洲1号乾燥ケーキ振止メ・上部サポート作図 | P8: =IF(ISNA(VLOOKUP(業務内容と時間メモ!M3,業務内容と時間メモ!R$2:AI$9999,15,FALSE)),"",VLOOKUP(業務内容と時間メモ!M3,業務内容と時間メモ!R$2:AI$9999,15,FALSE)) -> 舞洲1号 | Q8: =IF(ISNA(VLOOKUP(業務内容と時間メモ!M3,業務内容と時間メモ!R$2:AI$9999,14,FALSE)),"",VLOOKUP(業務内容と時間メモ!M3,業務内容と時間メモ!R$2:AI$9999,14,FALSE)) -> 乾燥ケーキ振止メ・上部サポート作図 | R8: =IF(ISNA(VLOOKUP(業務内容と時間メモ!M3,業務内容と時間メモ!R$2:AI$9999,16,FALSE)),"",VLOOKUP(業務内容と時間メモ!M3,業務内容と時間メモ!R$2:AI$9999,16,FALSE)) | S8: =IF(ISNA(VLOOKUP(業務内容と時間メモ!M3,業務内容と時間メモ!R$2:AI$9999,17,FALSE)),"",VLOOKUP(業務内容と時間メモ!M3,業務内容と時間メモ!R$2:AI$9999,17,FALSE)) -> 乾燥ケーキ振止メ・上部サポート | T8: =IF(SUMIFS(業務内容と時間メモ!E:E,業務内容と時間メモ!AB:AB,N8,業務内容と時間メモ!AD:AD,O8)=0,"",SUMIFS(業務内容と時間メモ!E:E,業務内容と時間メモ!AB:AB,N8,業務内容と時間メモ!AD:AD,O8)) | U8: =IF(SUMIFS(業務内容と時間メモ!F:F,業務内容と時間メモ!AB:AB,N8,業務内容と時間メモ!AD:AD,O8)=0,"",SUMIFS(業務内容と時間メモ!F:F,業務内容と時間メモ!AB:AB,N8,業務内容と時間メモ!AD:AD,O8)) -> 7.75
A9: =IF(ISNA(VLOOKUP(K9,L9:S10006,3,FALSE)),"",VLOOKUP(K9,L8:S10006,3,FALSE)) -> 5 | B9: =IF(ISNA(VLOOKUP(K9,L9:S10006,5,FALSE)),"",VLOOKUP(K9,L8:S10006,5,FALSE)&"など") -> 舞洲1号など | C9: =IF(SUMIF(N:N,A9,U:U)=0,"",SUMIF(N:N,A9,U:U)) -> 147.25 | J9: =IF(O9="","",IF(OR(COUNTIF(O9,"*職場*"),COUNTIF(O9,"*後輩教育*")),"サブ","メイン")) -> サブ | K9: 左表に入れますねぇ8 | L9: =IF(M9="","",IF(COUNTIF(INDIRECT("M$1:M"&ROW()),"左表に入れますねぇ")>=1,"左表に入れますねぇ"&COUNTIF(INDIRECT("M$1:M"&ROW()),"左表に入れますねぇ"),"")) | M9: =IF(N9="","",IF(COUNTIF(N$1:N9,N9)>1,"",IF(COUNTIF(N:N,N9)>=1,"左表に入れますねぇ",""))) | N9: =IF(ISNA(VLOOKUP(業務内容と時間メモ!M9,業務内容と時間メモ!R$2:AI$9999,11,FALSE)),"",VLOOKUP(業務内容と時間メモ!M9,業務内容と時間メモ!R$2:AI$9999,11,FALSE)) -> 11 | O9: =IF(ISNA(VLOOKUP(業務内容と時間メモ!M9,業務内容と時間メモ!R$2:AI$9999,13,FALSE)),"",VLOOKUP(業務内容と時間メモ!M9,業務内容と時間メモ!R$2:AI$9999,13,FALSE)) -> 職場自分のデスク回り整理整頓/清掃 | P9: =IF(ISNA(VLOOKUP(業務内容と時間メモ!M9,業務内容と時間メモ!R$2:AI$9999,15,FALSE)),"",VLOOKUP(業務内容と時間メモ!M9,業務内容と時間メモ!R$2:AI$9999,15,FALSE)) -> 職場 | Q9: =IF(ISNA(VLOOKUP(業務内容と時間メモ!M9,業務内容と時間メモ!R$2:AI$9999,14,FALSE)),"",VLOOKUP(業務内容と時間メモ!M9,業務内容と時間メモ!R$2:AI$9999,14,FALSE)) -> 自分のデスク回り整理整頓/清掃 | R9: =IF(ISNA(VLOOKUP(業務内容と時間メモ!M9,業務内容と時間メモ!R$2:AI$9999,16,FALSE)),"",VLOOKUP(業務内容と時間メモ!M9,業務内容と時間メモ!R$2:AI$9999,16,FALSE)) | S9: =IF(ISNA(VLOOKUP(業務内容と時間メモ!M9,業務内容と時間メモ!R$2:AI$9999,17,FALSE)),"",VLOOKUP(業務内容と時間メモ!M9,業務内容と時間メモ!R$2:AI$9999,17,FALSE)) -> 自分のデスク回り | T9: =IF(SUMIFS(業務内容と時間メモ!E:E,業務内容と時間メモ!AB:AB,N9,業務内容と時間メモ!AD:AD,O9)=0,"",SUMIFS(業務内容と時間メモ!E:E,業務内容と時間メモ!AB:AB,N9,業務内容と時間メモ!AD:AD,O9)) | U9: =IF(SUMIFS(業務内容と時間メモ!F:F,業務内容と時間メモ!AB:AB,N9,業務内容と時間メモ!AD:AD,O9)=0,"",SUMIFS(業務内容と時間メモ!F:F,業務内容と時間メモ!AB:AB,N9,業務内容と時間メモ!AD:AD,O9)) -> 1
A10: =IF(ISNA(VLOOKUP(K10,L10:S10007,3,FALSE)),"",VLOOKUP(K10,L9:S10007,3,FALSE)) -> 6 | B10: =IF(ISNA(VLOOKUP(K10,L10:S10007,5,FALSE)),"",VLOOKUP(K10,L9:S10007,5,FALSE)&"など") -> 舞洲1号など | C10: =IF(SUMIF(N:N,A10,U:U)=0,"",SUMIF(N:N,A10,U:U)) -> 163.75 | J10: =IF(O10="","",IF(OR(COUNTIF(O10,"*職場*"),COUNTIF(O10,"*後輩教育*")),"サブ","メイン")) -> メイン | K10: 左表に入れますねぇ9 | L10: =IF(M10="","",IF(COUNTIF(INDIRECT("M$1:M"&ROW()),"左表に入れますねぇ")>=1,"左表に入れますねぇ"&COUNTIF(INDIRECT("M$1:M"&ROW()),"左表に入れますねぇ"),"")) | M10: =IF(N10="","",IF(COUNTIF(N$1:N10,N10)>1,"",IF(COUNTIF(N:N,N10)>=1,"左表に入れますねぇ",""))) | N10: =IF(ISNA(VLOOKUP(業務内容と時間メモ!M10,業務内容と時間メモ!R$2:AI$9999,11,FALSE)),"",VLOOKUP(業務内容と時間メモ!M10,業務内容と時間メモ!R$2:AI$9999,11,FALSE)) -> 11 | O10: =IF(ISNA(VLOOKUP(業務内容と時間メモ!M10,業務内容と時間メモ!R$2:AI$9999,13,FALSE)),"",VLOOKUP(業務内容と時間メモ!M10,業務内容と時間メモ!R$2:AI$9999,13,FALSE)) -> 舞洲1号上部サポート・振止メ複数修正 | P10: =IF(ISNA(VLOOKUP(業務内容と時間メモ!M10,業務内容と時間メモ!R$2:AI$9999,15,FALSE)),"",VLOOKUP(業務内容と時間メモ!M10,業務内容と時間メモ!R$2:AI$9999,15,FALSE)) -> 舞洲1号 | Q10: =IF(ISNA(VLOOKUP(業務内容と時間メモ!M10,業務内容と時間メモ!R$2:AI$9999,14,FALSE)),"",VLOOKUP(業務内容と時間メモ!M10,業務内容と時間メモ!R$2:AI$9999,14,FALSE)) -> 上部サポート・振止メ複数修正 | R10: =IF(ISNA(VLOOKUP(業務内容と時間メモ!M10,業務内容と時間メモ!R$2:AI$9999,16,FALSE)),"",VLOOKUP(業務内容と時間メモ!M10,業務内容と時間メモ!R$2:AI$9999,16,FALSE)) | S10: =IF(ISNA(VLOOKUP(業務内容と時間メモ!M10,業務内容と時間メモ!R$2:AI$9999,17,FALSE)),"",VLOOKUP(業務内容と時間メモ!M10,業務内容と時間メモ!R$2:AI$9999,17,FALSE)) -> 上部サポート・振止メ複数 | T10: =IF(SUMIFS(業務内容と時間メモ!E:E,業務内容と時間メモ!AB:AB,N10,業務内容と時間メモ!AD:AD,O10)=0,"",SUMIFS(業務内容と時間メモ!E:E,業務内容と時間メモ!AB:AB,N10,業務内容と時間メモ!AD:AD,O10)) | U10: =IF(SUMIFS(業務内容と時間メモ!F:F,業務内容と時間メモ!AB:AB,N10,業務内容と時間メモ!AD:AD,O10)=0,"",SUMIFS(業務内容と時間メモ!F:F,業務内容と時間メモ!AB:AB,N10,業務内容と時間メモ!AD:AD,O10)) -> 1.75
A11: =IF(ISNA(VLOOKUP(K11,L11:S10008,3,FALSE)),"",VLOOKUP(K11,L10:S10008,3,FALSE)) -> 7 | B11: =IF(ISNA(VLOOKUP(K11,L11:S10008,5,FALSE)),"",VLOOKUP(K11,L10:S10008,5,FALSE)&"など") -> 新河岸5号など | C11: =IF(SUMIF(N:N,A11,U:U)=0,"",SUMIF(N:N,A11,U:U)) -> 177.25 | J11: =IF(O11="","",IF(OR(COUNTIF(O11,"*職場*"),COUNTIF(O11,"*後輩教育*")),"サブ","メイン")) -> メイン | K11: 左表に入れますねぇ10 | L11: =IF(M11="","",IF(COUNTIF(INDIRECT("M$1:M"&ROW()),"左表に入れますねぇ")>=1,"左表に入れますねぇ"&COUNTIF(INDIRECT("M$1:M"&ROW()),"左表に入れますねぇ"),"")) | M11: =IF(N11="","",IF(COUNTIF(N$1:N11,N11)>1,"",IF(COUNTIF(N:N,N11)>=1,"左表に入れますねぇ",""))) | N11: =IF(ISNA(VLOOKUP(業務内容と時間メモ!M11,業務内容と時間メモ!R$2:AI$9999,11,FALSE)),"",VLOOKUP(業務内容と時間メモ!M11,業務内容と時間メモ!R$2:AI$9999,11,FALSE)) -> 11 | O11: =IF(ISNA(VLOOKUP(業務内容と時間メモ!M11,業務内容と時間メモ!R$2:AI$9999,13,FALSE)),"",VLOOKUP(業務内容と時間メモ!M11,業務内容と時間メモ!R$2:AI$9999,13,FALSE)) -> 舞洲1号乾燥ガス循環ファン用ホイストレール作図 | P11: =IF(ISNA(VLOOKUP(業務内容と時間メモ!M11,業務内容と時間メモ!R$2:AI$9999,15,FALSE)),"",VLOOKUP(業務内容と時間メモ!M11,業務内容と時間メモ!R$2:AI$9999,15,FALSE)) -> 舞洲1号 | Q11: =IF(ISNA(VLOOKUP(業務内容と時間メモ!M11,業務内容と時間メモ!R$2:AI$9999,14,FALSE)),"",VLOOKUP(業務内容と時間メモ!M11,業務内容と時間メモ!R$2:AI$9999,14,FALSE)) -> 乾燥ガス循環ファン用ホイストレール作図 | R11: =IF(ISNA(VLOOKUP(業務内容と時間メモ!M11,業務内容と時間メモ!R$2:AI$9999,16,FALSE)),"",VLOOKUP(業務内容と時間メモ!M11,業務内容と時間メモ!R$2:AI$9999,16,FALSE)) | S11: =IF(ISNA(VLOOKUP(業務内容と時間メモ!M11,業務内容と時間メモ!R$2:AI$9999,17,FALSE)),"",VLOOKUP(業務内容と時間メモ!M11,業務内容と時間メモ!R$2:AI$9999,17,FALSE)) -> 乾燥ガス循環ファン用ホイストレール | T11: =IF(SUMIFS(業務内容と時間メモ!E:E,業務内容と時間メモ!AB:AB,N11,業務内容と時間メモ!AD:AD,O11)=0,"",SUMIFS(業務内容と時間メモ!E:E,業務内容と時間メモ!AB:AB,N11,業務内容と時間メモ!AD:AD,O11)) | U11: =IF(SUMIFS(業務内容と時間メモ!F:F,業務内容と時間メモ!AB:AB,N11,業務内容と時間メモ!AD:AD,O11)=0,"",SUMIFS(業務内容と時間メモ!F:F,業務内容と時間メモ!AB:AB,N11,業務内容と時間メモ!AD:AD,O11)) -> 6.75
A12: =IF(ISNA(VLOOKUP(K12,L12:S10009,3,FALSE)),"",VLOOKUP(K12,L11:S10009,3,FALSE)) -> 8 | B12: =IF(ISNA(VLOOKUP(K12,L12:S10009,5,FALSE)),"",VLOOKUP(K12,L11:S10009,5,FALSE)&"など") -> 仙塩浄化センターなど | C12: =IF(SUMIF(N:N,A12,U:U)=0,"",SUMIF(N:N,A12,U:U)) -> 124 | J12: =IF(O12="","",IF(OR(COUNTIF(O12,"*職場*"),COUNTIF(O12,"*後輩教育*")),"サブ","メイン")) -> メイン | K12: 左表に入れますねぇ11 | L12: =IF(M12="","",IF(COUNTIF(INDIRECT("M$1:M"&ROW()),"左表に入れますねぇ")>=1,"左表に入れますねぇ"&COUNTIF(INDIRECT("M$1:M"&ROW()),"左表に入れますねぇ"),"")) | M12: =IF(N12="","",IF(COUNTIF(N$1:N12,N12)>1,"",IF(COUNTIF(N:N,N12)>=1,"左表に入れますねぇ",""))) | N12: =IF(ISNA(VLOOKUP(業務内容と時間メモ!M12,業務内容と時間メモ!R$2:AI$9999,11,FALSE)),"",VLOOKUP(業務内容と時間メモ!M12,業務内容と時間メモ!R$2:AI$9999,11,FALSE)) -> 11 | O12: =IF(ISNA(VLOOKUP(業務内容と時間メモ!M12,業務内容と時間メモ!R$2:AI$9999,13,FALSE)),"",VLOOKUP(業務内容と時間メモ!M12,業務内容と時間メモ!R$2:AI$9999,13,FALSE)) -> 舞洲1号バーナファン用ホイストレール作図 | P12: =IF(ISNA(VLOOKUP(業務内容と時間メモ!M12,業務内容と時間メモ!R$2:AI$9999,15,FALSE)),"",VLOOKUP(業務内容と時間メモ!M12,業務内容と時間メモ!R$2:AI$9999,15,FALSE)) -> 舞洲1号 | Q12: =IF(ISNA(VLOOKUP(業務内容と時間メモ!M12,業務内容と時間メモ!R$2:AI$9999,14,FALSE)),"",VLOOKUP(業務内容と時間メモ!M12,業務内容と時間メモ!R$2:AI$9999,14,FALSE)) -> バーナファン用ホイストレール作図 | R12: =IF(ISNA(VLOOKUP(業務内容と時間メモ!M12,業務内容と時間メモ!R$2:AI$9999,16,FALSE)),"",VLOOKUP(業務内容と時間メモ!M12,業務内容と時間メモ!R$2:AI$9999,16,FALSE)) | S12: =IF(ISNA(VLOOKUP(業務内容と時間メモ!M12,業務内容と時間メモ!R$2:AI$9999,17,FALSE)),"",VLOOKUP(業務内容と時間メモ!M12,業務内容と時間メモ!R$2:AI$9999,17,FALSE)) -> バーナファン用ホイストレール | T12: =IF(SUMIFS(業務内容と時間メモ!E:E,業務内容と時間メモ!AB:AB,N12,業務内容と時間メモ!AD:AD,O12)=0,"",SUMIFS(業務内容と時間メモ!E:E,業務内容と時間メモ!AB:AB,N12,業務内容と時間メモ!AD:AD,O12)) | U12: =IF(SUMIFS(業務内容と時間メモ!F:F,業務内容と時間メモ!AB:AB,N12,業務内容と時間メモ!AD:AD,O12)=0,"",SUMIFS(業務内容と時間メモ!F:F,業務内容と時間メモ!AB:AB,N12,業務内容と時間メモ!AD:AD,O12)) -> 7.75
A13: =IF(ISNA(VLOOKUP(K13,L13:S10010,3,FALSE)),"",VLOOKUP(K13,L12:S10010,3,FALSE)) -> 9 | B13: =IF(ISNA(VLOOKUP(K13,L13:S10010,5,FALSE)),"",VLOOKUP(K13,L12:S10010,5,FALSE)&"など") -> 新河岸5号など | C13: =IF(SUMIF(N:N,A13,U:U)=0,"",SUMIF(N:N,A13,U:U)) -> 54.25 | J13: =IF(O13="","",IF(OR(COUNTIF(O13,"*職場*"),COUNTIF(O13,"*後輩教育*")),"サブ","メイン")) -> メイン | K13: 左表に入れますねぇ12 | L13: =IF(M13="","",IF(COUNTIF(INDIRECT("M$1:M"&ROW()),"左表に入れますねぇ")>=1,"左表に入れますねぇ"&COUNTIF(INDIRECT("M$1:M"&ROW()),"左表に入れますねぇ"),"")) | M13: =IF(N13="","",IF(COUNTIF(N$1:N13,N13)>1,"",IF(COUNTIF(N:N,N13)>=1,"左表に入れますねぇ",""))) | N13: =IF(ISNA(VLOOKUP(業務内容と時間メモ!M13,業務内容と時間メモ!R$2:AI$9999,11,FALSE)),"",VLOOKUP(業務内容と時間メモ!M13,業務内容と時間メモ!R$2:AI$9999,11,FALSE)) -> 11 | O13: =IF(ISNA(VLOOKUP(業務内容と時間メモ!M13,業務内容と時間メモ!R$2:AI$9999,13,FALSE)),"",VLOOKUP(業務内容と時間メモ!M13,業務内容と時間メモ!R$2:AI$9999,13,FALSE)) -> 舞洲1号メインバーナ/熱風炉 配管ユニット作図 | P13: =IF(ISNA(VLOOKUP(業務内容と時間メモ!M13,業務内容と時間メモ!R$2:AI$9999,15,FALSE)),"",VLOOKUP(業務内容と時間メモ!M13,業務内容と時間メモ!R$2:AI$9999,15,FALSE)) -> 舞洲1号 | Q13: =IF(ISNA(VLOOKUP(業務内容と時間メモ!M13,業務内容と時間メモ!R$2:AI$9999,14,FALSE)),"",VLOOKUP(業務内容と時間メモ!M13,業務内容と時間メモ!R$2:AI$9999,14,FALSE)) -> メインバーナ/熱風炉 配管ユニット作図 | R13: =IF(ISNA(VLOOKUP(業務内容と時間メモ!M13,業務内容と時間メモ!R$2:AI$9999,16,FALSE)),"",VLOOKUP(業務内容と時間メモ!M13,業務内容と時間メモ!R$2:AI$9999,16,FALSE)) | S13: =IF(ISNA(VLOOKUP(業務内容と時間メモ!M13,業務内容と時間メモ!R$2:AI$9999,17,FALSE)),"",VLOOKUP(業務内容と時間メモ!M13,業務内容と時間メモ!R$2:AI$9999,17,FALSE)) -> メインバーナ/熱風炉 配管ユニット | T13: =IF(SUMIFS(業務内容と時間メモ!E:E,業務内容と時間メモ!AB:AB,N13,業務内容と時間メモ!AD:AD,O13)=0,"",SUMIFS(業務内容と時間メモ!E:E,業務内容と時間メモ!AB:AB,N13,業務内容と時間メモ!AD:AD,O13)) | U13: =IF(SUMIFS(業務内容と時間メモ!F:F,業務内容と時間メモ!AB:AB,N13,業務内容と時間メモ!AD:AD,O13)=0,"",SUMIFS(業務内容と時間メモ!F:F,業務内容と時間メモ!AB:AB,N13,業務内容と時間メモ!AD:AD,O13)) -> 10.25
A14: =IF(ISNA(VLOOKUP(K14,L14:S10011,3,FALSE)),"",VLOOKUP(K14,L13:S10011,3,FALSE)) | B14: =IF(ISNA(VLOOKUP(K14,L14:S10011,5,FALSE)),"",VLOOKUP(K14,L13:S10011,5,FALSE)&"など") | C14: =IF(SUMIF(N:N,A14,U:U)=0,"",SUMIF(N:N,A14,U:U)) | J14: =IF(O14="","",IF(OR(COUNTIF(O14,"*職場*"),COUNTIF(O14,"*後輩教育*")),"サブ","メイン")) -> メイン | K14: 左表に入れますねぇ13 | L14: =IF(M14="","",IF(COUNTIF(INDIRECT("M$1:M"&ROW()),"左表に入れますねぇ")>=1,"左表に入れますねぇ"&COUNTIF(INDIRECT("M$1:M"&ROW()),"左表に入れますねぇ"),"")) | M14: =IF(N14="","",IF(COUNTIF(N$1:N14,N14)>1,"",IF(COUNTIF(N:N,N14)>=1,"左表に入れますねぇ",""))) | N14: =IF(ISNA(VLOOKUP(業務内容と時間メモ!M14,業務内容と時間メモ!R$2:AI$9999,11,FALSE)),"",VLOOKUP(業務内容と時間メモ!M14,業務内容と時間メモ!R$2:AI$9999,11,FALSE)) -> 11 | O14: =IF(ISNA(VLOOKUP(業務内容と時間メモ!M14,業務内容と時間メモ!R$2:AI$9999,13,FALSE)),"",VLOOKUP(業務内容と時間メモ!M14,業務内容と時間メモ!R$2:AI$9999,13,FALSE)) -> 舞洲1号仕舞板詳細図作図 | P14: =IF(ISNA(VLOOKUP(業務内容と時間メモ!M14,業務内容と時間メモ!R$2:AI$9999,15,FALSE)),"",VLOOKUP(業務内容と時間メモ!M14,業務内容と時間メモ!R$2:AI$9999,15,FALSE)) -> 舞洲1号 | Q14: =IF(ISNA(VLOOKUP(業務内容と時間メモ!M14,業務内容と時間メモ!R$2:AI$9999,14,FALSE)),"",VLOOKUP(業務内容と時間メモ!M14,業務内容と時間メモ!R$2:AI$9999,14,FALSE)) -> 仕舞板詳細図作図 | R14: =IF(ISNA(VLOOKUP(業務内容と時間メモ!M14,業務内容と時間メモ!R$2:AI$9999,16,FALSE)),"",VLOOKUP(業務内容と時間メモ!M14,業務内容と時間メモ!R$2:AI$9999,16,FALSE)) | S14: =IF(ISNA(VLOOKUP(業務内容と時間メモ!M14,業務内容と時間メモ!R$2:AI$9999,17,FALSE)),"",VLOOKUP(業務内容と時間メモ!M14,業務内容と時間メモ!R$2:AI$9999,17,FALSE)) -> 仕舞板詳細図 | T14: =IF(SUMIFS(業務内容と時間メモ!E:E,業務内容と時間メモ!AB:AB,N14,業務内容と時間メモ!AD:AD,O14)=0,"",SUMIFS(業務内容と時間メモ!E:E,業務内容と時間メモ!AB:AB,N14,業務内容と時間メモ!AD:AD,O14)) | U14: =IF(SUMIFS(業務内容と時間メモ!F:F,業務内容と時間メモ!AB:AB,N14,業務内容と時間メモ!AD:AD,O14)=0,"",SUMIFS(業務内容と時間メモ!F:F,業務内容と時間メモ!AB:AB,N14,業務内容と時間メモ!AD:AD,O14)) -> 20.25
A15: =IF(ISNA(VLOOKUP(K15,L15:S10012,3,FALSE)),"",VLOOKUP(K15,L14:S10012,3,FALSE)) | B15: =IF(ISNA(VLOOKUP(K15,L15:S10012,5,FALSE)),"",VLOOKUP(K15,L14:S10012,5,FALSE)&"など") | C15: =IF(SUMIF(N:N,A15,U:U)=0,"",SUMIF(N:N,A15,U:U)) | J15: =IF(O15="","",IF(OR(COUNTIF(O15,"*職場*"),COUNTIF(O15,"*後輩教育*")),"サブ","メイン")) -> サブ | K15: 左表に入れますねぇ14 | L15: =IF(M15="","",IF(COUNTIF(INDIRECT("M$1:M"&ROW()),"左表に入れますねぇ")>=1,"左表に入れますねぇ"&COUNTIF(INDIRECT("M$1:M"&ROW()),"左表に入れますねぇ"),"")) | M15: =IF(N15="","",IF(COUNTIF(N$1:N15,N15)>1,"",IF(COUNTIF(N:N,N15)>=1,"左表に入れますねぇ",""))) | N15: =IF(ISNA(VLOOKUP(業務内容と時間メモ!M15,業務内容と時間メモ!R$2:AI$9999,11,FALSE)),"",VLOOKUP(業務内容と時間メモ!M15,業務内容と時間メモ!R$2:AI$9999,11,FALSE)) -> 11 | O15: =IF(ISNA(VLOOKUP(業務内容と時間メモ!M15,業務内容と時間メモ!R$2:AI$9999,13,FALSE)),"",VLOOKUP(業務内容と時間メモ!M15,業務内容と時間メモ!R$2:AI$9999,13,FALSE)) -> 職場現場アドバイス聴取 | P15: =IF(ISNA(VLOOKUP(業務内容と時間メモ!M15,業務内容と時間メモ!R$2:AI$9999,15,FALSE)),"",VLOOKUP(業務内容と時間メモ!M15,業務内容と時間メモ!R$2:AI$9999,15,FALSE)) -> 職場 | Q15: =IF(ISNA(VLOOKUP(業務内容と時間メモ!M15,業務内容と時間メモ!R$2:AI$9999,14,FALSE)),"",VLOOKUP(業務内容と時間メモ!M15,業務内容と時間メモ!R$2:AI$9999,14,FALSE)) -> 現場アドバイス聴取 | R15: =IF(ISNA(VLOOKUP(業務内容と時間メモ!M15,業務内容と時間メモ!R$2:AI$9999,16,FALSE)),"",VLOOKUP(業務内容と時間メモ!M15,業務内容と時間メモ!R$2:AI$9999,16,FALSE)) | S15: =IF(ISNA(VLOOKUP(業務内容と時間メモ!M15,業務内容と時間メモ!R$2:AI$9999,17,FALSE)),"",VLOOKUP(業務内容と時間メモ!M15,業務内容と時間メモ!R$2:AI$9999,17,FALSE)) -> 現場 | T15: =IF(SUMIFS(業務内容と時間メモ!E:E,業務内容と時間メモ!AB:AB,N15,業務内容と時間メモ!AD:AD,O15)=0,"",SUMIFS(業務内容と時間メモ!E:E,業務内容と時間メモ!AB:AB,N15,業務内容と時間メモ!AD:AD,O15)) | U15: =IF(SUMIFS(業務内容と時間メモ!F:F,業務内容と時間メモ!AB:AB,N15,業務内容と時間メモ!AD:AD,O15)=0,"",SUMIFS(業務内容と時間メモ!F:F,業務内容と時間メモ!AB:AB,N15,業務内容と時間メモ!AD:AD,O15)) -> 0.5
A16: =IF(ISNA(VLOOKUP(K16,L16:S10013,3,FALSE)),"",VLOOKUP(K16,L15:S10013,3,FALSE)) | B16: =IF(ISNA(VLOOKUP(K16,L16:S10013,5,FALSE)),"",VLOOKUP(K16,L15:S10013,5,FALSE)&"など") | C16: =IF(SUMIF(N:N,A16,U:U)=0,"",SUMIF(N:N,A16,U:U)) | J16: =IF(O16="","",IF(OR(COUNTIF(O16,"*職場*"),COUNTIF(O16,"*後輩教育*")),"サブ","メイン")) -> サブ | K16: 左表に入れますねぇ15 | L16: =IF(M16="","",IF(COUNTIF(INDIRECT("M$1:M"&ROW()),"左表に入れますねぇ")>=1,"左表に入れますねぇ"&COUNTIF(INDIRECT("M$1:M"&ROW()),"左表に入れますねぇ"),"")) | M16: =IF(N16="","",IF(COUNTIF(N$1:N16,N16)>1,"",IF(COUNTIF(N:N,N16)>=1,"左表に入れますねぇ",""))) | N16: =IF(ISNA(VLOOKUP(業務内容と時間メモ!M16,業務内容と時間メモ!R$2:AI$9999,11,FALSE)),"",VLOOKUP(業務内容と時間メモ!M16,業務内容と時間メモ!R$2:AI$9999,11,FALSE)) -> 11 | O16: =IF(ISNA(VLOOKUP(業務内容と時間メモ!M16,業務内容と時間メモ!R$2:AI$9999,13,FALSE)),"",VLOOKUP(業務内容と時間メモ!M16,業務内容と時間メモ!R$2:AI$9999,13,FALSE)) -> 職場高校生向けパンフレット作成打ち合わせ | P16: =IF(ISNA(VLOOKUP(業務内容と時間メモ!M16,業務内容と時間メモ!R$2:AI$9999,15,FALSE)),"",VLOOKUP(業務内容と時間メモ!M16,業務内容と時間メモ!R$2:AI$9999,15,FALSE)) -> 職場 | Q16: =IF(ISNA(VLOOKUP(業務内容と時間メモ!M16,業務内容と時間メモ!R$2:AI$9999,14,FALSE)),"",VLOOKUP(業務内容と時間メモ!M16,業務内容と時間メモ!R$2:AI$9999,14,FALSE)) -> 高校生向けパンフレット作成打ち合わせ | R16: =IF(ISNA(VLOOKUP(業務内容と時間メモ!M16,業務内容と時間メモ!R$2:AI$9999,16,FALSE)),"",VLOOKUP(業務内容と時間メモ!M16,業務内容と時間メモ!R$2:AI$9999,16,FALSE)) | S16: =IF(ISNA(VLOOKUP(業務内容と時間メモ!M16,業務内容と時間メモ!R$2:AI$9999,17,FALSE)),"",VLOOKUP(業務内容と時間メモ!M16,業務内容と時間メモ!R$2:AI$9999,17,FALSE)) -> 高校生向けパンフレット作成 | T16: =IF(SUMIFS(業務内容と時間メモ!E:E,業務内容と時間メモ!AB:AB,N16,業務内容と時間メモ!AD:AD,O16)=0,"",SUMIFS(業務内容と時間メモ!E:E,業務内容と時間メモ!AB:AB,N16,業務内容と時間メモ!AD:AD,O16)) | U16: =IF(SUMIFS(業務内容と時間メモ!F:F,業務内容と時間メモ!AB:AB,N16,業務内容と時間メモ!AD:AD,O16)=0,"",SUMIFS(業務内容と時間メモ!F:F,業務内容と時間メモ!AB:AB,N16,業務内容と時間メモ!AD:AD,O16)) -> 2
A17: =IF(ISNA(VLOOKUP(K17,L17:S10014,3,FALSE)),"",VLOOKUP(K17,L16:S10014,3,FALSE)) | B17: =IF(ISNA(VLOOKUP(K17,L17:S10014,5,FALSE)),"",VLOOKUP(K17,L16:S10014,5,FALSE)&"など") | C17: =IF(SUMIF(N:N,A17,U:U)=0,"",SUMIF(N:N,A17,U:U)) | J17: =IF(O17="","",IF(OR(COUNTIF(O17,"*職場*"),COUNTIF(O17,"*後輩教育*")),"サブ","メイン")) -> サブ | K17: 左表に入れますねぇ16 | L17: =IF(M17="","",IF(COUNTIF(INDIRECT("M$1:M"&ROW()),"左表に入れますねぇ")>=1,"左表に入れますねぇ"&COUNTIF(INDIRECT("M$1:M"&ROW()),"左表に入れますねぇ"),"")) | M17: =IF(N17="","",IF(COUNTIF(N$1:N17,N17)>1,"",IF(COUNTIF(N:N,N17)>=1,"左表に入れますねぇ",""))) | N17: =IF(ISNA(VLOOKUP(業務内容と時間メモ!M17,業務内容と時間メモ!R$2:AI$9999,11,FALSE)),"",VLOOKUP(業務内容と時間メモ!M17,業務内容と時間メモ!R$2:AI$9999,11,FALSE)) -> 11 | O17: =IF(ISNA(VLOOKUP(業務内容と時間メモ!M17,業務内容と時間メモ!R$2:AI$9999,13,FALSE)),"",VLOOKUP(業務内容と時間メモ!M17,業務内容と時間メモ!R$2:AI$9999,13,FALSE)) -> 職場高校生向けパンフレット作成作成 | P17: =IF(ISNA(VLOOKUP(業務内容と時間メモ!M17,業務内容と時間メモ!R$2:AI$9999,15,FALSE)),"",VLOOKUP(業務内容と時間メモ!M17,業務内容と時間メモ!R$2:AI$9999,15,FALSE)) -> 職場 | Q17: =IF(ISNA(VLOOKUP(業務内容と時間メモ!M17,業務内容と時間メモ!R$2:AI$9999,14,FALSE)),"",VLOOKUP(業務内容と時間メモ!M17,業務内容と時間メモ!R$2:AI$9999,14,FALSE)) -> 高校生向けパンフレット作成作成 | R17: =IF(ISNA(VLOOKUP(業務内容と時間メモ!M17,業務内容と時間メモ!R$2:AI$9999,16,FALSE)),"",VLOOKUP(業務内容と時間メモ!M17,業務内容と時間メモ!R$2:AI$9999,16,FALSE)) | S17: =IF(ISNA(VLOOKUP(業務内容と時間メモ!M17,業務内容と時間メモ!R$2:AI$9999,17,FALSE)),"",VLOOKUP(業務内容と時間メモ!M17,業務内容と時間メモ!R$2:AI$9999,17,FALSE)) -> 高校生向けパンフレット作成 | T17: =IF(SUMIFS(業務内容と時間メモ!E:E,業務内容と時間メモ!AB:AB,N17,業務内容と時間メモ!AD:AD,O17)=0,"",SUMIFS(業務内容と時間メモ!E:E,業務内容と時間メモ!AB:AB,N17,業務内容と時間メモ!AD:AD,O17)) | U17: =IF(SUMIFS(業務内容と時間メモ!F:F,業務内容と時間メモ!AB:AB,N17,業務内容と時間メモ!AD:AD,O17)=0,"",SUMIFS(業務内容と時間メモ!F:F,業務内容と時間メモ!AB:AB,N17,業務内容と時間メモ!AD:AD,O17)) -> 41.5
A18: =IF(ISNA(VLOOKUP(K18,L18:S10015,3,FALSE)),"",VLOOKUP(K18,L17:S10015,3,FALSE)) | B18: =IF(ISNA(VLOOKUP(K18,L18:S10015,5,FALSE)),"",VLOOKUP(K18,L17:S10015,5,FALSE)&"など") | C18: =IF(SUMIF(N:N,A18,U:U)=0,"",SUMIF(N:N,A18,U:U)) | J18: =IF(O18="","",IF(OR(COUNTIF(O18,"*職場*"),COUNTIF(O18,"*後輩教育*")),"サブ","メイン")) -> メイン | K18: 左表に入れますねぇ17 | L18: =IF(M18="","",IF(COUNTIF(INDIRECT("M$1:M"&ROW()),"左表に入れますねぇ")>=1,"左表に入れますねぇ"&COUNTIF(INDIRECT("M$1:M"&ROW()),"左表に入れますねぇ"),"")) | M18: =IF(N18="","",IF(COUNTIF(N$1:N18,N18)>1,"",IF(COUNTIF(N:N,N18)>=1,"左表に入れますねぇ",""))) | N18: =IF(ISNA(VLOOKUP(業務内容と時間メモ!M18,業務内容と時間メモ!R$2:AI$9999,11,FALSE)),"",VLOOKUP(業務内容と時間メモ!M18,業務内容と時間メモ!R$2:AI$9999,11,FALSE)) -> 11 | O18: =IF(ISNA(VLOOKUP(業務内容と時間メモ!M18,業務内容と時間メモ!R$2:AI$9999,13,FALSE)),"",VLOOKUP(業務内容と時間メモ!M18,業務内容と時間メモ!R$2:AI$9999,13,FALSE)) -> 舞洲1号乾燥ケーキ搬送コンベヤ上部サポート作図 | P18: =IF(ISNA(VLOOKUP(業務内容と時間メモ!M18,業務内容と時間メモ!R$2:AI$9999,15,FALSE)),"",VLOOKUP(業務内容と時間メモ!M18,業務内容と時間メモ!R$2:AI$9999,15,FALSE)) -> 舞洲1号 | Q18: =IF(ISNA(VLOOKUP(業務内容と時間メモ!M18,業務内容と時間メモ!R$2:AI$9999,14,FALSE)),"",VLOOKUP(業務内容と時間メモ!M18,業務内容と時間メモ!R$2:AI$9999,14,FALSE)) -> 乾燥ケーキ搬送コンベヤ上部サポート作図 | R18: =IF(ISNA(VLOOKUP(業務内容と時間メモ!M18,業務内容と時間メモ!R$2:AI$9999,16,FALSE)),"",VLOOKUP(業務内容と時間メモ!M18,業務内容と時間メモ!R$2:AI$9999,16,FALSE)) | S18: =IF(ISNA(VLOOKUP(業務内容と時間メモ!M18,業務内容と時間メモ!R$2:AI$9999,17,FALSE)),"",VLOOKUP(業務内容と時間メモ!M18,業務内容と時間メモ!R$2:AI$9999,17,FALSE)) -> 乾燥ケーキ搬送コンベヤ上部サポート | T18: =IF(SUMIFS(業務内容と時間メモ!E:E,業務内容と時間メモ!AB:AB,N18,業務内容と時間メモ!AD:AD,O18)=0,"",SUMIFS(業務内容と時間メモ!E:E,業務内容と時間メモ!AB:AB,N18,業務内容と時間メモ!AD:AD,O18)) | U18: =IF(SUMIFS(業務内容と時間メモ!F:F,業務内容と時間メモ!AB:AB,N18,業務内容と時間メモ!AD:AD,O18)=0,"",SUMIFS(業務内容と時間メモ!F:F,業務内容と時間メモ!AB:AB,N18,業務内容と時間メモ!AD:AD,O18)) -> 26
A19: =IF(ISNA(VLOOKUP(K19,L19:S10016,3,FALSE)),"",VLOOKUP(K19,L18:S10016,3,FALSE)) | B19: =IF(ISNA(VLOOKUP(K19,L19:S10016,5,FALSE)),"",VLOOKUP(K19,L18:S10016,5,FALSE)&"など") | C19: =IF(SUMIF(N:N,A19,U:U)=0,"",SUMIF(N:N,A19,U:U)) | J19: =IF(O19="","",IF(OR(COUNTIF(O19,"*職場*"),COUNTIF(O19,"*後輩教育*")),"サブ","メイン")) -> サブ | K19: 左表に入れますねぇ18 | L19: =IF(M19="","",IF(COUNTIF(INDIRECT("M$1:M"&ROW()),"左表に入れますねぇ")>=1,"左表に入れますねぇ"&COUNTIF(INDIRECT("M$1:M"&ROW()),"左表に入れますねぇ"),"")) -> 左表に入れますねぇ3 | M19: =IF(N19="","",IF(COUNTIF(N$1:N19,N19)>1,"",IF(COUNTIF(N:N,N19)>=1,"左表に入れますねぇ",""))) -> 左表に入れますねぇ | N19: =IF(ISNA(VLOOKUP(業務内容と時間メモ!M19,業務内容と時間メモ!R$2:AI$9999,11,FALSE)),"",VLOOKUP(業務内容と時間メモ!M19,業務内容と時間メモ!R$2:AI$9999,11,FALSE)) -> 12 | O19: =IF(ISNA(VLOOKUP(業務内容と時間メモ!M19,業務内容と時間メモ!R$2:AI$9999,13,FALSE)),"",VLOOKUP(業務内容と時間メモ!M19,業務内容と時間メモ!R$2:AI$9999,13,FALSE)) -> 職場高校生向けパンフレット作成作成 | P19: =IF(ISNA(VLOOKUP(業務内容と時間メモ!M19,業務内容と時間メモ!R$2:AI$9999,15,FALSE)),"",VLOOKUP(業務内容と時間メモ!M19,業務内容と時間メモ!R$2:AI$9999,15,FALSE)) -> 職場 | Q19: =IF(ISNA(VLOOKUP(業務内容と時間メモ!M19,業務内容と時間メモ!R$2:AI$9999,14,FALSE)),"",VLOOKUP(業務内容と時間メモ!M19,業務内容と時間メモ!R$2:AI$9999,14,FALSE)) -> 高校生向けパンフレット作成作成 | R19: =IF(ISNA(VLOOKUP(業務内容と時間メモ!M19,業務内容と時間メモ!R$2:AI$9999,16,FALSE)),"",VLOOKUP(業務内容と時間メモ!M19,業務内容と時間メモ!R$2:AI$9999,16,FALSE)) | S19: =IF(ISNA(VLOOKUP(業務内容と時間メモ!M19,業務内容と時間メモ!R$2:AI$9999,17,FALSE)),"",VLOOKUP(業務内容と時間メモ!M19,業務内容と時間メモ!R$2:AI$9999,17,FALSE)) -> 高校生向けパンフレット作成 | T19: =IF(SUMIFS(業務内容と時間メモ!E:E,業務内容と時間メモ!AB:AB,N19,業務内容と時間メモ!AD:AD,O19)=0,"",SUMIFS(業務内容と時間メモ!E:E,業務内容と時間メモ!AB:AB,N19,業務内容と時間メモ!AD:AD,O19)) | U19: =IF(SUMIFS(業務内容と時間メモ!F:F,業務内容と時間メモ!AB:AB,N19,業務内容と時間メモ!AD:AD,O19)=0,"",SUMIFS(業務内容と時間メモ!F:F,業務内容と時間メモ!AB:AB,N19,業務内容と時間メモ!AD:AD,O19)) -> 29
A20: =IF(ISNA(VLOOKUP(K20,L20:S10017,3,FALSE)),"",VLOOKUP(K20,L19:S10017,3,FALSE)) | B20: =IF(ISNA(VLOOKUP(K20,L20:S10017,5,FALSE)),"",VLOOKUP(K20,L19:S10017,5,FALSE)&"など") | C20: =IF(SUMIF(N:N,A20,U:U)=0,"",SUMIF(N:N,A20,U:U)) | J20: =IF(O20="","",IF(OR(COUNTIF(O20,"*職場*"),COUNTIF(O20,"*後輩教育*")),"サブ","メイン")) -> メイン | K20: 左表に入れますねぇ19 | L20: =IF(M20="","",IF(COUNTIF(INDIRECT("M$1:M"&ROW()),"左表に入れますねぇ")>=1,"左表に入れますねぇ"&COUNTIF(INDIRECT("M$1:M"&ROW()),"左表に入れますねぇ"),"")) | M20: =IF(N20="","",IF(COUNTIF(N$1:N20,N20)>1,"",IF(COUNTIF(N:N,N20)>=1,"左表に入れますねぇ",""))) | N20: =IF(ISNA(VLOOKUP(業務内容と時間メモ!M20,業務内容と時間メモ!R$2:AI$9999,11,FALSE)),"",VLOOKUP(業務内容と時間メモ!M20,業務内容と時間メモ!R$2:AI$9999,11,FALSE)) -> 12 | O20: =IF(ISNA(VLOOKUP(業務内容と時間メモ!M20,業務内容と時間メモ!R$2:AI$9999,13,FALSE)),"",VLOOKUP(業務内容と時間メモ!M20,業務内容と時間メモ!R$2:AI$9999,13,FALSE)) -> 舞洲1号乾燥ケーキ搬送コンベヤ上部サポート作図 | P20: =IF(ISNA(VLOOKUP(業務内容と時間メモ!M20,業務内容と時間メモ!R$2:AI$9999,15,FALSE)),"",VLOOKUP(業務内容と時間メモ!M20,業務内容と時間メモ!R$2:AI$9999,15,FALSE)) -> 舞洲1号 | Q20: =IF(ISNA(VLOOKUP(業務内容と時間メモ!M20,業務内容と時間メモ!R$2:AI$9999,14,FALSE)),"",VLOOKUP(業務内容と時間メモ!M20,業務内容と時間メモ!R$2:AI$9999,14,FALSE)) -> 乾燥ケーキ搬送コンベヤ上部サポート作図 | R20: =IF(ISNA(VLOOKUP(業務内容と時間メモ!M20,業務内容と時間メモ!R$2:AI$9999,16,FALSE)),"",VLOOKUP(業務内容と時間メモ!M20,業務内容と時間メモ!R$2:AI$9999,16,FALSE)) | S20: =IF(ISNA(VLOOKUP(業務内容と時間メモ!M20,業務内容と時間メモ!R$2:AI$9999,17,FALSE)),"",VLOOKUP(業務内容と時間メモ!M20,業務内容と時間メモ!R$2:AI$9999,17,FALSE)) -> 乾燥ケーキ搬送コンベヤ上部サポート | T20: =IF(SUMIFS(業務内容と時間メモ!E:E,業務内容と時間メモ!AB:AB,N20,業務内容と時間メモ!AD:AD,O20)=0,"",SUMIFS(業務内容と時間メモ!E:E,業務内容と時間メモ!AB:AB,N20,業務内容と時間メモ!AD:AD,O20)) | U20: =IF(SUMIFS(業務内容と時間メモ!F:F,業務内容と時間メモ!AB:AB,N20,業務内容と時間メモ!AD:AD,O20)=0,"",SUMIFS(業務内容と時間メモ!F:F,業務内容と時間メモ!AB:AB,N20,業務内容と時間メモ!AD:AD,O20)) -> 18
... A63: =IF(ISNA(VLOOKUP(K63,L63:S10060,3,FALSE)),"",VLOOKUP(K63,L62:S10060,3,FALSE)) | B63: =IF(ISNA(VLOOKUP(K63,L63:S10060,5,FALSE)),"",VLOOKUP(K63,L62:S10060,5,FALSE)&"など") | C63: =IF(SUMIF(N:N,A63,U:U)=0,"",SUMIF(N:N,A63,U:U)) | J63: =IF(O63="","",IF(OR(COUNTIF(O63,"*職場*"),COUNTIF(O63,"*後輩教育*")),"サブ","メイン")) -> メイン | K63: 左表に入れますねぇ62 | L63: =IF(M63="","",IF(COUNTIF(INDIRECT("M$1:M"&ROW()),"左表に入れますねぇ")>=1,"左表に入れますねぇ"&COUNTIF(INDIRECT("M$1:M"&ROW()),"左表に入れますねぇ"),"")) -> 左表に入れますねぇ8 | M63: =IF(N63="","",IF(COUNTIF(N$1:N63,N63)>1,"",IF(COUNTIF(N:N,N63)>=1,"左表に入れますねぇ",""))) -> 左表に入れますねぇ | N63: =IF(ISNA(VLOOKUP(業務内容と時間メモ!M63,業務内容と時間メモ!R$2:AI$9999,11,FALSE)),"",VLOOKUP(業務内容と時間メモ!M63,業務内容と時間メモ!R$2:AI$9999,11,FALSE)) -> 5 | O63: =IF(ISNA(VLOOKUP(業務内容と時間メモ!M63,業務内容と時間メモ!R$2:AI$9999,13,FALSE)),"",VLOOKUP(業務内容と時間メモ!M63,業務内容と時間メモ!R$2:AI$9999,13,FALSE)) -> 舞洲1号シュート作図 | P63: =IF(ISNA(VLOOKUP(業務内容と時間メモ!M63,業務内容と時間メモ!R$2:AI$9999,15,FALSE)),"",VLOOKUP(業務内容と時間メモ!M63,業務内容と時間メモ!R$2:AI$9999,15,FALSE)) -> 舞洲1号 | Q63: =IF(ISNA(VLOOKUP(業務内容と時間メモ!M63,業務内容と時間メモ!R$2:AI$9999,14,FALSE)),"",VLOOKUP(業務内容と時間メモ!M63,業務内容と時間メモ!R$2:AI$9999,14,FALSE)) -> シュート作図 | R63: =IF(ISNA(VLOOKUP(業務内容と時間メモ!M63,業務内容と時間メモ!R$2:AI$9999,16,FALSE)),"",VLOOKUP(業務内容と時間メモ!M63,業務内容と時間メモ!R$2:AI$9999,16,FALSE)) | S63: =IF(ISNA(VLOOKUP(業務内容と時間メモ!M63,業務内容と時間メモ!R$2:AI$9999,17,FALSE)),"",VLOOKUP(業務内容と時間メモ!M63,業務内容と時間メモ!R$2:AI$9999,17,FALSE)) -> シュート | T63: =IF(SUMIFS(業務内容と時間メモ!E:E,業務内容と時間メモ!AB:AB,N63,業務内容と時間メモ!AD:AD,O63)=0,"",SUMIFS(業務内容と時間メモ!E:E,業務内容と時間メモ!AB:AB,N63,業務内容と時間メモ!AD:AD,O63)) | U63: =IF(SUMIFS(業務内容と時間メモ!F:F,業務内容と時間メモ!AB:AB,N63,業務内容と時間メモ!AD:AD,O63)=0,"",SUMIFS(業務内容と時間メモ!F:F,業務内容と時間メモ!AB:AB,N63,業務内容と時間メモ!AD:AD,O63)) -> 69.75
A64: =IF(ISNA(VLOOKUP(K64,L64:S10061,3,FALSE)),"",VLOOKUP(K64,L63:S10061,3,FALSE)) | B64: =IF(ISNA(VLOOKUP(K64,L64:S10061,5,FALSE)),"",VLOOKUP(K64,L63:S10061,5,FALSE)&"など") | C64: =IF(SUMIF(N:N,A64,U:U)=0,"",SUMIF(N:N,A64,U:U)) | J64: =IF(O64="","",IF(OR(COUNTIF(O64,"*職場*"),COUNTIF(O64,"*後輩教育*")),"サブ","メイン")) -> メイン | K64: 左表に入れますねぇ66 | L64: =IF(M64="","",IF(COUNTIF(INDIRECT("M$1:M"&ROW()),"左表に入れますねぇ")>=1,"左表に入れますねぇ"&COUNTIF(INDIRECT("M$1:M"&ROW()),"左表に入れますねぇ"),"")) | M64: =IF(N64="","",IF(COUNTIF(N$1:N64,N64)>1,"",IF(COUNTIF(N:N,N64)>=1,"左表に入れますねぇ",""))) | N64: =IF(ISNA(VLOOKUP(業務内容と時間メモ!M67,業務内容と時間メモ!R$2:AI$9999,11,FALSE)),"",VLOOKUP(業務内容と時間メモ!M67,業務内容と時間メモ!R$2:AI$9999,11,FALSE)) -> 5 | O64: =IF(ISNA(VLOOKUP(業務内容と時間メモ!M67,業務内容と時間メモ!R$2:AI$9999,13,FALSE)),"",VLOOKUP(業務内容と時間メモ!M67,業務内容と時間メモ!R$2:AI$9999,13,FALSE)) -> 舞洲1号仕舞板作図 | P64: =IF(ISNA(VLOOKUP(業務内容と時間メモ!M67,業務内容と時間メモ!R$2:AI$9999,15,FALSE)),"",VLOOKUP(業務内容と時間メモ!M67,業務内容と時間メモ!R$2:AI$9999,15,FALSE)) -> 舞洲1号 | Q64: =IF(ISNA(VLOOKUP(業務内容と時間メモ!M67,業務内容と時間メモ!R$2:AI$9999,14,FALSE)),"",VLOOKUP(業務内容と時間メモ!M67,業務内容と時間メモ!R$2:AI$9999,14,FALSE)) -> 仕舞板作図 | R64: =IF(ISNA(VLOOKUP(業務内容と時間メモ!M67,業務内容と時間メモ!R$2:AI$9999,16,FALSE)),"",VLOOKUP(業務内容と時間メモ!M67,業務内容と時間メモ!R$2:AI$9999,16,FALSE)) | S64: =IF(ISNA(VLOOKUP(業務内容と時間メモ!M67,業務内容と時間メモ!R$2:AI$9999,17,FALSE)),"",VLOOKUP(業務内容と時間メモ!M67,業務内容と時間メモ!R$2:AI$9999,17,FALSE)) -> 仕舞板 | T64: =IF(SUMIFS(業務内容と時間メモ!E:E,業務内容と時間メモ!AB:AB,N64,業務内容と時間メモ!AD:AD,O64)=0,"",SUMIFS(業務内容と時間メモ!E:E,業務内容と時間メモ!AB:AB,N64,業務内容と時間メモ!AD:AD,O64)) | U64: =IF(SUMIFS(業務内容と時間メモ!F:F,業務内容と時間メモ!AB:AB,N64,業務内容と時間メモ!AD:AD,O64)=0,"",SUMIFS(業務内容と時間メモ!F:F,業務内容と時間メモ!AB:AB,N64,業務内容と時間メモ!AD:AD,O64)) -> 15.5
A65: =IF(ISNA(VLOOKUP(K65,L65:S10062,3,FALSE)),"",VLOOKUP(K65,L64:S10062,3,FALSE)) | B65: =IF(ISNA(VLOOKUP(K65,L65:S10062,5,FALSE)),"",VLOOKUP(K65,L64:S10062,5,FALSE)&"など") | C65: =IF(SUMIF(N:N,A65,U:U)=0,"",SUMIF(N:N,A65,U:U)) | J65: =IF(O65="","",IF(OR(COUNTIF(O65,"*職場*"),COUNTIF(O65,"*後輩教育*")),"サブ","メイン")) -> メイン | K65: 左表に入れますねぇ63 | L65: =IF(M65="","",IF(COUNTIF(INDIRECT("M$1:M"&ROW()),"左表に入れますねぇ")>=1,"左表に入れますねぇ"&COUNTIF(INDIRECT("M$1:M"&ROW()),"左表に入れますねぇ"),"")) | M65: =IF(N65="","",IF(COUNTIF(N$1:N65,N65)>1,"",IF(COUNTIF(N:N,N65)>=1,"左表に入れますねぇ",""))) | N65: =IF(ISNA(VLOOKUP(業務内容と時間メモ!M64,業務内容と時間メモ!R$2:AI$9999,11,FALSE)),"",VLOOKUP(業務内容と時間メモ!M64,業務内容と時間メモ!R$2:AI$9999,11,FALSE)) -> 5 | O65: =IF(ISNA(VLOOKUP(業務内容と時間メモ!M64,業務内容と時間メモ!R$2:AI$9999,13,FALSE)),"",VLOOKUP(業務内容と時間メモ!M64,業務内容と時間メモ!R$2:AI$9999,13,FALSE)) -> 東プラ2号ダクト作図 | P65: =IF(ISNA(VLOOKUP(業務内容と時間メモ!M64,業務内容と時間メモ!R$2:AI$9999,15,FALSE)),"",VLOOKUP(業務内容と時間メモ!M64,業務内容と時間メモ!R$2:AI$9999,15,FALSE)) -> 東プラ2号 | Q65: =IF(ISNA(VLOOKUP(業務内容と時間メモ!M64,業務内容と時間メモ!R$2:AI$9999,14,FALSE)),"",VLOOKUP(業務内容と時間メモ!M64,業務内容と時間メモ!R$2:AI$9999,14,FALSE)) -> ダクト作図 | R65: =IF(ISNA(VLOOKUP(業務内容と時間メモ!M64,業務内容と時間メモ!R$2:AI$9999,16,FALSE)),"",VLOOKUP(業務内容と時間メモ!M64,業務内容と時間メモ!R$2:AI$9999,16,FALSE)) | S65: =IF(ISNA(VLOOKUP(業務内容と時間メモ!M64,業務内容と時間メモ!R$2:AI$9999,17,FALSE)),"",VLOOKUP(業務内容と時間メモ!M64,業務内容と時間メモ!R$2:AI$9999,17,FALSE)) -> ダクト | T65: =IF(SUMIFS(業務内容と時間メモ!E:E,業務内容と時間メモ!AB:AB,N65,業務内容と時間メモ!AD:AD,O65)=0,"",SUMIFS(業務内容と時間メモ!E:E,業務内容と時間メモ!AB:AB,N65,業務内容と時間メモ!AD:AD,O65)) | U65: =IF(SUMIFS(業務内容と時間メモ!F:F,業務内容と時間メモ!AB:AB,N65,業務内容と時間メモ!AD:AD,O65)=0,"",SUMIFS(業務内容と時間メモ!F:F,業務内容と時間メモ!AB:AB,N65,業務内容と時間メモ!AD:AD,O65)) -> 31
A66: =IF(ISNA(VLOOKUP(K66,L66:S10063,3,FALSE)),"",VLOOKUP(K66,L65:S10063,3,FALSE)) | B66: =IF(ISNA(VLOOKUP(K66,L66:S10063,5,FALSE)),"",VLOOKUP(K66,L65:S10063,5,FALSE)&"など") | C66: =IF(SUMIF(N:N,A66,U:U)=0,"",SUMIF(N:N,A66,U:U)) | J66: =IF(O66="","",IF(OR(COUNTIF(O66,"*職場*"),COUNTIF(O66,"*後輩教育*")),"サブ","メイン")) -> メイン | K66: 左表に入れますねぇ65 | L66: =IF(M66="","",IF(COUNTIF(INDIRECT("M$1:M"&ROW()),"左表に入れますねぇ")>=1,"左表に入れますねぇ"&COUNTIF(INDIRECT("M$1:M"&ROW()),"左表に入れますねぇ"),"")) | M66: =IF(N66="","",IF(COUNTIF(N$1:N66,N66)>1,"",IF(COUNTIF(N:N,N66)>=1,"左表に入れますねぇ",""))) | N66: =IF(ISNA(VLOOKUP(業務内容と時間メモ!M66,業務内容と時間メモ!R$2:AI$9999,11,FALSE)),"",VLOOKUP(業務内容と時間メモ!M66,業務内容と時間メモ!R$2:AI$9999,11,FALSE)) -> 5 | O66: =IF(ISNA(VLOOKUP(業務内容と時間メモ!M66,業務内容と時間メモ!R$2:AI$9999,13,FALSE)),"",VLOOKUP(業務内容と時間メモ!M66,業務内容と時間メモ!R$2:AI$9999,13,FALSE)) -> 中部水再生センター汚水集合管作図 | P66: =IF(ISNA(VLOOKUP(業務内容と時間メモ!M66,業務内容と時間メモ!R$2:AI$9999,15,FALSE)),"",VLOOKUP(業務内容と時間メモ!M66,業務内容と時間メモ!R$2:AI$9999,15,FALSE)) -> 中部水再生センター | Q66: =IF(ISNA(VLOOKUP(業務内容と時間メモ!M66,業務内容と時間メモ!R$2:AI$9999,14,FALSE)),"",VLOOKUP(業務内容と時間メモ!M66,業務内容と時間メモ!R$2:AI$9999,14,FALSE)) -> 汚水集合管作図 | R66: =IF(ISNA(VLOOKUP(業務内容と時間メモ!M66,業務内容と時間メモ!R$2:AI$9999,16,FALSE)),"",VLOOKUP(業務内容と時間メモ!M66,業務内容と時間メモ!R$2:AI$9999,16,FALSE)) | S66: =IF(ISNA(VLOOKUP(業務内容と時間メモ!M66,業務内容と時間メモ!R$2:AI$9999,17,FALSE)),"",VLOOKUP(業務内容と時間メモ!M66,業務内容と時間メモ!R$2:AI$9999,17,FALSE)) -> 汚水集合管 | T66: =IF(SUMIFS(業務内容と時間メモ!E:E,業務内容と時間メモ!AB:AB,N66,業務内容と時間メモ!AD:AD,O66)=0,"",SUMIFS(業務内容と時間メモ!E:E,業務内容と時間メモ!AB:AB,N66,業務内容と時間メモ!AD:AD,O66)) | U66: =IF(SUMIFS(業務内容と時間メモ!F:F,業務内容と時間メモ!AB:AB,N66,業務内容と時間メモ!AD:AD,O66)=0,"",SUMIFS(業務内容と時間メモ!F:F,業務内容と時間メモ!AB:AB,N66,業務内容と時間メモ!AD:AD,O66)) -> 31
A67: =IF(ISNA(VLOOKUP(K67,L67:S10064,3,FALSE)),"",VLOOKUP(K67,L66:S10064,3,FALSE)) | B67: =IF(ISNA(VLOOKUP(K67,L67:S10064,5,FALSE)),"",VLOOKUP(K67,L66:S10064,5,FALSE)&"など") | C67: =IF(SUMIF(N:N,A67,U:U)=0,"",SUMIF(N:N,A67,U:U)) | J67: =IF(O67="","",IF(OR(COUNTIF(O67,"*職場*"),COUNTIF(O67,"*後輩教育*")),"サブ","メイン")) -> サブ | K67: 左表に入れますねぇ64 | L67: =IF(M67="","",IF(COUNTIF(INDIRECT("M$1:M"&ROW()),"左表に入れますねぇ")>=1,"左表に入れますねぇ"&COUNTIF(INDIRECT("M$1:M"&ROW()),"左表に入れますねぇ"),"")) | M67: =IF(N67="","",IF(COUNTIF(N$1:N67,N67)>1,"",IF(COUNTIF(N:N,N67)>=1,"左表に入れますねぇ",""))) | N67: =IF(ISNA(VLOOKUP(業務内容と時間メモ!M65,業務内容と時間メモ!R$2:AI$9999,11,FALSE)),"",VLOOKUP(業務内容と時間メモ!M65,業務内容と時間メモ!R$2:AI$9999,11,FALSE)) -> 5 | O67: =IF(ISNA(VLOOKUP(業務内容と時間メモ!M65,業務内容と時間メモ!R$2:AI$9999,13,FALSE)),"",VLOOKUP(業務内容と時間メモ!M65,業務内容と時間メモ!R$2:AI$9999,13,FALSE)) -> 職場休み全日休暇(-7.75時間) | P67: =IF(ISNA(VLOOKUP(業務内容と時間メモ!M65,業務内容と時間メモ!R$2:AI$9999,15,FALSE)),"",VLOOKUP(業務内容と時間メモ!M65,業務内容と時間メモ!R$2:AI$9999,15,FALSE)) -> 職場 | Q67: =IF(ISNA(VLOOKUP(業務内容と時間メモ!M65,業務内容と時間メモ!R$2:AI$9999,14,FALSE)),"",VLOOKUP(業務内容と時間メモ!M65,業務内容と時間メモ!R$2:AI$9999,14,FALSE)) -> 休み全日休暇(-7.75時間) | R67: =IF(ISNA(VLOOKUP(業務内容と時間メモ!M65,業務内容と時間メモ!R$2:AI$9999,16,FALSE)),"",VLOOKUP(業務内容と時間メモ!M65,業務内容と時間メモ!R$2:AI$9999,16,FALSE)) | S67: =IF(ISNA(VLOOKUP(業務内容と時間メモ!M65,業務内容と時間メモ!R$2:AI$9999,17,FALSE)),"",VLOOKUP(業務内容と時間メモ!M65,業務内容と時間メモ!R$2:AI$9999,17,FALSE)) -> 休み | T67: =IF(SUMIFS(業務内容と時間メモ!E:E,業務内容と時間メモ!AB:AB,N67,業務内容と時間メモ!AD:AD,O67)=0,"",SUMIFS(業務内容と時間メモ!E:E,業務内容と時間メモ!AB:AB,N67,業務内容と時間メモ!AD:AD,O67)) | U67: =IF(SUMIFS(業務内容と時間メモ!F:F,業務内容と時間メモ!AB:AB,N67,業務内容と時間メモ!AD:AD,O67)=0,"",SUMIFS(業務内容と時間メモ!F:F,業務内容と時間メモ!AB:AB,N67,業務内容と時間メモ!AD:AD,O67))
A68: =IF(ISNA(VLOOKUP(K68,L68:S10065,3,FALSE)),"",VLOOKUP(K68,L67:S10065,3,FALSE)) | B68: =IF(ISNA(VLOOKUP(K68,L68:S10065,5,FALSE)),"",VLOOKUP(K68,L67:S10065,5,FALSE)&"など") | C68: =IF(SUMIF(N:N,A68,U:U)=0,"",SUMIF(N:N,A68,U:U)) | J68: =IF(O68="","",IF(OR(COUNTIF(O68,"*職場*"),COUNTIF(O68,"*後輩教育*")),"サブ","メイン")) -> メイン | K68: 左表に入れますねぇ67 | L68: =IF(M68="","",IF(COUNTIF(INDIRECT("M$1:M"&ROW()),"左表に入れますねぇ")>=1,"左表に入れますねぇ"&COUNTIF(INDIRECT("M$1:M"&ROW()),"左表に入れますねぇ"),"")) -> 左表に入れますねぇ9 | M68: =IF(N68="","",IF(COUNTIF(N$1:N68,N68)>1,"",IF(COUNTIF(N:N,N68)>=1,"左表に入れますねぇ",""))) -> 左表に入れますねぇ | N68: =IF(ISNA(VLOOKUP(業務内容と時間メモ!M68,業務内容と時間メモ!R$2:AI$9999,11,FALSE)),"",VLOOKUP(業務内容と時間メモ!M68,業務内容と時間メモ!R$2:AI$9999,11,FALSE)) -> 6 | O68: =IF(ISNA(VLOOKUP(業務内容と時間メモ!M68,業務内容と時間メモ!R$2:AI$9999,13,FALSE)),"",VLOOKUP(業務内容と時間メモ!M68,業務内容と時間メモ!R$2:AI$9999,13,FALSE)) -> 舞洲1号シュート作図 | P68: =IF(ISNA(VLOOKUP(業務内容と時間メモ!M68,業務内容と時間メモ!R$2:AI$9999,15,FALSE)),"",VLOOKUP(業務内容と時間メモ!M68,業務内容と時間メモ!R$2:AI$9999,15,FALSE)) -> 舞洲1号 | Q68: =IF(ISNA(VLOOKUP(業務内容と時間メモ!M68,業務内容と時間メモ!R$2:AI$9999,14,FALSE)),"",VLOOKUP(業務内容と時間メモ!M68,業務内容と時間メモ!R$2:AI$9999,14,FALSE)) -> シュート作図 | R68: =IF(ISNA(VLOOKUP(業務内容と時間メモ!M68,業務内容と時間メモ!R$2:AI$9999,16,FALSE)),"",VLOOKUP(業務内容と時間メモ!M68,業務内容と時間メモ!R$2:AI$9999,16,FALSE)) | S68: =IF(ISNA(VLOOKUP(業務内容と時間メモ!M68,業務内容と時間メモ!R$2:AI$9999,17,FALSE)),"",VLOOKUP(業務内容と時間メモ!M68,業務内容と時間メモ!R$2:AI$9999,17,FALSE)) -> シュート | T68: =IF(SUMIFS(業務内容と時間メモ!E:E,業務内容と時間メモ!AB:AB,N68,業務内容と時間メモ!AD:AD,O68)=0,"",SUMIFS(業務内容と時間メモ!E:E,業務内容と時間メモ!AB:AB,N68,業務内容と時間メモ!AD:AD,O68)) | U68: =IF(SUMIFS(業務内容と時間メモ!F:F,業務内容と時間メモ!AB:AB,N68,業務内容と時間メモ!AD:AD,O68)=0,"",SUMIFS(業務内容と時間メモ!F:F,業務内容と時間メモ!AB:AB,N68,業務内容と時間メモ!AD:AD,O68)) -> 50
A69: =IF(ISNA(VLOOKUP(K69,L69:S10066,3,FALSE)),"",VLOOKUP(K69,L68:S10066,3,FALSE)) | B69: =IF(ISNA(VLOOKUP(K69,L69:S10066,5,FALSE)),"",VLOOKUP(K69,L68:S10066,5,FALSE)&"など") | C69: =IF(SUMIF(N:N,A69,U:U)=0,"",SUMIF(N:N,A69,U:U)) | J69: =IF(O69="","",IF(OR(COUNTIF(O69,"*職場*"),COUNTIF(O69,"*後輩教育*")),"サブ","メイン")) -> メイン | K69: 左表に入れますねぇ68 | L69: =IF(M69="","",IF(COUNTIF(INDIRECT("M$1:M"&ROW()),"左表に入れますねぇ")>=1,"左表に入れますねぇ"&COUNTIF(INDIRECT("M$1:M"&ROW()),"左表に入れますねぇ"),"")) | M69: =IF(N69="","",IF(COUNTIF(N$1:N69,N69)>1,"",IF(COUNTIF(N:N,N69)>=1,"左表に入れますねぇ",""))) | N69: =IF(ISNA(VLOOKUP(業務内容と時間メモ!M69,業務内容と時間メモ!R$2:AI$9999,11,FALSE)),"",VLOOKUP(業務内容と時間メモ!M69,業務内容と時間メモ!R$2:AI$9999,11,FALSE)) -> 6 | O69: =IF(ISNA(VLOOKUP(業務内容と時間メモ!M69,業務内容と時間メモ!R$2:AI$9999,13,FALSE)),"",VLOOKUP(業務内容と時間メモ!M69,業務内容と時間メモ!R$2:AI$9999,13,FALSE)) -> 東プラ2号ダクト作図 | P69: =IF(ISNA(VLOOKUP(業務内容と時間メモ!M69,業務内容と時間メモ!R$2:AI$9999,15,FALSE)),"",VLOOKUP(業務内容と時間メモ!M69,業務内容と時間メモ!R$2:AI$9999,15,FALSE)) -> 東プラ2号 | Q69: =IF(ISNA(VLOOKUP(業務内容と時間メモ!M69,業務内容と時間メモ!R$2:AI$9999,14,FALSE)),"",VLOOKUP(業務内容と時間メモ!M69,業務内容と時間メモ!R$2:AI$9999,14,FALSE)) -> ダクト作図 | R69: =IF(ISNA(VLOOKUP(業務内容と時間メモ!M69,業務内容と時間メモ!R$2:AI$9999,16,FALSE)),"",VLOOKUP(業務内容と時間メモ!M69,業務内容と時間メモ!R$2:AI$9999,16,FALSE)) | S69: =IF(ISNA(VLOOKUP(業務内容と時間メモ!M69,業務内容と時間メモ!R$2:AI$9999,17,FALSE)),"",VLOOKUP(業務内容と時間メモ!M69,業務内容と時間メモ!R$2:AI$9999,17,FALSE)) -> ダクト | T69: =IF(SUMIFS(業務内容と時間メモ!E:E,業務内容と時間メモ!AB:AB,N69,業務内容と時間メモ!AD:AD,O69)=0,"",SUMIFS(業務内容と時間メモ!E:E,業務内容と時間メモ!AB:AB,N69,業務内容と時間メモ!AD:AD,O69)) | U69: =IF(SUMIFS(業務内容と時間メモ!F:F,業務内容と時間メモ!AB:AB,N69,業務内容と時間メモ!AD:AD,O69)=0,"",SUMIFS(業務内容と時間メモ!F:F,業務内容と時間メモ!AB:AB,N69,業務内容と時間メモ!AD:AD,O69)) -> 15.5
A70: =IF(ISNA(VLOOKUP(K70,L70:S10067,3,FALSE)),"",VLOOKUP(K70,L69:S10067,3,FALSE)) | B70: =IF(ISNA(VLOOKUP(K70,L70:S10067,5,FALSE)),"",VLOOKUP(K70,L69:S10067,5,FALSE)&"など") | C70: =IF(SUMIF(N:N,A70,U:U)=0,"",SUMIF(N:N,A70,U:U)) | J70: =IF(O70="","",IF(OR(COUNTIF(O70,"*職場*"),COUNTIF(O70,"*後輩教育*")),"サブ","メイン")) -> メイン | K70: 左表に入れますねぇ69 | L70: =IF(M70="","",IF(COUNTIF(INDIRECT("M$1:M"&ROW()),"左表に入れますねぇ")>=1,"左表に入れますねぇ"&COUNTIF(INDIRECT("M$1:M"&ROW()),"左表に入れますねぇ"),"")) | M70: =IF(N70="","",IF(COUNTIF(N$1:N70,N70)>1,"",IF(COUNTIF(N:N,N70)>=1,"左表に入れますねぇ",""))) | N70: =IF(ISNA(VLOOKUP(業務内容と時間メモ!M70,業務内容と時間メモ!R$2:AI$9999,11,FALSE)),"",VLOOKUP(業務内容と時間メモ!M70,業務内容と時間メモ!R$2:AI$9999,11,FALSE)) -> 6 | O70: =IF(ISNA(VLOOKUP(業務内容と時間メモ!M70,業務内容と時間メモ!R$2:AI$9999,13,FALSE)),"",VLOOKUP(業務内容と時間メモ!M70,業務内容と時間メモ!R$2:AI$9999,13,FALSE)) -> 新河岸5号受座/振止メ作図 | P70: =IF(ISNA(VLOOKUP(業務内容と時間メモ!M70,業務内容と時間メモ!R$2:AI$9999,15,FALSE)),"",VLOOKUP(業務内容と時間メモ!M70,業務内容と時間メモ!R$2:AI$9999,15,FALSE)) -> 新河岸5号 | Q70: =IF(ISNA(VLOOKUP(業務内容と時間メモ!M70,業務内容と時間メモ!R$2:AI$9999,14,FALSE)),"",VLOOKUP(業務内容と時間メモ!M70,業務内容と時間メモ!R$2:AI$9999,14,FALSE)) -> 受座/振止メ作図 | R70: =IF(ISNA(VLOOKUP(業務内容と時間メモ!M70,業務内容と時間メモ!R$2:AI$9999,16,FALSE)),"",VLOOKUP(業務内容と時間メモ!M70,業務内容と時間メモ!R$2:AI$9999,16,FALSE)) | S70: =IF(ISNA(VLOOKUP(業務内容と時間メモ!M70,業務内容と時間メモ!R$2:AI$9999,17,FALSE)),"",VLOOKUP(業務内容と時間メモ!M70,業務内容と時間メモ!R$2:AI$9999,17,FALSE)) -> 受座/振止メ | T70: =IF(SUMIFS(業務内容と時間メモ!E:E,業務内容と時間メモ!AB:AB,N70,業務内容と時間メモ!AD:AD,O70)=0,"",SUMIFS(業務内容と時間メモ!E:E,業務内容と時間メモ!AB:AB,N70,業務内容と時間メモ!AD:AD,O70)) | U70: =IF(SUMIFS(業務内容と時間メモ!F:F,業務内容と時間メモ!AB:AB,N70,業務内容と時間メモ!AD:AD,O70)=0,"",SUMIFS(業務内容と時間メモ!F:F,業務内容と時間メモ!AB:AB,N70,業務内容と時間メモ!AD:AD,O70)) -> 98.25
A71: =IF(ISNA(VLOOKUP(K71,L71:S10068,3,FALSE)),"",VLOOKUP(K71,L70:S10068,3,FALSE)) | B71: =IF(ISNA(VLOOKUP(K71,L71:S10068,5,FALSE)),"",VLOOKUP(K71,L70:S10068,5,FALSE)&"など") | C71: =IF(SUMIF(N:N,A71,U:U)=0,"",SUMIF(N:N,A71,U:U)) | J71: =IF(O71="","",IF(OR(COUNTIF(O71,"*職場*"),COUNTIF(O71,"*後輩教育*")),"サブ","メイン")) -> メイン | K71: 左表に入れますねぇ70 | L71: =IF(M71="","",IF(COUNTIF(INDIRECT("M$1:M"&ROW()),"左表に入れますねぇ")>=1,"左表に入れますねぇ"&COUNTIF(INDIRECT("M$1:M"&ROW()),"左表に入れますねぇ"),"")) -> 左表に入れますねぇ10 | M71: =IF(N71="","",IF(COUNTIF(N$1:N71,N71)>1,"",IF(COUNTIF(N:N,N71)>=1,"左表に入れますねぇ",""))) -> 左表に入れますねぇ | N71: =IF(ISNA(VLOOKUP(業務内容と時間メモ!M71,業務内容と時間メモ!R$2:AI$9999,11,FALSE)),"",VLOOKUP(業務内容と時間メモ!M71,業務内容と時間メモ!R$2:AI$9999,11,FALSE)) -> 7 | O71: =IF(ISNA(VLOOKUP(業務内容と時間メモ!M71,業務内容と時間メモ!R$2:AI$9999,13,FALSE)),"",VLOOKUP(業務内容と時間メモ!M71,業務内容と時間メモ!R$2:AI$9999,13,FALSE)) -> 新河岸5号受座/振止メ作図 | P71: =IF(ISNA(VLOOKUP(業務内容と時間メモ!M71,業務内容と時間メモ!R$2:AI$9999,15,FALSE)),"",VLOOKUP(業務内容と時間メモ!M71,業務内容と時間メモ!R$2:AI$9999,15,FALSE)) -> 新河岸5号 | Q71: =IF(ISNA(VLOOKUP(業務内容と時間メモ!M71,業務内容と時間メモ!R$2:AI$9999,14,FALSE)),"",VLOOKUP(業務内容と時間メモ!M71,業務内容と時間メモ!R$2:AI$9999,14,FALSE)) -> 受座/振止メ作図 | R71: =IF(ISNA(VLOOKUP(業務内容と時間メモ!M71,業務内容と時間メモ!R$2:AI$9999,16,FALSE)),"",VLOOKUP(業務内容と時間メモ!M71,業務内容と時間メモ!R$2:AI$9999,16,FALSE)) | S71: =IF(ISNA(VLOOKUP(業務内容と時間メモ!M71,業務内容と時間メモ!R$2:AI$9999,17,FALSE)),"",VLOOKUP(業務内容と時間メモ!M71,業務内容と時間メモ!R$2:AI$9999,17,FALSE)) -> 受座/振止メ | T71: =IF(SUMIFS(業務内容と時間メモ!E:E,業務内容と時間メモ!AB:AB,N71,業務内容と時間メモ!AD:AD,O71)=0,"",SUMIFS(業務内容と時間メモ!E:E,業務内容と時間メモ!AB:AB,N71,業務内容と時間メモ!AD:AD,O71)) | U71: =IF(SUMIFS(業務内容と時間メモ!F:F,業務内容と時間メモ!AB:AB,N71,業務内容と時間メモ!AD:AD,O71)=0,"",SUMIFS(業務内容と時間メモ!F:F,業務内容と時間メモ!AB:AB,N71,業務内容と時間メモ!AD:AD,O71)) -> 22.25
A72: =IF(ISNA(VLOOKUP(K72,L72:S10069,3,FALSE)),"",VLOOKUP(K72,L71:S10069,3,FALSE)) | B72: =IF(ISNA(VLOOKUP(K72,L72:S10069,5,FALSE)),"",VLOOKUP(K72,L71:S10069,5,FALSE)&"など") | C72: =IF(SUMIF(N:N,A72,U:U)=0,"",SUMIF(N:N,A72,U:U)) | J72: =IF(O72="","",IF(OR(COUNTIF(O72,"*職場*"),COUNTIF(O72,"*後輩教育*")),"サブ","メイン")) -> メイン | K72: 左表に入れますねぇ71 | L72: =IF(M72="","",IF(COUNTIF(INDIRECT("M$1:M"&ROW()),"左表に入れますねぇ")>=1,"左表に入れますねぇ"&COUNTIF(INDIRECT("M$1:M"&ROW()),"左表に入れますねぇ"),"")) | M72: =IF(N72="","",IF(COUNTIF(N$1:N72,N72)>1,"",IF(COUNTIF(N:N,N72)>=1,"左表に入れますねぇ",""))) | N72: =IF(ISNA(VLOOKUP(業務内容と時間メモ!M72,業務内容と時間メモ!R$2:AI$9999,11,FALSE)),"",VLOOKUP(業務内容と時間メモ!M72,業務内容と時間メモ!R$2:AI$9999,11,FALSE)) -> 7 | O72: =IF(ISNA(VLOOKUP(業務内容と時間メモ!M72,業務内容と時間メモ!R$2:AI$9999,13,FALSE)),"",VLOOKUP(業務内容と時間メモ!M72,業務内容と時間メモ!R$2:AI$9999,13,FALSE)) -> 新河岸5号点検ステージ作図 | P72: =IF(ISNA(VLOOKUP(業務内容と時間メモ!M72,業務内容と時間メモ!R$2:AI$9999,15,FALSE)),"",VLOOKUP(業務内容と時間メモ!M72,業務内容と時間メモ!R$2:AI$9999,15,FALSE)) -> 新河岸5号 | Q72: =IF(ISNA(VLOOKUP(業務内容と時間メモ!M72,業務内容と時間メモ!R$2:AI$9999,14,FALSE)),"",VLOOKUP(業務内容と時間メモ!M72,業務内容と時間メモ!R$2:AI$9999,14,FALSE)) -> 点検ステージ作図 | R72: =IF(ISNA(VLOOKUP(業務内容と時間メモ!M72,業務内容と時間メモ!R$2:AI$9999,16,FALSE)),"",VLOOKUP(業務内容と時間メモ!M72,業務内容と時間メモ!R$2:AI$9999,16,FALSE)) | S72: =IF(ISNA(VLOOKUP(業務内容と時間メモ!M72,業務内容と時間メモ!R$2:AI$9999,17,FALSE)),"",VLOOKUP(業務内容と時間メモ!M72,業務内容と時間メモ!R$2:AI$9999,17,FALSE)) -> 点検ステージ | T72: =IF(SUMIFS(業務内容と時間メモ!E:E,業務内容と時間メモ!AB:AB,N72,業務内容と時間メモ!AD:AD,O72)=0,"",SUMIFS(業務内容と時間メモ!E:E,業務内容と時間メモ!AB:AB,N72,業務内容と時間メモ!AD:AD,O72)) | U72: =IF(SUMIFS(業務内容と時間メモ!F:F,業務内容と時間メモ!AB:AB,N72,業務内容と時間メモ!AD:AD,O72)=0,"",SUMIFS(業務内容と時間メモ!F:F,業務内容と時間メモ!AB:AB,N72,業務内容と時間メモ!AD:AD,O72)) -> 93
A73: =IF(ISNA(VLOOKUP(K73,L73:S10070,3,FALSE)),"",VLOOKUP(K73,L72:S10070,3,FALSE)) | B73: =IF(ISNA(VLOOKUP(K73,L73:S10070,5,FALSE)),"",VLOOKUP(K73,L72:S10070,5,FALSE)&"など") | C73: =IF(SUMIF(N:N,A73,U:U)=0,"",SUMIF(N:N,A73,U:U)) | J73: =IF(O73="","",IF(OR(COUNTIF(O73,"*職場*"),COUNTIF(O73,"*後輩教育*")),"サブ","メイン")) -> メイン | K73: 左表に入れますねぇ72 | L73: =IF(M73="","",IF(COUNTIF(INDIRECT("M$1:M"&ROW()),"左表に入れますねぇ")>=1,"左表に入れますねぇ"&COUNTIF(INDIRECT("M$1:M"&ROW()),"左表に入れますねぇ"),"")) | M73: =IF(N73="","",IF(COUNTIF(N$1:N73,N73)>1,"",IF(COUNTIF(N:N,N73)>=1,"左表に入れますねぇ",""))) | N73: =IF(ISNA(VLOOKUP(業務内容と時間メモ!M73,業務内容と時間メモ!R$2:AI$9999,11,FALSE)),"",VLOOKUP(業務内容と時間メモ!M73,業務内容と時間メモ!R$2:AI$9999,11,FALSE)) -> 7 | O73: =IF(ISNA(VLOOKUP(業務内容と時間メモ!M73,業務内容と時間メモ!R$2:AI$9999,13,FALSE)),"",VLOOKUP(業務内容と時間メモ!M73,業務内容と時間メモ!R$2:AI$9999,13,FALSE)) -> 東プラダクト作図 | P73: =IF(ISNA(VLOOKUP(業務内容と時間メモ!M73,業務内容と時間メモ!R$2:AI$9999,15,FALSE)),"",VLOOKUP(業務内容と時間メモ!M73,業務内容と時間メモ!R$2:AI$9999,15,FALSE)) -> 東プラ | Q73: =IF(ISNA(VLOOKUP(業務内容と時間メモ!M73,業務内容と時間メモ!R$2:AI$9999,14,FALSE)),"",VLOOKUP(業務内容と時間メモ!M73,業務内容と時間メモ!R$2:AI$9999,14,FALSE)) -> ダクト作図 | R73: =IF(ISNA(VLOOKUP(業務内容と時間メモ!M73,業務内容と時間メモ!R$2:AI$9999,16,FALSE)),"",VLOOKUP(業務内容と時間メモ!M73,業務内容と時間メモ!R$2:AI$9999,16,FALSE)) | S73: =IF(ISNA(VLOOKUP(業務内容と時間メモ!M73,業務内容と時間メモ!R$2:AI$9999,17,FALSE)),"",VLOOKUP(業務内容と時間メモ!M73,業務内容と時間メモ!R$2:AI$9999,17,FALSE)) -> ダクト | T73: =IF(SUMIFS(業務内容と時間メモ!E:E,業務内容と時間メモ!AB:AB,N73,業務内容と時間メモ!AD:AD,O73)=0,"",SUMIFS(業務内容と時間メモ!E:E,業務内容と時間メモ!AB:AB,N73,業務内容と時間メモ!AD:AD,O73)) | U73: =IF(SUMIFS(業務内容と時間メモ!F:F,業務内容と時間メモ!AB:AB,N73,業務内容と時間メモ!AD:AD,O73)=0,"",SUMIFS(業務内容と時間メモ!F:F,業務内容と時間メモ!AB:AB,N73,業務内容と時間メモ!AD:AD,O73)) -> 15.5
A74: =IF(ISNA(VLOOKUP(K74,L74:S10071,3,FALSE)),"",VLOOKUP(K74,L73:S10071,3,FALSE)) | B74: =IF(ISNA(VLOOKUP(K74,L74:S10071,5,FALSE)),"",VLOOKUP(K74,L73:S10071,5,FALSE)&"など") | C74: =IF(SUMIF(N:N,A74,U:U)=0,"",SUMIF(N:N,A74,U:U)) | J74: =IF(O74="","",IF(OR(COUNTIF(O74,"*職場*"),COUNTIF(O74,"*後輩教育*")),"サブ","メイン")) -> メイン | K74: 左表に入れますねぇ73 | L74: =IF(M74="","",IF(COUNTIF(INDIRECT("M$1:M"&ROW()),"左表に入れますねぇ")>=1,"左表に入れますねぇ"&COUNTIF(INDIRECT("M$1:M"&ROW()),"左表に入れますねぇ"),"")) | M74: =IF(N74="","",IF(COUNTIF(N$1:N74,N74)>1,"",IF(COUNTIF(N:N,N74)>=1,"左表に入れますねぇ",""))) | N74: =IF(ISNA(VLOOKUP(業務内容と時間メモ!M74,業務内容と時間メモ!R$2:AI$9999,11,FALSE)),"",VLOOKUP(業務内容と時間メモ!M74,業務内容と時間メモ!R$2:AI$9999,11,FALSE)) -> 7 | O74: =IF(ISNA(VLOOKUP(業務内容と時間メモ!M74,業務内容と時間メモ!R$2:AI$9999,13,FALSE)),"",VLOOKUP(業務内容と時間メモ!M74,業務内容と時間メモ!R$2:AI$9999,13,FALSE)) -> 新河岸5号ラダー作図 | P74: =IF(ISNA(VLOOKUP(業務内容と時間メモ!M74,業務内容と時間メモ!R$2:AI$9999,15,FALSE)),"",VLOOKUP(業務内容と時間メモ!M74,業務内容と時間メモ!R$2:AI$9999,15,FALSE)) -> 新河岸5号 | Q74: =IF(ISNA(VLOOKUP(業務内容と時間メモ!M74,業務内容と時間メモ!R$2:AI$9999,14,FALSE)),"",VLOOKUP(業務内容と時間メモ!M74,業務内容と時間メモ!R$2:AI$9999,14,FALSE)) -> ラダー作図 | R74: =IF(ISNA(VLOOKUP(業務内容と時間メモ!M74,業務内容と時間メモ!R$2:AI$9999,16,FALSE)),"",VLOOKUP(業務内容と時間メモ!M74,業務内容と時間メモ!R$2:AI$9999,16,FALSE)) | S74: =IF(ISNA(VLOOKUP(業務内容と時間メモ!M74,業務内容と時間メモ!R$2:AI$9999,17,FALSE)),"",VLOOKUP(業務内容と時間メモ!M74,業務内容と時間メモ!R$2:AI$9999,17,FALSE)) -> ラダー | T74: =IF(SUMIFS(業務内容と時間メモ!E:E,業務内容と時間メモ!AB:AB,N74,業務内容と時間メモ!AD:AD,O74)=0,"",SUMIFS(業務内容と時間メモ!E:E,業務内容と時間メモ!AB:AB,N74,業務内容と時間メモ!AD:AD,O74)) | U74: =IF(SUMIFS(業務内容と時間メモ!F:F,業務内容と時間メモ!AB:AB,N74,業務内容と時間メモ!AD:AD,O74)=0,"",SUMIFS(業務内容と時間メモ!F:F,業務内容と時間メモ!AB:AB,N74,業務内容と時間メモ!AD:AD,O74)) -> 46.5
A75: =IF(ISNA(VLOOKUP(K75,L75:S10072,3,FALSE)),"",VLOOKUP(K75,L74:S10072,3,FALSE)) | B75: =IF(ISNA(VLOOKUP(K75,L75:S10072,5,FALSE)),"",VLOOKUP(K75,L74:S10072,5,FALSE)&"など") | C75: =IF(SUMIF(N:N,A75,U:U)=0,"",SUMIF(N:N,A75,U:U)) | J75: =IF(O75="","",IF(OR(COUNTIF(O75,"*職場*"),COUNTIF(O75,"*後輩教育*")),"サブ","メイン")) -> メイン | K75: 左表に入れますねぇ74 | L75: =IF(M75="","",IF(COUNTIF(INDIRECT("M$1:M"&ROW()),"左表に入れますねぇ")>=1,"左表に入れますねぇ"&COUNTIF(INDIRECT("M$1:M"&ROW()),"左表に入れますねぇ"),"")) -> 左表に入れますねぇ11 | M75: =IF(N75="","",IF(COUNTIF(N$1:N75,N75)>1,"",IF(COUNTIF(N:N,N75)>=1,"左表に入れますねぇ",""))) -> 左表に入れますねぇ | N75: =IF(ISNA(VLOOKUP(業務内容と時間メモ!M75,業務内容と時間メモ!R$2:AI$9999,11,FALSE)),"",VLOOKUP(業務内容と時間メモ!M75,業務内容と時間メモ!R$2:AI$9999,11,FALSE)) -> 8 | O75: =IF(ISNA(VLOOKUP(業務内容と時間メモ!M75,業務内容と時間メモ!R$2:AI$9999,13,FALSE)),"",VLOOKUP(業務内容と時間メモ!M75,業務内容と時間メモ!R$2:AI$9999,13,FALSE)) -> 仙塩浄化センター砂冷却コンベヤ作図 | P75: =IF(ISNA(VLOOKUP(業務内容と時間メモ!M75,業務内容と時間メモ!R$2:AI$9999,15,FALSE)),"",VLOOKUP(業務内容と時間メモ!M75,業務内容と時間メモ!R$2:AI$9999,15,FALSE)) -> 仙塩浄化センター | Q75: =IF(ISNA(VLOOKUP(業務内容と時間メモ!M75,業務内容と時間メモ!R$2:AI$9999,14,FALSE)),"",VLOOKUP(業務内容と時間メモ!M75,業務内容と時間メモ!R$2:AI$9999,14,FALSE)) -> 砂冷却コンベヤ作図 | R75: =IF(ISNA(VLOOKUP(業務内容と時間メモ!M75,業務内容と時間メモ!R$2:AI$9999,16,FALSE)),"",VLOOKUP(業務内容と時間メモ!M75,業務内容と時間メモ!R$2:AI$9999,16,FALSE)) | S75: =IF(ISNA(VLOOKUP(業務内容と時間メモ!M75,業務内容と時間メモ!R$2:AI$9999,17,FALSE)),"",VLOOKUP(業務内容と時間メモ!M75,業務内容と時間メモ!R$2:AI$9999,17,FALSE)) -> 砂冷却コンベヤ | T75: =IF(SUMIFS(業務内容と時間メモ!E:E,業務内容と時間メモ!AB:AB,N75,業務内容と時間メモ!AD:AD,O75)=0,"",SUMIFS(業務内容と時間メモ!E:E,業務内容と時間メモ!AB:AB,N75,業務内容と時間メモ!AD:AD,O75)) | U75: =IF(SUMIFS(業務内容と時間メモ!F:F,業務内容と時間メモ!AB:AB,N75,業務内容と時間メモ!AD:AD,O75)=0,"",SUMIFS(業務内容と時間メモ!F:F,業務内容と時間メモ!AB:AB,N75,業務内容と時間メモ!AD:AD,O75)) -> 46.5
A76: =IF(ISNA(VLOOKUP(K76,L76:S10073,3,FALSE)),"",VLOOKUP(K76,L75:S10073,3,FALSE)) | B76: =IF(ISNA(VLOOKUP(K76,L76:S10073,5,FALSE)),"",VLOOKUP(K76,L75:S10073,5,FALSE)&"など") | C76: =IF(SUMIF(N:N,A76,U:U)=0,"",SUMIF(N:N,A76,U:U)) | J76: =IF(O76="","",IF(OR(COUNTIF(O76,"*職場*"),COUNTIF(O76,"*後輩教育*")),"サブ","メイン")) -> メイン | K76: 左表に入れますねぇ75 | L76: =IF(M76="","",IF(COUNTIF(INDIRECT("M$1:M"&ROW()),"左表に入れますねぇ")>=1,"左表に入れますねぇ"&COUNTIF(INDIRECT("M$1:M"&ROW()),"左表に入れますねぇ"),"")) | M76: =IF(N76="","",IF(COUNTIF(N$1:N76,N76)>1,"",IF(COUNTIF(N:N,N76)>=1,"左表に入れますねぇ",""))) | N76: =IF(ISNA(VLOOKUP(業務内容と時間メモ!M76,業務内容と時間メモ!R$2:AI$9999,11,FALSE)),"",VLOOKUP(業務内容と時間メモ!M76,業務内容と時間メモ!R$2:AI$9999,11,FALSE)) -> 8 | O76: =IF(ISNA(VLOOKUP(業務内容と時間メモ!M76,業務内容と時間メモ!R$2:AI$9999,13,FALSE)),"",VLOOKUP(業務内容と時間メモ!M76,業務内容と時間メモ!R$2:AI$9999,13,FALSE)) -> 新河岸5号点検ステージ作図 | P76: =IF(ISNA(VLOOKUP(業務内容と時間メモ!M76,業務内容と時間メモ!R$2:AI$9999,15,FALSE)),"",VLOOKUP(業務内容と時間メモ!M76,業務内容と時間メモ!R$2:AI$9999,15,FALSE)) -> 新河岸5号 | Q76: =IF(ISNA(VLOOKUP(業務内容と時間メモ!M76,業務内容と時間メモ!R$2:AI$9999,14,FALSE)),"",VLOOKUP(業務内容と時間メモ!M76,業務内容と時間メモ!R$2:AI$9999,14,FALSE)) -> 点検ステージ作図 | R76: =IF(ISNA(VLOOKUP(業務内容と時間メモ!M76,業務内容と時間メモ!R$2:AI$9999,16,FALSE)),"",VLOOKUP(業務内容と時間メモ!M76,業務内容と時間メモ!R$2:AI$9999,16,FALSE)) | S76: =IF(ISNA(VLOOKUP(業務内容と時間メモ!M76,業務内容と時間メモ!R$2:AI$9999,17,FALSE)),"",VLOOKUP(業務内容と時間メモ!M76,業務内容と時間メモ!R$2:AI$9999,17,FALSE)) -> 点検ステージ | T76: =IF(SUMIFS(業務内容と時間メモ!E:E,業務内容と時間メモ!AB:AB,N76,業務内容と時間メモ!AD:AD,O76)=0,"",SUMIFS(業務内容と時間メモ!E:E,業務内容と時間メモ!AB:AB,N76,業務内容と時間メモ!AD:AD,O76)) | U76: =IF(SUMIFS(業務内容と時間メモ!F:F,業務内容と時間メモ!AB:AB,N76,業務内容と時間メモ!AD:AD,O76)=0,"",SUMIFS(業務内容と時間メモ!F:F,業務内容と時間メモ!AB:AB,N76,業務内容と時間メモ!AD:AD,O76)) -> 31
A77: =IF(ISNA(VLOOKUP(K77,L77:S10074,3,FALSE)),"",VLOOKUP(K77,L76:S10074,3,FALSE)) | B77: =IF(ISNA(VLOOKUP(K77,L77:S10074,5,FALSE)),"",VLOOKUP(K77,L76:S10074,5,FALSE)&"など") | C77: =IF(SUMIF(N:N,A77,U:U)=0,"",SUMIF(N:N,A77,U:U)) | J77: =IF(O77="","",IF(OR(COUNTIF(O77,"*職場*"),COUNTIF(O77,"*後輩教育*")),"サブ","メイン")) -> メイン | K77: 左表に入れますねぇ76 | L77: =IF(M77="","",IF(COUNTIF(INDIRECT("M$1:M"&ROW()),"左表に入れますねぇ")>=1,"左表に入れますねぇ"&COUNTIF(INDIRECT("M$1:M"&ROW()),"左表に入れますねぇ"),"")) | M77: =IF(N77="","",IF(COUNTIF(N$1:N77,N77)>1,"",IF(COUNTIF(N:N,N77)>=1,"左表に入れますねぇ",""))) | N77: =IF(ISNA(VLOOKUP(業務内容と時間メモ!M77,業務内容と時間メモ!R$2:AI$9999,11,FALSE)),"",VLOOKUP(業務内容と時間メモ!M77,業務内容と時間メモ!R$2:AI$9999,11,FALSE)) -> 8 | O77: =IF(ISNA(VLOOKUP(業務内容と時間メモ!M77,業務内容と時間メモ!R$2:AI$9999,13,FALSE)),"",VLOOKUP(業務内容と時間メモ!M77,業務内容と時間メモ!R$2:AI$9999,13,FALSE)) -> 東プラダクト現場見学 | P77: =IF(ISNA(VLOOKUP(業務内容と時間メモ!M77,業務内容と時間メモ!R$2:AI$9999,15,FALSE)),"",VLOOKUP(業務内容と時間メモ!M77,業務内容と時間メモ!R$2:AI$9999,15,FALSE)) -> 東プラ | Q77: =IF(ISNA(VLOOKUP(業務内容と時間メモ!M77,業務内容と時間メモ!R$2:AI$9999,14,FALSE)),"",VLOOKUP(業務内容と時間メモ!M77,業務内容と時間メモ!R$2:AI$9999,14,FALSE)) -> ダクト現場見学 | R77: =IF(ISNA(VLOOKUP(業務内容と時間メモ!M77,業務内容と時間メモ!R$2:AI$9999,16,FALSE)),"",VLOOKUP(業務内容と時間メモ!M77,業務内容と時間メモ!R$2:AI$9999,16,FALSE)) | S77: =IF(ISNA(VLOOKUP(業務内容と時間メモ!M77,業務内容と時間メモ!R$2:AI$9999,17,FALSE)),"",VLOOKUP(業務内容と時間メモ!M77,業務内容と時間メモ!R$2:AI$9999,17,FALSE)) -> ダクト | T77: =IF(SUMIFS(業務内容と時間メモ!E:E,業務内容と時間メモ!AB:AB,N77,業務内容と時間メモ!AD:AD,O77)=0,"",SUMIFS(業務内容と時間メモ!E:E,業務内容と時間メモ!AB:AB,N77,業務内容と時間メモ!AD:AD,O77)) | U77: =IF(SUMIFS(業務内容と時間メモ!F:F,業務内容と時間メモ!AB:AB,N77,業務内容と時間メモ!AD:AD,O77)=0,"",SUMIFS(業務内容と時間メモ!F:F,業務内容と時間メモ!AB:AB,N77,業務内容と時間メモ!AD:AD,O77)) -> 7.75
A78: =IF(ISNA(VLOOKUP(K78,L78:S10075,3,FALSE)),"",VLOOKUP(K78,L77:S10075,3,FALSE)) | B78: =IF(ISNA(VLOOKUP(K78,L78:S10075,5,FALSE)),"",VLOOKUP(K78,L77:S10075,5,FALSE)&"など") | C78: =IF(SUMIF(N:N,A78,U:U)=0,"",SUMIF(N:N,A78,U:U)) | J78: =IF(O78="","",IF(OR(COUNTIF(O78,"*職場*"),COUNTIF(O78,"*後輩教育*")),"サブ","メイン")) | K78: 左表に入れますねぇ85 | L78: =IF(M78="","",IF(COUNTIF(INDIRECT("M$1:M"&ROW()),"左表に入れますねぇ")>=1,"左表に入れますねぇ"&COUNTIF(INDIRECT("M$1:M"&ROW()),"左表に入れますねぇ"),"")) | M78: =IF(N78="","",IF(COUNTIF(N$1:N78,N78)>1,"",IF(COUNTIF(N:N,N78)>=1,"左表に入れますねぇ",""))) | N78: =IF(ISNA(VLOOKUP(業務内容と時間メモ!M86,業務内容と時間メモ!R$2:AI$9999,11,FALSE)),"",VLOOKUP(業務内容と時間メモ!M86,業務内容と時間メモ!R$2:AI$9999,11,FALSE)) | O78: =IF(ISNA(VLOOKUP(業務内容と時間メモ!M86,業務内容と時間メモ!R$2:AI$9999,13,FALSE)),"",VLOOKUP(業務内容と時間メモ!M86,業務内容と時間メモ!R$2:AI$9999,13,FALSE)) | P78: =IF(ISNA(VLOOKUP(業務内容と時間メモ!M86,業務内容と時間メモ!R$2:AI$9999,15,FALSE)),"",VLOOKUP(業務内容と時間メモ!M86,業務内容と時間メモ!R$2:AI$9999,15,FALSE)) | Q78: =IF(ISNA(VLOOKUP(業務内容と時間メモ!M86,業務内容と時間メモ!R$2:AI$9999,14,FALSE)),"",VLOOKUP(業務内容と時間メモ!M86,業務内容と時間メモ!R$2:AI$9999,14,FALSE)) | R78: =IF(ISNA(VLOOKUP(業務内容と時間メモ!M86,業務内容と時間メモ!R$2:AI$9999,16,FALSE)),"",VLOOKUP(業務内容と時間メモ!M86,業務内容と時間メモ!R$2:AI$9999,16,FALSE)) | S78: =IF(ISNA(VLOOKUP(業務内容と時間メモ!M86,業務内容と時間メモ!R$2:AI$9999,17,FALSE)),"",VLOOKUP(業務内容と時間メモ!M86,業務内容と時間メモ!R$2:AI$9999,17,FALSE)) | T78: =IF(SUMIFS(業務内容と時間メモ!E:E,業務内容と時間メモ!AB:AB,N78,業務内容と時間メモ!AD:AD,O78)=0,"",SUMIFS(業務内容と時間メモ!E:E,業務内容と時間メモ!AB:AB,N78,業務内容と時間メモ!AD:AD,O78)) | U78: =IF(SUMIFS(業務内容と時間メモ!F:F,業務内容と時間メモ!AB:AB,N78,業務内容と時間メモ!AD:AD,O78)=0,"",SUMIFS(業務内容と時間メモ!F:F,業務内容と時間メモ!AB:AB,N78,業務内容と時間メモ!AD:AD,O78))
